Workbook

Sheet MODE EMPLOI
A1: DDC Calculateur — synthese automatique
A4: 1. SAISIE : collez vos cas (colonnes A a E). Colonne F = noeud (auto).
A5: 2. SYNTHESE : 11 lignes par noeud detecte — le tableau grandit avec vos noeuds.
A6: 3. Plus de cas dans un meme noeud ne rajoute pas de lignes (maxi/mini par famille).
A7: 4. Si besoin : touche F9 pour forcer le recalcul.
A9: Excel 2019 ou 365 requis (formules MINIFS / MAXIFS).
A10: Gardez Vent G/D, Vent D/G, Neige... dans Nom_cas.

Sheet SAISIE
A1: SAISIE — Vos cas de charge
A2: Collez toutes vos lignes DDC ici (plusieurs noeuds possibles).
A4: Noeud_Cas | B4: Nom_cas | C4: FX_daN | D4: FY_daN | E4: FZ_daN | F4: Noeud
A5: 47/1 | B5: G : Couverture : PA 6 BS 10 PV15 | C5: -116 | D5: 7 | E5: -1285 | F5: =IF(A5="","",VALUE(LEFT(A5,FIND("/",A5&"/")-1))) -> 47
A6: 47/2 | B6: Vent G/D dep.(-) Portique 2 | C6: 905 | D6: 40 | E6: 1422 | F6: =IF(A6="","",VALUE(LEFT(A6,FIND("/",A6&"/")-1))) -> 47
A7: 47/3 | B7: Vent G/D sur.(+) Portique 2 | C7: 900 | D7: 32 | E7: 1444 | F7: =IF(A7="","",VALUE(LEFT(A7,FIND("/",A7&"/")-1))) -> 47
A8: 47/4 | B8: Vent D/G dep.(-) Cpe - Portique 2 | C8: -345 | D8: 5 | E8: 462 | F8: =IF(A8="","",VALUE(LEFT(A8,FIND("/",A8&"/")-1))) -> 47
A9: 47/5 | B9: Vent D/G dep.(-) Cpe + Portique 2 | C9: -513 | D9: -11 | E9: -281 | F9: =IF(A9="","",VALUE(LEFT(A9,FIND("/",A9&"/")-1))) -> 47
A10: 47/6 | B10: Vent D/G sur.(+) Cpe - Portique 2 | C10: -349 | D10: -2 | E10: 485 | F10: =IF(A10="","",VALUE(LEFT(A10,FIND("/",A10&"/")-1))) -> 47
A11: 47/7 | B11: Vent D/G sur.(+) Cpe + Portique 2 | C11: -518 | D11: -22 | E11: -258 | F11: =IF(A11="","",VALUE(LEFT(A11,FIND("/",A11&"/")-1))) -> 47
A12: 47/8 | B12: Vent Av./Arr. dep.(-) Portique 2 | C12: -241 | D12: 205 | E12: 815 | F12: =IF(A12="","",VALUE(LEFT(A12,FIND("/",A12&"/")-1))) -> 47
A13: 47/9 | B13: Vent Av./Arr. sur.(+) Portique 2 | C13: -198 | D13: 195 | E13: 598 | F13: =IF(A13="","",VALUE(LEFT(A13,FIND("/",A13&"/")-1))) -> 47
A14: 47/10 | B14: Vent Arr./Av. dep.(-) Portique 2 | C14: -105 | D14: 0 | E14: 400 | F14: =IF(A14="","",VALUE(LEFT(A14,FIND("/",A14&"/")-1))) -> 47
A15: 47/11 | B15: Vent Arr./Av. sur.(+) Portique 2 | C15: -37 | D15: -11 | E15: 56 | F15: =IF(A15="","",VALUE(LEFT(A15,FIND("/",A15&"/")-1))) -> 47
A16: 47/12 | B16: Neige cas I | C16: -113 | D16: 0 | E16: -1010 | F16: =IF(A16="","",VALUE(LEFT(A16,FIND("/",A16&"/")-1))) -> 47
... A18: 47/14 | B18: Neige accidentel | C18: -251 | D18: 0 | E18: -2244 | F18: =IF(A18="","",VALUE(LEFT(A18,FIND("/",A18&"/")-1))) -> 47
F19: =IF(A19="","",VALUE(LEFT(A19,FIND("/",A19&"/")-1)))
F20: =IF(A20="","",VALUE(LEFT(A20,FIND("/",A20&"/")-1)))
F21: =IF(A21="","",VALUE(LEFT(A21,FIND("/",A21&"/")-1)))
F22: =IF(A22="","",VALUE(LEFT(A22,FIND("/",A22&"/")-1)))
F23: =IF(A23="","",VALUE(LEFT(A23,FIND("/",A23&"/")-1)))
F24: =IF(A24="","",VALUE(LEFT(A24,FIND("/",A24&"/")-1)))
F25: =IF(A25="","",VALUE(LEFT(A25,FIND("/",A25&"/")-1)))
F26: =IF(A26="","",VALUE(LEFT(A26,FIND("/",A26&"/")-1)))
F27: =IF(A27="","",VALUE(LEFT(A27,FIND("/",A27&"/")-1)))
F28: =IF(A28="","",VALUE(LEFT(A28,FIND("/",A28&"/")-1)))
F29: =IF(A29="","",VALUE(LEFT(A29,FIND("/",A29&"/")-1)))
F30: =IF(A30="","",VALUE(LEFT(A30,FIND("/",A30&"/")-1)))
... F504: =IF(A504="","",VALUE(LEFT(A504,FIND("/",A504&"/")-1)))

Sheet SYNTHESE
A1: SYNTHESE — Calcul automatique par noeud
A2: =COUNTA(SAISIE!$A$5:$A$504)&" cas saisis | "&SUMPRODUCT(--(MOD(ROW($G$5:$G$484)-5,12)=0)*($G$5:$G$484<>""))&" noeud(s)" -> 14 cas saisis | 1 noeud(s)
A4: Nom du cas | B4: FX [daN] | C4: FY [daN] | D4: FZ [daN] | E4: Note
A5: =IF($G$5="","","Noeud "&$G$5) -> Noeud 47 | G5: =IFERROR(INDEX(SAISIE!$F$5:$F$504,_xlfn.AGGREGATE(15,6,ROW(SAISIE!$F$5:$F$504)-ROW(SAISIE!$F$5)+1/(SAISIE!$F$5:$F$504<>"")/(COUNTIF($G$4:G4,SAISIE!$F$5:$F$504)=0),1)),"") -> 47
A6: Couverture | B6: =IF($G$5="","",IFERROR(IFERROR(LOOKUP(2,1/((SAISIE!$F$5:$F$504=$G$5)*(LEFT(SAISIE!$B$5:$B$504,2)="G ")),SAISIE!$C$5:$C$504),LOOKUP(2,1/((SAISIE!$F$5:$F$504=$G$5)*(ISNUMBER(SEARCH("Couverture",SAISIE!$B$5:$B$504)))),SAISIE!$C$5:$C$504)),"-")) -> -116 | C6: =IF($G$5="","",IFERROR(IFERROR(LOOKUP(2,1/((SAISIE!$F$5:$F$504=$G$5)*(LEFT(SAISIE!$B$5:$B$504,2)="G ")),SAISIE!$D$5:$D$504),LOOKUP(2,1/((SAISIE!$F$5:$F$504=$G$5)*(ISNUMBER(SEARCH("Couverture",SAISIE!$B$5:$B$504)))),SAISIE!$D$5:$D$504)),"-")) -> 7 | D6: =IF($G$5="","",IFERROR(IFERROR(LOOKUP(2,1/((SAISIE!$F$5:$F$504=$G$5)*(LEFT(SAISIE!$B$5:$B$504,2)="G ")),SAISIE!$E$5:$E$504),LOOKUP(2,1/((SAISIE!$F$5:$F$504=$G$5)*(ISNUMBER(SEARCH("Couverture",SAISIE!$B$5:$B$504)))),SAISIE!$E$5:$E$504)),"-")) -> -1285
A7: Vent G/D maxi | B7: =IF($G$5="","",IFERROR(IF(_xlfn.MINIFS(SAISIE!$E$5:$E$504,SAISIE!$B$5:$B$504,"*Vent G/D*",SAISIE!$F$5:$F$504,$G$5)>=0,_xlfn.MAXIFS(SAISIE!$C$5:$C$504,SAISIE!$B$5:$B$504,"*Vent G/D*",SAISIE!$F$5:$F$504,$G$5),INDEX(SAISIE!$C$5:$C$504,MATCH(_xlfn.MINIFS(SAISIE!$E$5:$E$504,SAISIE!$B$5:$B$504,"*Vent G/D*",SAISIE!$F$5:$F$504,$G$5),SAISIE!$E$5:$E$504,0))),"-")) -> 905 | C7: =IF($G$5="","",IFERROR(IF(_xlfn.MINIFS(SAISIE!$E$5:$E$504,SAISIE!$B$5:$B$504,"*Vent G/D*",SAISIE!$F$5:$F$504,$G$5)>=0,INDEX(SAISIE!$D$5:$D$504,MATCH(_xlfn.MAXIFS(SAISIE!$C$5:$C$504,SAISIE!$B$5:$B$504,"*Vent G/D*",SAISIE!$F$5:$F$504,$G$5),SAISIE!$C$5:$C$504,0)),INDEX(SAISIE!$D$5:$D$504,MATCH(_xlfn.MINIFS(SAISIE!$E$5:$E$504,SAISIE!$B$5:$B$504,"*Vent G/D*",SAISIE!$F$5:$F$504,$G$5),SAISIE!$E$5:$E$504,0))),"-")) -> 40 | D7: =IF($G$5="","",IFERROR(IF(_xlfn.MINIFS(SAISIE!$E$5:$E$504,SAISIE!$B$5:$B$504,"*Vent G/D*",SAISIE!$F$5:$F$504,$G$5)>=0,0,_xlfn.MINIFS(SAISIE!$E$5:$E$504,SAISIE!$B$5:$B$504,"*Vent G/D*",SAISIE!$F$5:$F$504,$G$5)),"-")) -> 0 | E7: (compression)
A8: Vent G/D mini | B8: =IF($G$5="","",IFERROR(INDEX(SAISIE!$C$5:$C$504,MATCH(_xlfn.MAXIFS(SAISIE!$E$5:$E$504,SAISIE!$B$5:$B$504,"*Vent G/D*",SAISIE!$F$5:$F$504,$G$5),SAISIE!$E$5:$E$504,0)),"-")) -> 900 | C8: =IF($G$5="","",IFERROR(INDEX(SAISIE!$D$5:$D$504,MATCH(_xlfn.MAXIFS(SAISIE!$E$5:$E$504,SAISIE!$B$5:$B$504,"*Vent G/D*",SAISIE!$F$5:$F$504,$G$5),SAISIE!$E$5:$E$504,0)),"-")) -> 32 | D8: =IF($G$5="","",IFERROR(_xlfn.MAXIFS(SAISIE!$E$5:$E$504,SAISIE!$B$5:$B$504,"*Vent G/D*",SAISIE!$F$5:$F$504,$G$5),"-")) -> 1444 | E8: (soulevement)
A9: Vent D/ G maxi | B9: =IF($G$5="","",IFERROR(IF(_xlfn.MINIFS(SAISIE!$E$5:$E$504,SAISIE!$B$5:$B$504,"*Vent D/G*",SAISIE!$F$5:$F$504,$G$5)>=0,_xlfn.MAXIFS(SAISIE!$C$5:$C$504,SAISIE!$B$5:$B$504,"*Vent D/G*",SAISIE!$F$5:$F$504,$G$5),INDEX(SAISIE!$C$5:$C$504,MATCH(_xlfn.MINIFS(SAISIE!$E$5:$E$504,SAISIE!$B$5:$B$504,"*Vent D/G*",SAISIE!$F$5:$F$504,$G$5),SAISIE!$E$5:$E$504,0))),"-")) -> -513 | C9: =IF($G$5="","",IFERROR(IF(_xlfn.MINIFS(SAISIE!$E$5:$E$504,SAISIE!$B$5:$B$504,"*Vent D/G*",SAISIE!$F$5:$F$504,$G$5)>=0,INDEX(SAISIE!$D$5:$D$504,MATCH(_xlfn.MAXIFS(SAISIE!$C$5:$C$504,SAISIE!$B$5:$B$504,"*Vent D/G*",SAISIE!$F$5:$F$504,$G$5),SAISIE!$C$5:$C$504,0)),INDEX(SAISIE!$D$5:$D$504,MATCH(_xlfn.MINIFS(SAISIE!$E$5:$E$504,SAISIE!$B$5:$B$504,"*Vent D/G*",SAISIE!$F$5:$F$504,$G$5),SAISIE!$E$5:$E$504,0))),"-")) -> -11 | D9: =IF($G$5="","",IFERROR(IF(_xlfn.MINIFS(SAISIE!$E$5:$E$504,SAISIE!$B$5:$B$504,"*Vent D/G*",SAISIE!$F$5:$F$504,$G$5)>=0,0,_xlfn.MINIFS(SAISIE!$E$5:$E$504,SAISIE!$B$5:$B$504,"*Vent D/G*",SAISIE!$F$5:$F$504,$G$5)),"-")) -> -281 | E9: (compression)
A10: Vent D/G mini | B10: =IF($G$5="","",IFERROR(INDEX(SAISIE!$C$5:$C$504,MATCH(_xlfn.MAXIFS(SAISIE!$E$5:$E$504,SAISIE!$B$5:$B$504,"*Vent D/G*",SAISIE!$F$5:$F$504,$G$5),SAISIE!$E$5:$E$504,0)),"-")) -> -349 | C10: =IF($G$5="","",IFERROR(INDEX(SAISIE!$D$5:$D$504,MATCH(_xlfn.MAXIFS(SAISIE!$E$5:$E$504,SAISIE!$B$5:$B$504,"*Vent D/G*",SAISIE!$F$5:$F$504,$G$5),SAISIE!$E$5:$E$504,0)),"-")) -> -2 | D10: =IF($G$5="","",IFERROR(_xlfn.MAXIFS(SAISIE!$E$5:$E$504,SAISIE!$B$5:$B$504,"*Vent D/G*",SAISIE!$F$5:$F$504,$G$5),"-")) -> 485 | E10: (soulevement)
A11: Vent Av./Arr. maxi | B11: =IF($G$5="","",IFERROR(IF(_xlfn.MINIFS(SAISIE!$E$5:$E$504,SAISIE!$B$5:$B$504,"*Vent Av./Arr.*",SAISIE!$F$5:$F$504,$G$5)>=0,_xlfn.MAXIFS(SAISIE!$C$5:$C$504,SAISIE!$B$5:$B$504,"*Vent Av./Arr.*",SAISIE!$F$5:$F$504,$G$5),INDEX(SAISIE!$C$5:$C$504,MATCH(_xlfn.MINIFS(SAISIE!$E$5:$E$504,SAISIE!$B$5:$B$504,"*Vent Av./Arr.*",SAISIE!$F$5:$F$504,$G$5),SAISIE!$E$5:$E$504,0))),"-")) -> -198 | C11: =IF($G$5="","",IFERROR(IF(_xlfn.MINIFS(SAISIE!$E$5:$E$504,SAISIE!$B$5:$B$504,"*Vent Av./Arr.*",SAISIE!$F$5:$F$504,$G$5)>=0,INDEX(SAISIE!$D$5:$D$504,MATCH(_xlfn.MAXIFS(SAISIE!$C$5:$C$504,SAISIE!$B$5:$B$504,"*Vent Av./Arr.*",SAISIE!$F$5:$F$504,$G$5),SAISIE!$C$5:$C$504,0)),INDEX(SAISIE!$D$5:$D$504,MATCH(_xlfn.MINIFS(SAISIE!$E$5:$E$504,SAISIE!$B$5:$B$504,"*Vent Av./Arr.*",SAISIE!$F$5:$F$504,$G$5),SAISIE!$E$5:$E$504,0))),"-")) -> 195 | D11: =IF($G$5="","",IFERROR(IF(_xlfn.MINIFS(SAISIE!$E$5:$E$504,SAISIE!$B$5:$B$504,"*Vent Av./Arr.*",SAISIE!$F$5:$F$504,$G$5)>=0,0,_xlfn.MINIFS(SAISIE!$E$5:$E$504,SAISIE!$B$5:$B$504,"*Vent Av./Arr.*",SAISIE!$F$5:$F$504,$G$5)),"-")) -> 0 | E11: (compression)
A12: Vent Av./Arr. mini | B12: =IF($G$5="","",IFERROR(INDEX(SAISIE!$C$5:$C$504,MATCH(_xlfn.MAXIFS(SAISIE!$E$5:$E$504,SAISIE!$B$5:$B$504,"*Vent Av./Arr.*",SAISIE!$F$5:$F$504,$G$5),SAISIE!$E$5:$E$504,0)),"-")) -> -241 | C12: =IF($G$5="","",IFERROR(INDEX(SAISIE!$D$5:$D$504,MATCH(_xlfn.MAXIFS(SAISIE!$E$5:$E$504,SAISIE!$B$5:$B$504,"*Vent Av./Arr.*",SAISIE!$F$5:$F$504,$G$5),SAISIE!$E$5:$E$504,0)),"-")) -> 205 | D12: =IF($G$5="","",IFERROR(_xlfn.MAXIFS(SAISIE!$E$5:$E$504,SAISIE!$B$5:$B$504,"*Vent Av./Arr.*",SAISIE!$F$5:$F$504,$G$5),"-")) -> 815 | E12: (soulevement)
A13: Vent Arr./Av maxi | B13: =IF($G$5="","",IFERROR(IF(_xlfn.MINIFS(SAISIE!$E$5:$E$504,SAISIE!$B$5:$B$504,"*Vent Arr./Av.*",SAISIE!$F$5:$F$504,$G$5)>=0,_xlfn.MAXIFS(SAISIE!$C$5:$C$504,SAISIE!$B$5:$B$504,"*Vent Arr./Av.*",SAISIE!$F$5:$F$504,$G$5),INDEX(SAISIE!$C$5:$C$504,MATCH(_xlfn.MINIFS(SAISIE!$E$5:$E$504,SAISIE!$B$5:$B$504,"*Vent Arr./Av.*",SAISIE!$F$5:$F$504,$G$5),SAISIE!$E$5:$E$504,0))),"-")) -> -37 | C13: =IF($G$5="","",IFERROR(IF(_xlfn.MINIFS(SAISIE!$E$5:$E$504,SAISIE!$B$5:$B$504,"*Vent Arr./Av.*",SAISIE!$F$5:$F$504,$G$5)>=0,INDEX(SAISIE!$D$5:$D$504,MATCH(_xlfn.MAXIFS(SAISIE!$C$5:$C$504,SAISIE!$B$5:$B$504,"*Vent Arr./Av.*",SAISIE!$F$5:$F$504,$G$5),SAISIE!$C$5:$C$504,0)),INDEX(SAISIE!$D$5:$D$504,MATCH(_xlfn.MINIFS(SAISIE!$E$5:$E$504,SAISIE!$B$5:$B$504,"*Vent Arr./Av.*",SAISIE!$F$5:$F$504,$G$5),SAISIE!$E$5:$E$504,0))),"-")) -> -11 | D13: =IF($G$5="","",IFERROR(IF(_xlfn.MINIFS(SAISIE!$E$5:$E$504,SAISIE!$B$5:$B$504,"*Vent Arr./Av.*",SAISIE!$F$5:$F$504,$G$5)>=0,0,_xlfn.MINIFS(SAISIE!$E$5:$E$504,SAISIE!$B$5:$B$504,"*Vent Arr./Av.*",SAISIE!$F$5:$F$504,$G$5)),"-")) -> 0 | E13: (compression)
A14: Vent Arr./Av mini | B14: =IF($G$5="","",IFERROR(INDEX(SAISIE!$C$5:$C$504,MATCH(_xlfn.MAXIFS(SAISIE!$E$5:$E$504,SAISIE!$B$5:$B$504,"*Vent Arr./Av.*",SAISIE!$F$5:$F$504,$G$5),SAISIE!$E$5:$E$504,0)),"-")) -> -105 | C14: =IF($G$5="","",IFERROR(INDEX(SAISIE!$D$5:$D$504,MATCH(_xlfn.MAXIFS(SAISIE!$E$5:$E$504,SAISIE!$B$5:$B$504,"*Vent Arr./Av.*",SAISIE!$F$5:$F$504,$G$5),SAISIE!$E$5:$E$504,0)),"-")) -> 0 | D14: =IF($G$5="","",IFERROR(_xlfn.MAXIFS(SAISIE!$E$5:$E$504,SAISIE!$B$5:$B$504,"*Vent Arr./Av.*",SAISIE!$F$5:$F$504,$G$5),"-")) -> 400 | E14: (soulevement)
A15: Neige normale | B15: =IF($G$5="","",IFERROR(INDEX(SAISIE!$C$5:$C$504,MATCH(_xlfn.MINIFS(SAISIE!$E$5:$E$504,SAISIE!$B$5:$B$504,"*Neige*",SAISIE!$B$5:$B$504,"<>*accidentel*",SAISIE!$F$5:$F$504,$G$5),SAISIE!$E$5:$E$504,0)),"-")) -> -113 | C15: =IF($G$5="","",IFERROR(INDEX(SAISIE!$D$5:$D$504,MATCH(_xlfn.MINIFS(SAISIE!$E$5:$E$504,SAISIE!$B$5:$B$504,"*Neige*",SAISIE!$B$5:$B$504,"<>*accidentel*",SAISIE!$F$5:$F$504,$G$5),SAISIE!$E$5:$E$504,0)),"-")) -> 0 | D15: =IF($G$5="","",IFERROR(INDEX(SAISIE!$E$5:$E$504,MATCH(_xlfn.MINIFS(SAISIE!$E$5:$E$504,SAISIE!$B$5:$B$504,"*Neige*",SAISIE!$B$5:$B$504,"<>*accidentel*",SAISIE!$F$5:$F$504,$G$5),SAISIE!$E$5:$E$504,0)),"-")) -> -1010
A16: Neige accidentelle | B16: =IF($G$5="","",IFERROR(LOOKUP(2,1/((SAISIE!$F$5:$F$504=$G$5)*(ISNUMBER(SEARCH("accidentel",SAISIE!$B$5:$B$504)))),SAISIE!$C$5:$C$504),"-")) -> -251 | C16: =IF($G$5="","",IFERROR(LOOKUP(2,1/((SAISIE!$F$5:$F$504=$G$5)*(ISNUMBER(SEARCH("accidentel",SAISIE!$B$5:$B$504)))),SAISIE!$D$5:$D$504),"-")) -> 0 | D16: =IF($G$5="","",IFERROR(LOOKUP(2,1/((SAISIE!$F$5:$F$504=$G$5)*(ISNUMBER(SEARCH("accidentel",SAISIE!$B$5:$B$504)))),SAISIE!$E$5:$E$504),"-")) -> -2244
A17: =IF($G$17="","","Noeud "&$G$17) | G17: =IFERROR(INDEX(SAISIE!$F$5:$F$504,_xlfn.AGGREGATE(15,6,ROW(SAISIE!$F$5:$F$504)-ROW(SAISIE!$F$5)+1/(SAISIE!$F$5:$F$504<>"")/(COUNTIF($G$4:G16,SAISIE!$F$5:$F$504)=0),1)),"")
A18: Couverture | B18: =IF($G$17="","",IFERROR(IFERROR(LOOKUP(2,1/((SAISIE!$F$5:$F$504=$G$17)*(LEFT(SAISIE!$B$5:$B$504,2)="G ")),SAISIE!$C$5:$C$504),LOOKUP(2,1/((SAISIE!$F$5:$F$504=$G$17)*(ISNUMBER(SEARCH("Couverture",SAISIE!$B$5:$B$504)))),SAISIE!$C$5:$C$504)),"-")) | C18: =IF($G$17="","",IFERROR(IFERROR(LOOKUP(2,1/((SAISIE!$F$5:$F$504=$G$17)*(LEFT(SAISIE!$B$5:$B$504,2)="G ")),SAISIE!$D$5:$D$504),LOOKUP(2,1/((SAISIE!$F$5:$F$504=$G$17)*(ISNUMBER(SEARCH("Couverture",SAISIE!$B$5:$B$504)))),SAISIE!$D$5:$D$504)),"-")) | D18: =IF($G$17="","",IFERROR(IFERROR(LOOKUP(2,1/((SAISIE!$F$5:$F$504=$G$17)*(LEFT(SAISIE!$B$5:$B$504,2)="G ")),SAISIE!$E$5:$E$504),LOOKUP(2,1/((SAISIE!$F$5:$F$504=$G$17)*(ISNUMBER(SEARCH("Couverture",SAISIE!$B$5:$B$504)))),SAISIE!$E$5:$E$504)),"-"))
A19: Vent G/D maxi | B19: =IF($G$17="","",IFERROR(IF(_xlfn.MINIFS(SAISIE!$E$5:$E$504,SAISIE!$B$5:$B$504,"*Vent G/D*",SAISIE!$F$5:$F$504,$G$17)>=0,_xlfn.MAXIFS(SAISIE!$C$5:$C$504,SAISIE!$B$5:$B$504,"*Vent G/D*",SAISIE!$F$5:$F$504,$G$17),INDEX(SAISIE!$C$5:$C$504,MATCH(_xlfn.MINIFS(SAISIE!$E$5:$E$504,SAISIE!$B$5:$B$504,"*Vent G/D*",SAISIE!$F$5:$F$504,$G$17),SAISIE!$E$5:$E$504,0))),"-")) | C19: =IF($G$17="","",IFERROR(IF(_xlfn.MINIFS(SAISIE!$E$5:$E$504,SAISIE!$B$5:$B$504,"*Vent G/D*",SAISIE!$F$5:$F$504,$G$17)>=0,INDEX(SAISIE!$D$5:$D$504,MATCH(_xlfn.MAXIFS(SAISIE!$C$5:$C$504,SAISIE!$B$5:$B$504,"*Vent G/D*",SAISIE!$F$5:$F$504,$G$17),SAISIE!$C$5:$C$504,0)),INDEX(SAISIE!$D$5:$D$504,MATCH(_xlfn.MINIFS(SAISIE!$E$5:$E$504,SAISIE!$B$5:$B$504,"*Vent G/D*",SAISIE!$F$5:$F$504,$G$17),SAISIE!$E$5:$E$504,0))),"-")) | D19: =IF($G$17="","",IFERROR(IF(_xlfn.MINIFS(SAISIE!$E$5:$E$504,SAISIE!$B$5:$B$504,"*Vent G/D*",SAISIE!$F$5:$F$504,$G$17)>=0,0,_xlfn.MINIFS(SAISIE!$E$5:$E$504,SAISIE!$B$5:$B$504,"*Vent G/D*",SAISIE!$F$5:$F$504,$G$17)),"-")) | E19: (compression)
A20: Vent G/D mini | B20: =IF($G$17="","",IFERROR(INDEX(SAISIE!$C$5:$C$504,MATCH(_xlfn.MAXIFS(SAISIE!$E$5:$E$504,SAISIE!$B$5:$B$504,"*Vent G/D*",SAISIE!$F$5:$F$504,$G$17),SAISIE!$E$5:$E$504,0)),"-")) | C20: =IF($G$17="","",IFERROR(INDEX(SAISIE!$D$5:$D$504,MATCH(_xlfn.MAXIFS(SAISIE!$E$5:$E$504,SAISIE!$B$5:$B$504,"*Vent G/D*",SAISIE!$F$5:$F$504,$G$17),SAISIE!$E$5:$E$504,0)),"-")) | D20: =IF($G$17="","",IFERROR(_xlfn.MAXIFS(SAISIE!$E$5:$E$504,SAISIE!$B$5:$B$504,"*Vent G/D*",SAISIE!$F$5:$F$504,$G$17),"-")) | E20: (soulevement)
A21: Vent D/ G maxi | B21: =IF($G$17="","",IFERROR(IF(_xlfn.MINIFS(SAISIE!$E$5:$E$504,SAISIE!$B$5:$B$504,"*Vent D/G*",SAISIE!$F$5:$F$504,$G$17)>=0,_xlfn.MAXIFS(SAISIE!$C$5:$C$504,SAISIE!$B$5:$B$504,"*Vent D/G*",SAISIE!$F$5:$F$504,$G$17),INDEX(SAISIE!$C$5:$C$504,MATCH(_xlfn.MINIFS(SAISIE!$E$5:$E$504,SAISIE!$B$5:$B$504,"*Vent D/G*",SAISIE!$F$5:$F$504,$G$17),SAISIE!$E$5:$E$504,0))),"-")) | C21: =IF($G$17="","",IFERROR(IF(_xlfn.MINIFS(SAISIE!$E$5:$E$504,SAISIE!$B$5:$B$504,"*Vent D/G*",SAISIE!$F$5:$F$504,$G$17)>=0,INDEX(SAISIE!$D$5:$D$504,MATCH(_xlfn.MAXIFS(SAISIE!$C$5:$C$504,SAISIE!$B$5:$B$504,"*Vent D/G*",SAISIE!$F$5:$F$504,$G$17),SAISIE!$C$5:$C$504,0)),INDEX(SAISIE!$D$5:$D$504,MATCH(_xlfn.MINIFS(SAISIE!$E$5:$E$504,SAISIE!$B$5:$B$504,"*Vent D/G*",SAISIE!$F$5:$F$504,$G$17),SAISIE!$E$5:$E$504,0))),"-")) | D21: =IF($G$17="","",IFERROR(IF(_xlfn.MINIFS(SAISIE!$E$5:$E$504,SAISIE!$B$5:$B$504,"*Vent D/G*",SAISIE!$F$5:$F$504,$G$17)>=0,0,_xlfn.MINIFS(SAISIE!$E$5:$E$504,SAISIE!$B$5:$B$504,"*Vent D/G*",SAISIE!$F$5:$F$504,$G$17)),"-")) | E21: (compression)
A22: Vent D/G mini | B22: =IF($G$17="","",IFERROR(INDEX(SAISIE!$C$5:$C$504,MATCH(_xlfn.MAXIFS(SAISIE!$E$5:$E$504,SAISIE!$B$5:$B$504,"*Vent D/G*",SAISIE!$F$5:$F$504,$G$17),SAISIE!$E$5:$E$504,0)),"-")) | C22: =IF($G$17="","",IFERROR(INDEX(SAISIE!$D$5:$D$504,MATCH(_xlfn.MAXIFS(SAISIE!$E$5:$E$504,SAISIE!$B$5:$B$504,"*Vent D/G*",SAISIE!$F$5:$F$504,$G$17),SAISIE!$E$5:$E$504,0)),"-")) | D22: =IF($G$17="","",IFERROR(_xlfn.MAXIFS(SAISIE!$E$5:$E$504,SAISIE!$B$5:$B$504,"*Vent D/G*",SAISIE!$F$5:$F$504,$G$17),"-")) | E22: (soulevement)
A23: Vent Av./Arr. maxi | B23: =IF($G$17="","",IFERROR(IF(_xlfn.MINIFS(SAISIE!$E$5:$E$504,SAISIE!$B$5:$B$504,"*Vent Av./Arr.*",SAISIE!$F$5:$F$504,$G$17)>=0,_xlfn.MAXIFS(SAISIE!$C$5:$C$504,SAISIE!$B$5:$B$504,"*Vent Av./Arr.*",SAISIE!$F$5:$F$504,$G$17),INDEX(SAISIE!$C$5:$C$504,MATCH(_xlfn.MINIFS(SAISIE!$E$5:$E$504,SAISIE!$B$5:$B$504,"*Vent Av./Arr.*",SAISIE!$F$5:$F$504,$G$17),SAISIE!$E$5:$E$504,0))),"-")) | C23: =IF($G$17="","",IFERROR(IF(_xlfn.MINIFS(SAISIE!$E$5:$E$504,SAISIE!$B$5:$B$504,"*Vent Av./Arr.*",SAISIE!$F$5:$F$504,$G$17)>=0,INDEX(SAISIE!$D$5:$D$504,MATCH(_xlfn.MAXIFS(SAISIE!$C$5:$C$504,SAISIE!$B$5:$B$504,"*Vent Av./Arr.*",SAISIE!$F$5:$F$504,$G$17),SAISIE!$C$5:$C$504,0)),INDEX(SAISIE!$D$5:$D$504,MATCH(_xlfn.MINIFS(SAISIE!$E$5:$E$504,SAISIE!$B$5:$B$504,"*Vent Av./Arr.*",SAISIE!$F$5:$F$504,$G$17),SAISIE!$E$5:$E$504,0))),"-")) | D23: =IF($G$17="","",IFERROR(IF(_xlfn.MINIFS(SAISIE!$E$5:$E$504,SAISIE!$B$5:$B$504,"*Vent Av./Arr.*",SAISIE!$F$5:$F$504,$G$17)>=0,0,_xlfn.MINIFS(SAISIE!$E$5:$E$504,SAISIE!$B$5:$B$504,"*Vent Av./Arr.*",SAISIE!$F$5:$F$504,$G$17)),"-")) | E23: (compression)
A24: Vent Av./Arr. mini | B24: =IF($G$17="","",IFERROR(INDEX(SAISIE!$C$5:$C$504,MATCH(_xlfn.MAXIFS(SAISIE!$E$5:$E$504,SAISIE!$B$5:$B$504,"*Vent Av./Arr.*",SAISIE!$F$5:$F$504,$G$17),SAISIE!$E$5:$E$504,0)),"-")) | C24: =IF($G$17="","",IFERROR(INDEX(SAISIE!$D$5:$D$504,MATCH(_xlfn.MAXIFS(SAISIE!$E$5:$E$504,SAISIE!$B$5:$B$504,"*Vent Av./Arr.*",SAISIE!$F$5:$F$504,$G$17),SAISIE!$E$5:$E$504,0)),"-")) | D24: =IF($G$17="","",IFERROR(_xlfn.MAXIFS(SAISIE!$E$5:$E$504,SAISIE!$B$5:$B$504,"*Vent Av./Arr.*",SAISIE!$F$5:$F$504,$G$17),"-")) | E24: (soulevement)
A25: Vent Arr./Av maxi | B25: =IF($G$17="","",IFERROR(IF(_xlfn.MINIFS(SAISIE!$E$5:$E$504,SAISIE!$B$5:$B$504,"*Vent Arr./Av.*",SAISIE!$F$5:$F$504,$G$17)>=0,_xlfn.MAXIFS(SAISIE!$C$5:$C$504,SAISIE!$B$5:$B$504,"*Vent Arr./Av.*",SAISIE!$F$5:$F$504,$G$17),INDEX(SAISIE!$C$5:$C$504,MATCH(_xlfn.MINIFS(SAISIE!$E$5:$E$504,SAISIE!$B$5:$B$504,"*Vent Arr./Av.*",SAISIE!$F$5:$F$504,$G$17),SAISIE!$E$5:$E$504,0))),"-")) | C25: =IF($G$17="","",IFERROR(IF(_xlfn.MINIFS(SAISIE!$E$5:$E$504,SAISIE!$B$5:$B$504,"*Vent Arr./Av.*",SAISIE!$F$5:$F$504,$G$17)>=0,INDEX(SAISIE!$D$5:$D$504,MATCH(_xlfn.MAXIFS(SAISIE!$C$5:$C$504,SAISIE!$B$5:$B$504,"*Vent Arr./Av.*",SAISIE!$F$5:$F$504,$G$17),SAISIE!$C$5:$C$504,0)),INDEX(SAISIE!$D$5:$D$504,MATCH(_xlfn.MINIFS(SAISIE!$E$5:$E$504,SAISIE!$B$5:$B$504,"*Vent Arr./Av.*",SAISIE!$F$5:$F$504,$G$17),SAISIE!$E$5:$E$504,0))),"-")) | D25: =IF($G$17="","",IFERROR(IF(_xlfn.MINIFS(SAISIE!$E$5:$E$504,SAISIE!$B$5:$B$504,"*Vent Arr./Av.*",SAISIE!$F$5:$F$504,$G$17)>=0,0,_xlfn.MINIFS(SAISIE!$E$5:$E$504,SAISIE!$B$5:$B$504,"*Vent Arr./Av.*",SAISIE!$F$5:$F$504,$G$17)),"-")) | E25: (compression)
A26: Vent Arr./Av mini | B26: =IF($G$17="","",IFERROR(INDEX(SAISIE!$C$5:$C$504,MATCH(_xlfn.MAXIFS(SAISIE!$E$5:$E$504,SAISIE!$B$5:$B$504,"*Vent Arr./Av.*",SAISIE!$F$5:$F$504,$G$17),SAISIE!$E$5:$E$504,0)),"-")) | C26: =IF($G$17="","",IFERROR(INDEX(SAISIE!$D$5:$D$504,MATCH(_xlfn.MAXIFS(SAISIE!$E$5:$E$504,SAISIE!$B$5:$B$504,"*Vent Arr./Av.*",SAISIE!$F$5:$F$504,$G$17),SAISIE!$E$5:$E$504,0)),"-")) | D26: =IF($G$17="","",IFERROR(_xlfn.MAXIFS(SAISIE!$E$5:$E$504,SAISIE!$B$5:$B$504,"*Vent Arr./Av.*",SAISIE!$F$5:$F$504,$G$17),"-")) | E26: (soulevement)
A27: Neige normale | B27: =IF($G$17="","",IFERROR(INDEX(SAISIE!$C$5:$C$504,MATCH(_xlfn.MINIFS(SAISIE!$E$5:$E$504,SAISIE!$B$5:$B$504,"*Neige*",SAISIE!$B$5:$B$504,"<>*accidentel*",SAISIE!$F$5:$F$504,$G$17),SAISIE!$E$5:$E$504,0)),"-")) | C27: =IF($G$17="","",IFERROR(INDEX(SAISIE!$D$5:$D$504,MATCH(_xlfn.MINIFS(SAISIE!$E$5:$E$504,SAISIE!$B$5:$B$504,"*Neige*",SAISIE!$B$5:$B$504,"<>*accidentel*",SAISIE!$F$5:$F$504,$G$17),SAISIE!$E$5:$E$504,0)),"-")) | D27: =IF($G$17="","",IFERROR(INDEX(SAISIE!$E$5:$E$504,MATCH(_xlfn.MINIFS(SAISIE!$E$5:$E$504,SAISIE!$B$5:$B$504,"*Neige*",SAISIE!$B$5:$B$504,"<>*accidentel*",SAISIE!$F$5:$F$504,$G$17),SAISIE!$E$5:$E$504,0)),"-"))
A28: Neige accidentelle | B28: =IF($G$17="","",IFERROR(LOOKUP(2,1/((SAISIE!$F$5:$F$504=$G$17)*(ISNUMBER(SEARCH("accidentel",SAISIE!$B$5:$B$504)))),SAISIE!$C$5:$C$504),"-")) | C28: =IF($G$17="","",IFERROR(LOOKUP(2,1/((SAISIE!$F$5:$F$504=$G$17)*(ISNUMBER(SEARCH("accidentel",SAISIE!$B$5:$B$504)))),SAISIE!$D$5:$D$504),"-")) | D28: =IF($G$17="","",IFERROR(LOOKUP(2,1/((SAISIE!$F$5:$F$504=$G$17)*(ISNUMBER(SEARCH("accidentel",SAISIE!$B$5:$B$504)))),SAISIE!$E$5:$E$504),"-"))
A29: =IF($G$29="","","Noeud "&$G$29) | G29: =IFERROR(INDEX(SAISIE!$F$5:$F$504,_xlfn.AGGREGATE(15,6,ROW(SAISIE!$F$5:$F$504)-ROW(SAISIE!$F$5)+1/(SAISIE!$F$5:$F$504<>"")/(COUNTIF($G$4:G28,SAISIE!$F$5:$F$504)=0),1)),"")
A30: Couverture | B30: =IF($G$29="","",IFERROR(IFERROR(LOOKUP(2,1/((SAISIE!$F$5:$F$504=$G$29)*(LEFT(SAISIE!$B$5:$B$504,2)="G ")),SAISIE!$C$5:$C$504),LOOKUP(2,1/((SAISIE!$F$5:$F$504=$G$29)*(ISNUMBER(SEARCH("Couverture",SAISIE!$B$5:$B$504)))),SAISIE!$C$5:$C$504)),"-")) | C30: =IF($G$29="","",IFERROR(IFERROR(LOOKUP(2,1/((SAISIE!$F$5:$F$504=$G$29)*(LEFT(SAISIE!$B$5:$B$504,2)="G ")),SAISIE!$D$5:$D$504),LOOKUP(2,1/((SAISIE!$F$5:$F$504=$G$29)*(ISNUMBER(SEARCH("Couverture",SAISIE!$B$5:$B$504)))),SAISIE!$D$5:$D$504)),"-")) | D30: =IF($G$29="","",IFERROR(IFERROR(LOOKUP(2,1/((SAISIE!$F$5:$F$504=$G$29)*(LEFT(SAISIE!$B$5:$B$504,2)="G ")),SAISIE!$E$5:$E$504),LOOKUP(2,1/((SAISIE!$F$5:$F$504=$G$29)*(ISNUMBER(SEARCH("Couverture",SAISIE!$B$5:$B$504)))),SAISIE!$E$5:$E$504)),"-"))
A31: Vent G/D maxi | B31: =IF($G$29="","",IFERROR(IF(_xlfn.MINIFS(SAISIE!$E$5:$E$504,SAISIE!$B$5:$B$504,"*Vent G/D*",SAISIE!$F$5:$F$504,$G$29)>=0,_xlfn.MAXIFS(SAISIE!$C$5:$C$504,SAISIE!$B$5:$B$504,"*Vent G/D*",SAISIE!$F$5:$F$504,$G$29),INDEX(SAISIE!$C$5:$C$504,MATCH(_xlfn.MINIFS(SAISIE!$E$5:$E$504,SAISIE!$B$5:$B$504,"*Vent G/D*",SAISIE!$F$5:$F$504,$G$29),SAISIE!$E$5:$E$504,0))),"-")) | C31: =IF($G$29="","",IFERROR(IF(_xlfn.MINIFS(SAISIE!$E$5:$E$504,SAISIE!$B$5:$B$504,"*Vent G/D*",SAISIE!$F$5:$F$504,$G$29)>=0,INDEX(SAISIE!$D$5:$D$504,MATCH(_xlfn.MAXIFS(SAISIE!$C$5:$C$504,SAISIE!$B$5:$B$504,"*Vent G/D*",SAISIE!$F$5:$F$504,$G$29),SAISIE!$C$5:$C$504,0)),INDEX(SAISIE!$D$5:$D$504,MATCH(_xlfn.MINIFS(SAISIE!$E$5:$E$504,SAISIE!$B$5:$B$504,"*Vent G/D*",SAISIE!$F$5:$F$504,$G$29),SAISIE!$E$5:$E$504,0))),"-")) | D31: =IF($G$29="","",IFERROR(IF(_xlfn.MINIFS(SAISIE!$E$5:$E$504,SAISIE!$B$5:$B$504,"*Vent G/D*",SAISIE!$F$5:$F$504,$G$29)>=0,0,_xlfn.MINIFS(SAISIE!$E$5:$E$504,SAISIE!$B$5:$B$504,"*Vent G/D*",SAISIE!$F$5:$F$504,$G$29)),"-")) | E31: (compression)
A32: Vent G/D mini | B32: =IF($G$29="","",IFERROR(INDEX(SAISIE!$C$5:$C$504,MATCH(_xlfn.MAXIFS(SAISIE!$E$5:$E$504,SAISIE!$B$5:$B$504,"*Vent G/D*",SAISIE!$F$5:$F$504,$G$29),SAISIE!$E$5:$E$504,0)),"-")) | C32: =IF($G$29="","",IFERROR(INDEX(SAISIE!$D$5:$D$504,MATCH(_xlfn.MAXIFS(SAISIE!$E$5:$E$504,SAISIE!$B$5:$B$504,"*Vent G/D*",SAISIE!$F$5:$F$504,$G$29),SAISIE!$E$5:$E$504,0)),"-")) | D32: =IF($G$29="","",IFERROR(_xlfn.MAXIFS(SAISIE!$E$5:$E$504,SAISIE!$B$5:$B$504,"*Vent G/D*",SAISIE!$F$5:$F$504,$G$29),"-")) | E32: (soulevement)
A33: Vent D/ G maxi | B33: =IF($G$29="","",IFERROR(IF(_xlfn.MINIFS(SAISIE!$E$5:$E$504,SAISIE!$B$5:$B$504,"*Vent D/G*",SAISIE!$F$5:$F$504,$G$29)>=0,_xlfn.MAXIFS(SAISIE!$C$5:$C$504,SAISIE!$B$5:$B$504,"*Vent D/G*",SAISIE!$F$5:$F$504,$G$29),INDEX(SAISIE!$C$5:$C$504,MATCH(_xlfn.MINIFS(SAISIE!$E$5:$E$504,SAISIE!$B$5:$B$504,"*Vent D/G*",SAISIE!$F$5:$F$504,$G$29),SAISIE!$E$5:$E$504,0))),"-")) | C33: =IF($G$29="","",IFERROR(IF(_xlfn.MINIFS(SAISIE!$E$5:$E$504,SAISIE!$B$5:$B$504,"*Vent D/G*",SAISIE!$F$5:$F$504,$G$29)>=0,INDEX(SAISIE!$D$5:$D$504,MATCH(_xlfn.MAXIFS(SAISIE!$C$5:$C$504,SAISIE!$B$5:$B$504,"*Vent D/G*",SAISIE!$F$5:$F$504,$G$29),SAISIE!$C$5:$C$504,0)),INDEX(SAISIE!$D$5:$D$504,MATCH(_xlfn.MINIFS(SAISIE!$E$5:$E$504,SAISIE!$B$5:$B$504,"*Vent D/G*",SAISIE!$F$5:$F$504,$G$29),SAISIE!$E$5:$E$504,0))),"-")) | D33: =IF($G$29="","",IFERROR(IF(_xlfn.MINIFS(SAISIE!$E$5:$E$504,SAISIE!$B$5:$B$504,"*Vent D/G*",SAISIE!$F$5:$F$504,$G$29)>=0,0,_xlfn.MINIFS(SAISIE!$E$5:$E$504,SAISIE!$B$5:$B$504,"*Vent D/G*",SAISIE!$F$5:$F$504,$G$29)),"-")) | E33: (compression)
A34: Vent D/G mini | B34: =IF($G$29="","",IFERROR(INDEX(SAISIE!$C$5:$C$504,MATCH(_xlfn.MAXIFS(SAISIE!$E$5:$E$504,SAISIE!$B$5:$B$504,"*Vent D/G*",SAISIE!$F$5:$F$504,$G$29),SAISIE!$E$5:$E$504,0)),"-")) | C34: =IF($G$29="","",IFERROR(INDEX(SAISIE!$D$5:$D$504,MATCH(_xlfn.MAXIFS(SAISIE!$E$5:$E$504,SAISIE!$B$5:$B$504,"*Vent D/G*",SAISIE!$F$5:$F$504,$G$29),SAISIE!$E$5:$E$504,0)),"-")) | D34: =IF($G$29="","",IFERROR(_xlfn.MAXIFS(SAISIE!$E$5:$E$504,SAISIE!$B$5:$B$504,"*Vent D/G*",SAISIE!$F$5:$F$504,$G$29),"-")) | E34: (soulevement)
A35: Vent Av./Arr. maxi | B35: =IF($G$29="","",IFERROR(IF(_xlfn.MINIFS(SAISIE!$E$5:$E$504,SAISIE!$B$5:$B$504,"*Vent Av./Arr.*",SAISIE!$F$5:$F$504,$G$29)>=0,_xlfn.MAXIFS(SAISIE!$C$5:$C$504,SAISIE!$B$5:$B$504,"*Vent Av./Arr.*",SAISIE!$F$5:$F$504,$G$29),INDEX(SAISIE!$C$5:$C$504,MATCH(_xlfn.MINIFS(SAISIE!$E$5:$E$504,SAISIE!$B$5:$B$504,"*Vent Av./Arr.*",SAISIE!$F$5:$F$504,$G$29),SAISIE!$E$5:$E$504,0))),"-")) | C35: =IF($G$29="","",IFERROR(IF(_xlfn.MINIFS(SAISIE!$E$5:$E$504,SAISIE!$B$5:$B$504,"*Vent Av./Arr.*",SAISIE!$F$5:$F$504,$G$29)>=0,INDEX(SAISIE!$D$5:$D$504,MATCH(_xlfn.MAXIFS(SAISIE!$C$5:$C$504,SAISIE!$B$5:$B$504,"*Vent Av./Arr.*",SAISIE!$F$5:$F$504,$G$29),SAISIE!$C$5:$C$504,0)),INDEX(SAISIE!$D$5:$D$504,MATCH(_xlfn.MINIFS(SAISIE!$E$5:$E$504,SAISIE!$B$5:$B$504,"*Vent Av./Arr.*",SAISIE!$F$5:$F$504,$G$29),SAISIE!$E$5:$E$504,0))),"-")) | D35: =IF($G$29="","",IFERROR(IF(_xlfn.MINIFS(SAISIE!$E$5:$E$504,SAISIE!$B$5:$B$504,"*Vent Av./Arr.*",SAISIE!$F$5:$F$504,$G$29)>=0,0,_xlfn.MINIFS(SAISIE!$E$5:$E$504,SAISIE!$B$5:$B$504,"*Vent Av./Arr.*",SAISIE!$F$5:$F$504,$G$29)),"-")) | E35: (compression)
A36: Vent Av./Arr. mini | B36: =IF($G$29="","",IFERROR(INDEX(SAISIE!$C$5:$C$504,MATCH(_xlfn.MAXIFS(SAISIE!$E$5:$E$504,SAISIE!$B$5:$B$504,"*Vent Av./Arr.*",SAISIE!$F$5:$F$504,$G$29),SAISIE!$E$5:$E$504,0)),"-")) | C36: =IF($G$29="","",IFERROR(INDEX(SAISIE!$D$5:$D$504,MATCH(_xlfn.MAXIFS(SAISIE!$E$5:$E$504,SAISIE!$B$5:$B$504,"*Vent Av./Arr.*",SAISIE!$F$5:$F$504,$G$29),SAISIE!$E$5:$E$504,0)),"-")) | D36: =IF($G$29="","",IFERROR(_xlfn.MAXIFS(SAISIE!$E$5:$E$504,SAISIE!$B$5:$B$504,"*Vent Av./Arr.*",SAISIE!$F$5:$F$504,$G$29),"-")) | E36: (soulevement)
A37: Vent Arr./Av maxi | B37: =IF($G$29="","",IFERROR(IF(_xlfn.MINIFS(SAISIE!$E$5:$E$504,SAISIE!$B$5:$B$504,"*Vent Arr./Av.*",SAISIE!$F$5:$F$504,$G$29)>=0,_xlfn.MAXIFS(SAISIE!$C$5:$C$504,SAISIE!$B$5:$B$504,"*Vent Arr./Av.*",SAISIE!$F$5:$F$504,$G$29),INDEX(SAISIE!$C$5:$C$504,MATCH(_xlfn.MINIFS(SAISIE!$E$5:$E$504,SAISIE!$B$5:$B$504,"*Vent Arr./Av.*",SAISIE!$F$5:$F$504,$G$29),SAISIE!$E$5:$E$504,0))),"-")) | C37: =IF($G$29="","",IFERROR(IF(_xlfn.MINIFS(SAISIE!$E$5:$E$504,SAISIE!$B$5:$B$504,"*Vent Arr./Av.*",SAISIE!$F$5:$F$504,$G$29)>=0,INDEX(SAISIE!$D$5:$D$504,MATCH(_xlfn.MAXIFS(SAISIE!$C$5:$C$504,SAISIE!$B$5:$B$504,"*Vent Arr./Av.*",SAISIE!$F$5:$F$504,$G$29),SAISIE!$C$5:$C$504,0)),INDEX(SAISIE!$D$5:$D$504,MATCH(_xlfn.MINIFS(SAISIE!$E$5:$E$504,SAISIE!$B$5:$B$504,"*Vent Arr./Av.*",SAISIE!$F$5:$F$504,$G$29),SAISIE!$E$5:$E$504,0))),"-")) | D37: =IF($G$29="","",IFERROR(IF(_xlfn.MINIFS(SAISIE!$E$5:$E$504,SAISIE!$B$5:$B$504,"*Vent Arr./Av.*",SAISIE!$F$5:$F$504,$G$29)>=0,0,_xlfn.MINIFS(SAISIE!$E$5:$E$504,SAISIE!$B$5:$B$504,"*Vent Arr./Av.*",SAISIE!$F$5:$F$504,$G$29)),"-")) | E37: (compression)
A38: Vent Arr./Av mini | B38: =IF($G$29="","",IFERROR(INDEX(SAISIE!$C$5:$C$504,MATCH(_xlfn.MAXIFS(SAISIE!$E$5:$E$504,SAISIE!$B$5:$B$504,"*Vent Arr./Av.*",SAISIE!$F$5:$F$504,$G$29),SAISIE!$E$5:$E$504,0)),"-")) | C38: =IF($G$29="","",IFERROR(INDEX(SAISIE!$D$5:$D$504,MATCH(_xlfn.MAXIFS(SAISIE!$E$5:$E$504,SAISIE!$B$5:$B$504,"*Vent Arr./Av.*",SAISIE!$F$5:$F$504,$G$29),SAISIE!$E$5:$E$504,0)),"-")) | D38: =IF($G$29="","",IFERROR(_xlfn.MAXIFS(SAISIE!$E$5:$E$504,SAISIE!$B$5:$B$504,"*Vent Arr./Av.*",SAISIE!$F$5:$F$504,$G$29),"-")) | E38: (soulevement)
A39: Neige normale | B39: =IF($G$29="","",IFERROR(INDEX(SAISIE!$C$5:$C$504,MATCH(_xlfn.MINIFS(SAISIE!$E$5:$E$504,SAISIE!$B$5:$B$504,"*Neige*",SAISIE!$B$5:$B$504,"<>*accidentel*",SAISIE!$F$5:$F$504,$G$29),SAISIE!$E$5:$E$504,0)),"-")) | C39: =IF($G$29="","",IFERROR(INDEX(SAISIE!$D$5:$D$504,MATCH(_xlfn.MINIFS(SAISIE!$E$5:$E$504,SAISIE!$B$5:$B$504,"*Neige*",SAISIE!$B$5:$B$504,"<>*accidentel*",SAISIE!$F$5:$F$504,$G$29),SAISIE!$E$5:$E$504,0)),"-")) | D39: =IF($G$29="","",IFERROR(INDEX(SAISIE!$E$5:$E$504,MATCH(_xlfn.MINIFS(SAISIE!$E$5:$E$504,SAISIE!$B$5:$B$504,"*Neige*",SAISIE!$B$5:$B$504,"<>*accidentel*",SAISIE!$F$5:$F$504,$G$29),SAISIE!$E$5:$E$504,0)),"-"))
A40: Neige accidentelle | B40: =IF($G$29="","",IFERROR(LOOKUP(2,1/((SAISIE!$F$5:$F$504=$G$29)*(ISNUMBER(SEARCH("accidentel",SAISIE!$B$5:$B$504)))),SAISIE!$C$5:$C$504),"-")) | C40: =IF($G$29="","",IFERROR(LOOKUP(2,1/((SAISIE!$F$5:$F$504=$G$29)*(ISNUMBER(SEARCH("accidentel",SAISIE!$B$5:$B$504)))),SAISIE!$D$5:$D$504),"-")) | D40: =IF($G$29="","",IFERROR(LOOKUP(2,1/((SAISIE!$F$5:$F$504=$G$29)*(ISNUMBER(SEARCH("accidentel",SAISIE!$B$5:$B$504)))),SAISIE!$E$5:$E$504),"-"))
A41: =IF($G$41="","","Noeud "&$G$41) | G41: =IFERROR(INDEX(SAISIE!$F$5:$F$504,_xlfn.AGGREGATE(15,6,ROW(SAISIE!$F$5:$F$504)-ROW(SAISIE!$F$5)+1/(SAISIE!$F$5:$F$504<>"")/(COUNTIF($G$4:G40,SAISIE!$F$5:$F$504)=0),1)),"")
...
