Workbook

Sheet MODE EMPLOI
A1: MODE D'EMPLOI — DDC Dynamique
A4: PREREQUIS : Microsoft Excel 365 (ou Excel 2021) — verifiez cellule SYNTHESE!G4 = OK
A6: Etape 1 — SAISIE
A7: - Collez vos cas bruts dans les colonnes A a E seulement.
A8: - Format Noeud_Cas : 47/1 ou 47/ 1 (les deux fonctionnent).
A9: - Colonnes F (Noeud) et G (Famille) : ne pas modifier, calcul automatique.
A11: Etape 2 — SYNTHESE
A12: - Cellule B3 (fond rouge) : tapez le numero de noeud de vos donnees, ex: 47
A13: - Cellule F4 : liste des noeuds detectes dans vos donnees.
A14: - B4 = Oui si vous avez rempli la colonne FY (stabilite 3D).
A16: Si rien ne s'affiche :
A17: 1. Verifiez que B3 = le bon noeud (pas 6 si vos donnees sont en 47 !)
... A21: Etape 3 — RECAP : synthese de tous les noeuds en un coup d'oeil.

Sheet SAISIE
A1: 1 — SAISIE DES CAS DE CHARGE
A2: Collez UNIQUEMENT dans A-E (Noeud_Cas, Nom, FX, FY, FZ). Ne touchez pas F-G : elles se remplissent automatiquement.
A4: Noeud_Cas | B4: Nom_cas | C4: FX_daN | D4: FY_daN | E4: FZ_daN | F4: Noeud | G4: Famille
A5: 47/1 | B5: G : Couverture : PA 6 BS 10 PV15 | C5: -116 | D5: 7 | E5: -1285 | F5: =IF([@Noeud_Cas]="","",VALUE(TRIM(LEFT([@Noeud_Cas],SEARCH("/",[@Noeud_Cas]&"/")-1)))) | G5: =IF([@Nom_cas]="","",IF(OR(ISNUMBER(SEARCH("Couverture",[@Nom_cas])),LEFT([@Nom_cas],2)="G "),"COUV",IF(ISNUMBER(SEARCH("Vent G/D",[@Nom_cas])),"VGD",IF(ISNUMBER(SEARCH("Vent D/G",[@Nom_cas])),"VDG",IF(ISNUMBER(SEARCH("Vent Av./Arr.",[@Nom_cas])),"VAA",IF(ISNUMBER(SEARCH("Vent Arr./Av.",[@Nom_cas])),"VAV",IF(ISNUMBER(SEARCH("accidentel",[@Nom_cas])),"NACC",IF(ISNUMBER(SEARCH("Neige",[@Nom_cas])),"NEIGE",""))))))))
A6: 47/2 | B6: Vent G/D dep.(-) Portique 2 | C6: 905 | D6: 40 | E6: 1422
A7: 47/3 | B7: Vent G/D sur.(+) Portique 2 | C7: 900 | D7: 32 | E7: 1444
A8: 47/4 | B8: Vent D/G dep.(-) Cpe - Portique 2 | C8: -345 | D8: 5 | E8: 462
A9: 47/5 | B9: Vent D/G dep.(-) Cpe + Portique 2 | C9: -513 | D9: -11 | E9: -281
A10: 47/6 | B10: Vent D/G sur.(+) Cpe - Portique 2 | C10: -349 | D10: -2 | E10: 485
A11: 47/7 | B11: Vent D/G sur.(+) Cpe + Portique 2 | C11: -518 | D11: -22 | E11: -258
A12: 47/8 | B12: Vent Av./Arr. dep.(-) Portique 2 | C12: -241 | D12: 205 | E12: 815
A13: 47/9 | B13: Vent Av./Arr. sur.(+) Portique 2 | C13: -198 | D13: 195 | E13: 598
A14: 47/10 | B14: Vent Arr./Av. dep.(-) Portique 2 | C14: -105 | D14: 0 | E14: 400
A15: 47/11 | B15: Vent Arr./Av. sur.(+) Portique 2 | C15: -37 | D15: -11 | E15: 56
A16: 47/12 | B16: Neige cas I | C16: -113 | D16: 0 | E16: -1010
A17: 47/13 | B17: Neige cas II | C17: -56 | D17: 0 | E17: -505
A18: 47/14 | B18: Neige accidentel | C18: -251 | D18: 0 | E18: -2244

Sheet SYNTHESE
A1: 2 — SYNTHESE DYNAMIQUE
A3: Noeud selectionne : | B3: 47 | F3: Noeuds dispo. | G3: Test Excel
A4: Calcul stabilite 3D (FY) : | B4: Oui | F4: =IFERROR(UNIQUE(FILTER(VALUE(TRIM(LEFT(SAISIE!$A$5:$A$504,SEARCH("/",SAISIE!$A$5:$A$504&"/")-1))),SAISIE!$A$5:$A$504<>"")),"") | G4: =IF(ISERROR(FILTER(A1:A2,A1<>"")),"Excel 365 REQUIS","OK")
A5: => Tapez le noeud de vos donnees (ex: 47) dans la cellule jaune/rouge B3
A7: Nom du cas | B7: FX [daN] | C7: FY [daN] | D7: FZ [daN] | E7: Note
A8: Couverture | B8: =IF($B$3="","",IFERROR(LET(v,FILTER(SAISIE!$C$5:$C$504,(VALUE(TRIM(LEFT(SAISIE!$A$5:$A$504,SEARCH("/",SAISIE!$A$5:$A$504&"/")-1)))=$B$3)*(OR(ISNUMBER(SEARCH("Couverture",SAISIE!$B$5:$B$504)),LEFT(SAISIE!$B$5:$B$504,2)="G "))*(SAISIE!$E$5:$E$504<>"")),IF(COUNT(v)=0,"-",INDEX(v,1))),"-")) | C8: =IF(OR($B$3="",$B$4<>"Oui"),"",IF($B$3="","",IFERROR(LET(v,FILTER(SAISIE!$D$5:$D$504,(VALUE(TRIM(LEFT(SAISIE!$A$5:$A$504,SEARCH("/",SAISIE!$A$5:$A$504&"/")-1)))=$B$3)*(OR(ISNUMBER(SEARCH("Couverture",SAISIE!$B$5:$B$504)),LEFT(SAISIE!$B$5:$B$504,2)="G "))*(SAISIE!$E$5:$E$504<>"")),IF(COUNT(v)=0,"-",INDEX(v,1))),"-"))) | D8: =IF($B$3="","",IFERROR(LET(v,FILTER(SAISIE!$E$5:$E$504,(VALUE(TRIM(LEFT(SAISIE!$A$5:$A$504,SEARCH("/",SAISIE!$A$5:$A$504&"/")-1)))=$B$3)*(OR(ISNUMBER(SEARCH("Couverture",SAISIE!$B$5:$B$504)),LEFT(SAISIE!$B$5:$B$504,2)="G "))*(SAISIE!$E$5:$E$504<>"")),IF(COUNT(v)=0,"-",INDEX(v,1))),"-"))
A9: Vent G/D maxi | B9: =IF($B$3="","",IFERROR(LET(fx,FILTER(SAISIE!$C$5:$C$504,(VALUE(TRIM(LEFT(SAISIE!$A$5:$A$504,SEARCH("/",SAISIE!$A$5:$A$504&"/")-1)))=$B$3)*(ISNUMBER(SEARCH("Vent G/D",SAISIE!$B$5:$B$504)))*(SAISIE!$E$5:$E$504<>"")),fz,FILTER(SAISIE!$E$5:$E$504,(VALUE(TRIM(LEFT(SAISIE!$A$5:$A$504,SEARCH("/",SAISIE!$A$5:$A$504&"/")-1)))=$B$3)*(ISNUMBER(SEARCH("Vent G/D",SAISIE!$B$5:$B$504)))*(SAISIE!$E$5:$E$504<>"")),mf,MIN(fz),IF(COUNT(fz)=0,"-",IF(MIN(fz)>=0,INDEX(fx,MATCH(MAX(fx),fx,0)),INDEX(fx,MATCH(mf,fz,0))))),"-")) | C9: =IF(OR($B$3="",$B$4<>"Oui"),"",IFERROR(LET(fy,FILTER(SAISIE!$D$5:$D$504,(VALUE(TRIM(LEFT(SAISIE!$A$5:$A$504,SEARCH("/",SAISIE!$A$5:$A$504&"/")-1)))=$B$3)*(ISNUMBER(SEARCH("Vent G/D",SAISIE!$B$5:$B$504)))*(SAISIE!$E$5:$E$504<>"")),fx,FILTER(SAISIE!$C$5:$C$504,(VALUE(TRIM(LEFT(SAISIE!$A$5:$A$504,SEARCH("/",SAISIE!$A$5:$A$504&"/")-1)))=$B$3)*(ISNUMBER(SEARCH("Vent G/D",SAISIE!$B$5:$B$504)))*(SAISIE!$E$5:$E$504<>"")),fz,FILTER(SAISIE!$E$5:$E$504,(VALUE(TRIM(LEFT(SAISIE!$A$5:$A$504,SEARCH("/",SAISIE!$A$5:$A$504&"/")-1)))=$B$3)*(ISNUMBER(SEARCH("Vent G/D",SAISIE!$B$5:$B$504)))*(SAISIE!$E$5:$E$504<>"")),mf,MIN(fz),IF(COUNT(fz)=0,"-",IF(MIN(fz)>=0,INDEX(fy,MATCH(MAX(fx),fx,0)),INDEX(fy,MATCH(mf,fz,0))))),"-")) | D9: =IF($B$3="","",IFERROR(LET(fz,FILTER(SAISIE!$E$5:$E$504,(VALUE(TRIM(LEFT(SAISIE!$A$5:$A$504,SEARCH("/",SAISIE!$A$5:$A$504&"/")-1)))=$B$3)*(ISNUMBER(SEARCH("Vent G/D",SAISIE!$B$5:$B$504)))*(SAISIE!$E$5:$E$504<>"")),IF(COUNT(fz)=0,"-",IF(MIN(fz)>=0,0,MIN(fz)))),"-")) | E9: (compression)
A10: Vent G/D mini | B10: =IF($B$3="","",IFERROR(LET(fx,FILTER(SAISIE!$C$5:$C$504,(VALUE(TRIM(LEFT(SAISIE!$A$5:$A$504,SEARCH("/",SAISIE!$A$5:$A$504&"/")-1)))=$B$3)*(ISNUMBER(SEARCH("Vent G/D",SAISIE!$B$5:$B$504)))*(SAISIE!$E$5:$E$504<>"")),fz,FILTER(SAISIE!$E$5:$E$504,(VALUE(TRIM(LEFT(SAISIE!$A$5:$A$504,SEARCH("/",SAISIE!$A$5:$A$504&"/")-1)))=$B$3)*(ISNUMBER(SEARCH("Vent G/D",SAISIE!$B$5:$B$504)))*(SAISIE!$E$5:$E$504<>"")),Mf,MAX(fz),INDEX(fx,MATCH(Mf,fz,0))),"-")) | C10: =IF(OR($B$3="",$B$4<>"Oui"),"",IFERROR(LET(fy,FILTER(SAISIE!$D$5:$D$504,(VALUE(TRIM(LEFT(SAISIE!$A$5:$A$504,SEARCH("/",SAISIE!$A$5:$A$504&"/")-1)))=$B$3)*(ISNUMBER(SEARCH("Vent G/D",SAISIE!$B$5:$B$504)))*(SAISIE!$E$5:$E$504<>"")),fz,FILTER(SAISIE!$E$5:$E$504,(VALUE(TRIM(LEFT(SAISIE!$A$5:$A$504,SEARCH("/",SAISIE!$A$5:$A$504&"/")-1)))=$B$3)*(ISNUMBER(SEARCH("Vent G/D",SAISIE!$B$5:$B$504)))*(SAISIE!$E$5:$E$504<>"")),Mf,MAX(fz),INDEX(fy,MATCH(Mf,fz,0))),"-")) | D10: =IF($B$3="","",IFERROR(LET(fz,FILTER(SAISIE!$E$5:$E$504,(VALUE(TRIM(LEFT(SAISIE!$A$5:$A$504,SEARCH("/",SAISIE!$A$5:$A$504&"/")-1)))=$B$3)*(ISNUMBER(SEARCH("Vent G/D",SAISIE!$B$5:$B$504)))*(SAISIE!$E$5:$E$504<>"")),IF(COUNT(fz)=0,"-",MAX(fz))),"-")) | E10: (soulevement)
A11: Vent D/ G maxi | B11: =IF($B$3="","",IFERROR(LET(fx,FILTER(SAISIE!$C$5:$C$504,(VALUE(TRIM(LEFT(SAISIE!$A$5:$A$504,SEARCH("/",SAISIE!$A$5:$A$504&"/")-1)))=$B$3)*(ISNUMBER(SEARCH("Vent D/G",SAISIE!$B$5:$B$504)))*(SAISIE!$E$5:$E$504<>"")),fz,FILTER(SAISIE!$E$5:$E$504,(VALUE(TRIM(LEFT(SAISIE!$A$5:$A$504,SEARCH("/",SAISIE!$A$5:$A$504&"/")-1)))=$B$3)*(ISNUMBER(SEARCH("Vent D/G",SAISIE!$B$5:$B$504)))*(SAISIE!$E$5:$E$504<>"")),mf,MIN(fz),IF(COUNT(fz)=0,"-",IF(MIN(fz)>=0,INDEX(fx,MATCH(MAX(fx),fx,0)),INDEX(fx,MATCH(mf,fz,0))))),"-")) | C11: =IF(OR($B$3="",$B$4<>"Oui"),"",IFERROR(LET(fy,FILTER(SAISIE!$D$5:$D$504,(VALUE(TRIM(LEFT(SAISIE!$A$5:$A$504,SEARCH("/",SAISIE!$A$5:$A$504&"/")-1)))=$B$3)*(ISNUMBER(SEARCH("Vent D/G",SAISIE!$B$5:$B$504)))*(SAISIE!$E$5:$E$504<>"")),fx,FILTER(SAISIE!$C$5:$C$504,(VALUE(TRIM(LEFT(SAISIE!$A$5:$A$504,SEARCH("/",SAISIE!$A$5:$A$504&"/")-1)))=$B$3)*(ISNUMBER(SEARCH("Vent D/G",SAISIE!$B$5:$B$504)))*(SAISIE!$E$5:$E$504<>"")),fz,FILTER(SAISIE!$E$5:$E$504,(VALUE(TRIM(LEFT(SAISIE!$A$5:$A$504,SEARCH("/",SAISIE!$A$5:$A$504&"/")-1)))=$B$3)*(ISNUMBER(SEARCH("Vent D/G",SAISIE!$B$5:$B$504)))*(SAISIE!$E$5:$E$504<>"")),mf,MIN(fz),IF(COUNT(fz)=0,"-",IF(MIN(fz)>=0,INDEX(fy,MATCH(MAX(fx),fx,0)),INDEX(fy,MATCH(mf,fz,0))))),"-")) | D11: =IF($B$3="","",IFERROR(LET(fz,FILTER(SAISIE!$E$5:$E$504,(VALUE(TRIM(LEFT(SAISIE!$A$5:$A$504,SEARCH("/",SAISIE!$A$5:$A$504&"/")-1)))=$B$3)*(ISNUMBER(SEARCH("Vent D/G",SAISIE!$B$5:$B$504)))*(SAISIE!$E$5:$E$504<>"")),IF(COUNT(fz)=0,"-",IF(MIN(fz)>=0,0,MIN(fz)))),"-")) | E11: (compression)
A12: Vent D/G mini | B12: =IF($B$3="","",IFERROR(LET(fx,FILTER(SAISIE!$C$5:$C$504,(VALUE(TRIM(LEFT(SAISIE!$A$5:$A$504,SEARCH("/",SAISIE!$A$5:$A$504&"/")-1)))=$B$3)*(ISNUMBER(SEARCH("Vent D/G",SAISIE!$B$5:$B$504)))*(SAISIE!$E$5:$E$504<>"")),fz,FILTER(SAISIE!$E$5:$E$504,(VALUE(TRIM(LEFT(SAISIE!$A$5:$A$504,SEARCH("/",SAISIE!$A$5:$A$504&"/")-1)))=$B$3)*(ISNUMBER(SEARCH("Vent D/G",SAISIE!$B$5:$B$504)))*(SAISIE!$E$5:$E$504<>"")),Mf,MAX(fz),INDEX(fx,MATCH(Mf,fz,0))),"-")) | C12: =IF(OR($B$3="",$B$4<>"Oui"),"",IFERROR(LET(fy,FILTER(SAISIE!$D$5:$D$504,(VALUE(TRIM(LEFT(SAISIE!$A$5:$A$504,SEARCH("/",SAISIE!$A$5:$A$504&"/")-1)))=$B$3)*(ISNUMBER(SEARCH("Vent D/G",SAISIE!$B$5:$B$504)))*(SAISIE!$E$5:$E$504<>"")),fz,FILTER(SAISIE!$E$5:$E$504,(VALUE(TRIM(LEFT(SAISIE!$A$5:$A$504,SEARCH("/",SAISIE!$A$5:$A$504&"/")-1)))=$B$3)*(ISNUMBER(SEARCH("Vent D/G",SAISIE!$B$5:$B$504)))*(SAISIE!$E$5:$E$504<>"")),Mf,MAX(fz),INDEX(fy,MATCH(Mf,fz,0))),"-")) | D12: =IF($B$3="","",IFERROR(LET(fz,FILTER(SAISIE!$E$5:$E$504,(VALUE(TRIM(LEFT(SAISIE!$A$5:$A$504,SEARCH("/",SAISIE!$A$5:$A$504&"/")-1)))=$B$3)*(ISNUMBER(SEARCH("Vent D/G",SAISIE!$B$5:$B$504)))*(SAISIE!$E$5:$E$504<>"")),IF(COUNT(fz)=0,"-",MAX(fz))),"-")) | E12: (soulevement)
A13: Vent Av./Arr. maxi | B13: =IF($B$3="","",IFERROR(LET(fx,FILTER(SAISIE!$C$5:$C$504,(VALUE(TRIM(LEFT(SAISIE!$A$5:$A$504,SEARCH("/",SAISIE!$A$5:$A$504&"/")-1)))=$B$3)*(ISNUMBER(SEARCH("Vent Av./Arr.",SAISIE!$B$5:$B$504)))*(SAISIE!$E$5:$E$504<>"")),fz,FILTER(SAISIE!$E$5:$E$504,(VALUE(TRIM(LEFT(SAISIE!$A$5:$A$504,SEARCH("/",SAISIE!$A$5:$A$504&"/")-1)))=$B$3)*(ISNUMBER(SEARCH("Vent Av./Arr.",SAISIE!$B$5:$B$504)))*(SAISIE!$E$5:$E$504<>"")),mf,MIN(fz),IF(COUNT(fz)=0,"-",IF(MIN(fz)>=0,INDEX(fx,MATCH(MAX(fx),fx,0)),INDEX(fx,MATCH(mf,fz,0))))),"-")) | C13: =IF(OR($B$3="",$B$4<>"Oui"),"",IFERROR(LET(fy,FILTER(SAISIE!$D$5:$D$504,(VALUE(TRIM(LEFT(SAISIE!$A$5:$A$504,SEARCH("/",SAISIE!$A$5:$A$504&"/")-1)))=$B$3)*(ISNUMBER(SEARCH("Vent Av./Arr.",SAISIE!$B$5:$B$504)))*(SAISIE!$E$5:$E$504<>"")),fx,FILTER(SAISIE!$C$5:$C$504,(VALUE(TRIM(LEFT(SAISIE!$A$5:$A$504,SEARCH("/",SAISIE!$A$5:$A$504&"/")-1)))=$B$3)*(ISNUMBER(SEARCH("Vent Av./Arr.",SAISIE!$B$5:$B$504)))*(SAISIE!$E$5:$E$504<>"")),fz,FILTER(SAISIE!$E$5:$E$504,(VALUE(TRIM(LEFT(SAISIE!$A$5:$A$504,SEARCH("/",SAISIE!$A$5:$A$504&"/")-1)))=$B$3)*(ISNUMBER(SEARCH("Vent Av./Arr.",SAISIE!$B$5:$B$504)))*(SAISIE!$E$5:$E$504<>"")),mf,MIN(fz),IF(COUNT(fz)=0,"-",IF(MIN(fz)>=0,INDEX(fy,MATCH(MAX(fx),fx,0)),INDEX(fy,MATCH(mf,fz,0))))),"-")) | D13: =IF($B$3="","",IFERROR(LET(fz,FILTER(SAISIE!$E$5:$E$504,(VALUE(TRIM(LEFT(SAISIE!$A$5:$A$504,SEARCH("/",SAISIE!$A$5:$A$504&"/")-1)))=$B$3)*(ISNUMBER(SEARCH("Vent Av./Arr.",SAISIE!$B$5:$B$504)))*(SAISIE!$E$5:$E$504<>"")),IF(COUNT(fz)=0,"-",IF(MIN(fz)>=0,0,MIN(fz)))),"-")) | E13: (compression)
A14: Vent Av./Arr. mini | B14: =IF($B$3="","",IFERROR(LET(fx,FILTER(SAISIE!$C$5:$C$504,(VALUE(TRIM(LEFT(SAISIE!$A$5:$A$504,SEARCH("/",SAISIE!$A$5:$A$504&"/")-1)))=$B$3)*(ISNUMBER(SEARCH("Vent Av./Arr.",SAISIE!$B$5:$B$504)))*(SAISIE!$E$5:$E$504<>"")),fz,FILTER(SAISIE!$E$5:$E$504,(VALUE(TRIM(LEFT(SAISIE!$A$5:$A$504,SEARCH("/",SAISIE!$A$5:$A$504&"/")-1)))=$B$3)*(ISNUMBER(SEARCH("Vent Av./Arr.",SAISIE!$B$5:$B$504)))*(SAISIE!$E$5:$E$504<>"")),Mf,MAX(fz),INDEX(fx,MATCH(Mf,fz,0))),"-")) | C14: =IF(OR($B$3="",$B$4<>"Oui"),"",IFERROR(LET(fy,FILTER(SAISIE!$D$5:$D$504,(VALUE(TRIM(LEFT(SAISIE!$A$5:$A$504,SEARCH("/",SAISIE!$A$5:$A$504&"/")-1)))=$B$3)*(ISNUMBER(SEARCH("Vent Av./Arr.",SAISIE!$B$5:$B$504)))*(SAISIE!$E$5:$E$504<>"")),fz,FILTER(SAISIE!$E$5:$E$504,(VALUE(TRIM(LEFT(SAISIE!$A$5:$A$504,SEARCH("/",SAISIE!$A$5:$A$504&"/")-1)))=$B$3)*(ISNUMBER(SEARCH("Vent Av./Arr.",SAISIE!$B$5:$B$504)))*(SAISIE!$E$5:$E$504<>"")),Mf,MAX(fz),INDEX(fy,MATCH(Mf,fz,0))),"-")) | D14: =IF($B$3="","",IFERROR(LET(fz,FILTER(SAISIE!$E$5:$E$504,(VALUE(TRIM(LEFT(SAISIE!$A$5:$A$504,SEARCH("/",SAISIE!$A$5:$A$504&"/")-1)))=$B$3)*(ISNUMBER(SEARCH("Vent Av./Arr.",SAISIE!$B$5:$B$504)))*(SAISIE!$E$5:$E$504<>"")),IF(COUNT(fz)=0,"-",MAX(fz))),"-")) | E14: (soulevement)
A15: Vent Arr./Av maxi | B15: =IF($B$3="","",IFERROR(LET(fx,FILTER(SAISIE!$C$5:$C$504,(VALUE(TRIM(LEFT(SAISIE!$A$5:$A$504,SEARCH("/",SAISIE!$A$5:$A$504&"/")-1)))=$B$3)*(ISNUMBER(SEARCH("Vent Arr./Av.",SAISIE!$B$5:$B$504)))*(SAISIE!$E$5:$E$504<>"")),fz,FILTER(SAISIE!$E$5:$E$504,(VALUE(TRIM(LEFT(SAISIE!$A$5:$A$504,SEARCH("/",SAISIE!$A$5:$A$504&"/")-1)))=$B$3)*(ISNUMBER(SEARCH("Vent Arr./Av.",SAISIE!$B$5:$B$504)))*(SAISIE!$E$5:$E$504<>"")),mf,MIN(fz),IF(COUNT(fz)=0,"-",IF(MIN(fz)>=0,INDEX(fx,MATCH(MAX(fx),fx,0)),INDEX(fx,MATCH(mf,fz,0))))),"-")) | C15: =IF(OR($B$3="",$B$4<>"Oui"),"",IFERROR(LET(fy,FILTER(SAISIE!$D$5:$D$504,(VALUE(TRIM(LEFT(SAISIE!$A$5:$A$504,SEARCH("/",SAISIE!$A$5:$A$504&"/")-1)))=$B$3)*(ISNUMBER(SEARCH("Vent Arr./Av.",SAISIE!$B$5:$B$504)))*(SAISIE!$E$5:$E$504<>"")),fx,FILTER(SAISIE!$C$5:$C$504,(VALUE(TRIM(LEFT(SAISIE!$A$5:$A$504,SEARCH("/",SAISIE!$A$5:$A$504&"/")-1)))=$B$3)*(ISNUMBER(SEARCH("Vent Arr./Av.",SAISIE!$B$5:$B$504)))*(SAISIE!$E$5:$E$504<>"")),fz,FILTER(SAISIE!$E$5:$E$504,(VALUE(TRIM(LEFT(SAISIE!$A$5:$A$504,SEARCH("/",SAISIE!$A$5:$A$504&"/")-1)))=$B$3)*(ISNUMBER(SEARCH("Vent Arr./Av.",SAISIE!$B$5:$B$504)))*(SAISIE!$E$5:$E$504<>"")),mf,MIN(fz),IF(COUNT(fz)=0,"-",IF(MIN(fz)>=0,INDEX(fy,MATCH(MAX(fx),fx,0)),INDEX(fy,MATCH(mf,fz,0))))),"-")) | D15: =IF($B$3="","",IFERROR(LET(fz,FILTER(SAISIE!$E$5:$E$504,(VALUE(TRIM(LEFT(SAISIE!$A$5:$A$504,SEARCH("/",SAISIE!$A$5:$A$504&"/")-1)))=$B$3)*(ISNUMBER(SEARCH("Vent Arr./Av.",SAISIE!$B$5:$B$504)))*(SAISIE!$E$5:$E$504<>"")),IF(COUNT(fz)=0,"-",IF(MIN(fz)>=0,0,MIN(fz)))),"-")) | E15: (compression)
A16: Vent Arr./Av mini | B16: =IF($B$3="","",IFERROR(LET(fx,FILTER(SAISIE!$C$5:$C$504,(VALUE(TRIM(LEFT(SAISIE!$A$5:$A$504,SEARCH("/",SAISIE!$A$5:$A$504&"/")-1)))=$B$3)*(ISNUMBER(SEARCH("Vent Arr./Av.",SAISIE!$B$5:$B$504)))*(SAISIE!$E$5:$E$504<>"")),fz,FILTER(SAISIE!$E$5:$E$504,(VALUE(TRIM(LEFT(SAISIE!$A$5:$A$504,SEARCH("/",SAISIE!$A$5:$A$504&"/")-1)))=$B$3)*(ISNUMBER(SEARCH("Vent Arr./Av.",SAISIE!$B$5:$B$504)))*(SAISIE!$E$5:$E$504<>"")),Mf,MAX(fz),INDEX(fx,MATCH(Mf,fz,0))),"-")) | C16: =IF(OR($B$3="",$B$4<>"Oui"),"",IFERROR(LET(fy,FILTER(SAISIE!$D$5:$D$504,(VALUE(TRIM(LEFT(SAISIE!$A$5:$A$504,SEARCH("/",SAISIE!$A$5:$A$504&"/")-1)))=$B$3)*(ISNUMBER(SEARCH("Vent Arr./Av.",SAISIE!$B$5:$B$504)))*(SAISIE!$E$5:$E$504<>"")),fz,FILTER(SAISIE!$E$5:$E$504,(VALUE(TRIM(LEFT(SAISIE!$A$5:$A$504,SEARCH("/",SAISIE!$A$5:$A$504&"/")-1)))=$B$3)*(ISNUMBER(SEARCH("Vent Arr./Av.",SAISIE!$B$5:$B$504)))*(SAISIE!$E$5:$E$504<>"")),Mf,MAX(fz),INDEX(fy,MATCH(Mf,fz,0))),"-")) | D16: =IF($B$3="","",IFERROR(LET(fz,FILTER(SAISIE!$E$5:$E$504,(VALUE(TRIM(LEFT(SAISIE!$A$5:$A$504,SEARCH("/",SAISIE!$A$5:$A$504&"/")-1)))=$B$3)*(ISNUMBER(SEARCH("Vent Arr./Av.",SAISIE!$B$5:$B$504)))*(SAISIE!$E$5:$E$504<>"")),IF(COUNT(fz)=0,"-",MAX(fz))),"-")) | E16: (soulevement)
A17: Neige normale | B17: =IF($B$3="","",IFERROR(LET(v,FILTER(SAISIE!$C$5:$C$504,(VALUE(TRIM(LEFT(SAISIE!$A$5:$A$504,SEARCH("/",SAISIE!$A$5:$A$504&"/")-1)))=$B$3)*(ISNUMBER(SEARCH("Neige",SAISIE!$B$5:$B$504))*(NOT(ISNUMBER(SEARCH("accidentel",SAISIE!$B$5:$B$504)))))*(SAISIE!$E$5:$E$504<>"")),fz,FILTER(SAISIE!$E$5:$E$504,(VALUE(TRIM(LEFT(SAISIE!$A$5:$A$504,SEARCH("/",SAISIE!$A$5:$A$504&"/")-1)))=$B$3)*(ISNUMBER(SEARCH("Neige",SAISIE!$B$5:$B$504))*(NOT(ISNUMBER(SEARCH("accidentel",SAISIE!$B$5:$B$504)))))*(SAISIE!$E$5:$E$504<>"")),IF(COUNT(fz)=0,"-",INDEX(v,MATCH(MIN(fz),fz,0)))),"-")) | C17: =IF(OR($B$3="",$B$4<>"Oui"),",IFERROR(LET(v,FILTER(SAISIE!$D$5:$D$504,(VALUE(TRIM(LEFT(SAISIE!$A$5:$A$504,SEARCH("/",SAISIE!$A$5:$A$504&"/")-1)))=$B$3)*(ISNUMBER(SEARCH("Neige",SAISIE!$B$5:$B$504))*(NOT(ISNUMBER(SEARCH("accidentel",SAISIE!$B$5:$B$504)))))*(SAISIE!$E$5:$E$504<>"")),fz,FILTER(SAISIE!$E$5:$E$504,(VALUE(TRIM(LEFT(SAISIE!$A$5:$A$504,SEARCH("/",SAISIE!$A$5:$A$504&"/")-1)))=$B$3)*(ISNUMBER(SEARCH("Neige",SAISIE!$B$5:$B$504))*(NOT(ISNUMBER(SEARCH("accidentel",SAISIE!$B$5:$B$504)))))*(SAISIE!$E$5:$E$504<>"")),IF(COUNT(fz)=0,"-",INDEX(v,MATCH(MIN(fz),fz,0)))),"-")) | D17: =IF($B$3="","",IFERROR(LET(v,FILTER(SAISIE!$E$5:$E$504,(VALUE(TRIM(LEFT(SAISIE!$A$5:$A$504,SEARCH("/",SAISIE!$A$5:$A$504&"/")-1)))=$B$3)*(ISNUMBER(SEARCH("Neige",SAISIE!$B$5:$B$504))*(NOT(ISNUMBER(SEARCH("accidentel",SAISIE!$B$5:$B$504)))))*(SAISIE!$E$5:$E$504<>"")),fz,FILTER(SAISIE!$E$5:$E$504,(VALUE(TRIM(LEFT(SAISIE!$A$5:$A$504,SEARCH("/",SAISIE!$A$5:$A$504&"/")-1)))=$B$3)*(ISNUMBER(SEARCH("Neige",SAISIE!$B$5:$B$504))*(NOT(ISNUMBER(SEARCH("accidentel",SAISIE!$B$5:$B$504)))))*(SAISIE!$E$5:$E$504<>"")),IF(COUNT(fz)=0,"-",INDEX(v,MATCH(MIN(fz),fz,0)))),"-"))
A18: Neige accidentelle | B18: =IF($B$3="","",IFERROR(LET(v,FILTER(SAISIE!$C$5:$C$504,(VALUE(TRIM(LEFT(SAISIE!$A$5:$A$504,SEARCH("/",SAISIE!$A$5:$A$504&"/")-1)))=$B$3)*(ISNUMBER(SEARCH("accidentel",SAISIE!$B$5:$B$504)))*(SAISIE!$E$5:$E$504<>"")),IF(COUNT(v)=0,"-",INDEX(v,1))),"-")) | C18: =IF(OR($B$3="",$B$4<>"Oui"),",IFERROR(LET(v,FILTER(SAISIE!$D$5:$D$504,(VALUE(TRIM(LEFT(SAISIE!$A$5:$A$504,SEARCH("/",SAISIE!$A$5:$A$504&"/")-1)))=$B$3)*(ISNUMBER(SEARCH("accidentel",SAISIE!$B$5:$B$504)))*(SAISIE!$E$5:$E$504<>"")),IF(COUNT(v)=0,"-",INDEX(v,1))),"-")) | D18: =IF($B$3="","",IFERROR(LET(v,FILTER(SAISIE!$E$5:$E$504,(VALUE(TRIM(LEFT(SAISIE!$A$5:$A$504,SEARCH("/",SAISIE!$A$5:$A$504&"/")-1)))=$B$3)*(ISNUMBER(SEARCH("accidentel",SAISIE!$B$5:$B$504)))*(SAISIE!$E$5:$E$504<>"")),IF(COUNT(v)=0,"-",INDEX(v,1))),"-"))

Sheet RECAP
A1: 3 — RECAP MULTI-NOEUDS
A4: Noeud | B4: Couv FX | C4: Couv FZ | D4: VGD max FX | E4: VGD max FZ | F4: VGD min FX | G4: VGD min FZ | H4: VDG max FX | I4: VDG max FZ | J4: VDG min FX | K4: VDG min FZ | L4: Neige N FX | M4: Neige N FZ | N4: Neige Acc FX | O4: Neige Acc FZ
A5: =IFERROR(INDEX(IFERROR(UNIQUE(FILTER(VALUE(TRIM(LEFT(SAISIE!$A$5:$A$504,SEARCH("/",SAISIE!$A$5:$A$504&"/")-1))),SAISIE!$A$5:$A$504<>"")),""),1),"") | B5: =IF($A5="","",IFERROR(LET(v,FILTER(SAISIE!$C$5:$C$504,(VALUE(TRIM(LEFT(SAISIE!$A$5:$A$504,SEARCH("/",SAISIE!$A$5:$A$504&"/")-1)))=$A5)*(OR(ISNUMBER(SEARCH("Couverture",SAISIE!$B$5:$B$504)),LEFT(SAISIE!$B$5:$B$504,2)="G "))),IF(COUNT(v)=0,"-",INDEX(v,1))),"-")) | C5: =IF($A5="","",IFERROR(LET(v,FILTER(SAISIE!$E$5:$E$504,(VALUE(TRIM(LEFT(SAISIE!$A$5:$A$504,SEARCH("/",SAISIE!$A$5:$A$504&"/")-1)))=$A5)*(OR(ISNUMBER(SEARCH("Couverture",SAISIE!$B$5:$B$504)),LEFT(SAISIE!$B$5:$B$504,2)="G "))),IF(COUNT(v)=0,"-",INDEX(v,1))),"-")) | D5: =IF($A5="","",IFERROR(LET(fx,FILTER(SAISIE!$C$5:$C$504,(VALUE(TRIM(LEFT(SAISIE!$A$5:$A$504,SEARCH("/",SAISIE!$A$5:$A$504&"/")-1)))=$A5)*(ISNUMBER(SEARCH("Vent G/D",SAISIE!$B$5:$B$504)))*(SAISIE!$E$5:$E$504<>"")),fz,FILTER(SAISIE!$E$5:$E$504,(VALUE(TRIM(LEFT(SAISIE!$A$5:$A$504,SEARCH("/",SAISIE!$A$5:$A$504&"/")-1)))=$A5)*(ISNUMBER(SEARCH("Vent G/D",SAISIE!$B$5:$B$504)))*(SAISIE!$E$5:$E$504<>"")),mf,MIN(fz),IF(COUNT(fz)=0,"-",IF(MIN(fz)>=0,INDEX(fx,MATCH(MAX(fx),fx,0)),INDEX(fx,MATCH(mf,fz,0))))),"-")) | E5: =IF($A5="","",IFERROR(LET(fz,FILTER(SAISIE!$E$5:$E$504,(VALUE(TRIM(LEFT(SAISIE!$A$5:$A$504,SEARCH("/",SAISIE!$A$5:$A$504&"/")-1)))=$A5)*(ISNUMBER(SEARCH("Vent G/D",SAISIE!$B$5:$B$504)))*(SAISIE!$E$5:$E$504<>"")),IF(COUNT(fz)=0,"-",IF(MIN(fz)>=0,0,MIN(fz)))),"-")) | F5: =IF($A5="","",IFERROR(LET(fx,FILTER(SAISIE!$C$5:$C$504,(VALUE(TRIM(LEFT(SAISIE!$A$5:$A$504,SEARCH("/",SAISIE!$A$5:$A$504&"/")-1)))=$A5)*(ISNUMBER(SEARCH("Vent G/D",SAISIE!$B$5:$B$504)))*(SAISIE!$E$5:$E$504<>"")),fz,FILTER(SAISIE!$E$5:$E$504,(VALUE(TRIM(LEFT(SAISIE!$A$5:$A$504,SEARCH("/",SAISIE!$A$5:$A$504&"/")-1)))=$A5)*(ISNUMBER(SEARCH("Vent G/D",SAISIE!$B$5:$B$504)))*(SAISIE!$E$5:$E$504<>"")),Mf,MAX(fz),INDEX(fx,MATCH(Mf,fz,0))),"-")) | G5: =IF($A5="","",IFERROR(LET(fz,FILTER(SAISIE!$E$5:$E$504,(VALUE(TRIM(LEFT(SAISIE!$A$5:$A$504,SEARCH("/",SAISIE!$A$5:$A$504&"/")-1)))=$A5)*(ISNUMBER(SEARCH("Vent G/D",SAISIE!$B$5:$B$504)))*(SAISIE!$E$5:$E$504<>"")),IF(COUNT(fz)=0,"-",MAX(fz))),"-")) | H5: =IF($A5="","",IFERROR(LET(fx,FILTER(SAISIE!$C$5:$C$504,(VALUE(TRIM(LEFT(SAISIE!$A$5:$A$504,SEARCH("/",SAISIE!$A$5:$A$504&"/")-1)))=$A5)*(ISNUMBER(SEARCH("Vent D/G",SAISIE!$B$5:$B$504)))*(SAISIE!$E$5:$E$504<>"")),fz,FILTER(SAISIE!$E$5:$E$504,(VALUE(TRIM(LEFT(SAISIE!$A$5:$A$504,SEARCH("/",SAISIE!$A$5:$A$504&"/")-1)))=$A5)*(ISNUMBER(SEARCH("Vent D/G",SAISIE!$B$5:$B$504)))*(SAISIE!$E$5:$E$504<>"")),mf,MIN(fz),IF(COUNT(fz)=0,"-",IF(MIN(fz)>=0,INDEX(fx,MATCH(MAX(fx),fx,0)),INDEX(fx,MATCH(mf,fz,0))))),"-")) | I5: =IF($A5="","",IFERROR(LET(fz,FILTER(SAISIE!$E$5:$E$504,(VALUE(TRIM(LEFT(SAISIE!$A$5:$A$504,SEARCH("/",SAISIE!$A$5:$A$504&"/")-1)))=$A5)*(ISNUMBER(SEARCH("Vent D/G",SAISIE!$B$5:$B$504)))*(SAISIE!$E$5:$E$504<>"")),IF(COUNT(fz)=0,"-",IF(MIN(fz)>=0,0,MIN(fz)))),"-")) | J5: =IF($A5="","",IFERROR(LET(fx,FILTER(SAISIE!$C$5:$C$504,(VALUE(TRIM(LEFT(SAISIE!$A$5:$A$504,SEARCH("/",SAISIE!$A$5:$A$504&"/")-1)))=$A5)*(ISNUMBER(SEARCH("Vent D/G",SAISIE!$B$5:$B$504)))*(SAISIE!$E$5:$E$504<>"")),fz,FILTER(SAISIE!$E$5:$E$504,(VALUE(TRIM(LEFT(SAISIE!$A$5:$A$504,SEARCH("/",SAISIE!$A$5:$A$504&"/")-1)))=$A5)*(ISNUMBER(SEARCH("Vent D/G",SAISIE!$B$5:$B$504)))*(SAISIE!$E$5:$E$504<>"")),Mf,MAX(fz),INDEX(fx,MATCH(Mf,fz,0))),"-")) | K5: =IF($A5="","",IFERROR(LET(fz,FILTER(SAISIE!$E$5:$E$504,(VALUE(TRIM(LEFT(SAISIE!$A$5:$A$504,SEARCH("/",SAISIE!$A$5:$A$504&"/")-1)))=$A5)*(ISNUMBER(SEARCH("Vent D/G",SAISIE!$B$5:$B$504)))*(SAISIE!$E$5:$E$504<>"")),IF(COUNT(fz)=0,"-",MAX(fz))),"-")) | L5: =IF($A5="","",IFERROR(LET(v,FILTER(SAISIE!$C$5:$C$504,(VALUE(TRIM(LEFT(SAISIE!$A$5:$A$504,SEARCH("/",SAISIE!$A$5:$A$504&"/")-1)))=$A5)*(ISNUMBER(SEARCH("Neige",SAISIE!$B$5:$B$504))*(NOT(ISNUMBER(SEARCH("accidentel",SAISIE!$B$5:$B$504)))))*(SAISIE!$E$5:$E$504<>"")),fz,FILTER(SAISIE!$E$5:$E$504,(VALUE(TRIM(LEFT(SAISIE!$A$5:$A$504,SEARCH("/",SAISIE!$A$5:$A$504&"/")-1)))=$A5)*(ISNUMBER(SEARCH("Neige",SAISIE!$B$5:$B$504))*(NOT(ISNUMBER(SEARCH("accidentel",SAISIE!$B$5:$B$504)))))*(SAISIE!$E$5:$E$504<>"")),IF(COUNT(fz)=0,"-",INDEX(v,MATCH(MIN(fz),fz,0)))),"-")) | M5: =IF($A5="","",IFERROR(LET(v,FILTER(SAISIE!$E$5:$E$504,(VALUE(TRIM(LEFT(SAISIE!$A$5:$A$504,SEARCH("/",SAISIE!$A$5:$A$504&"/")-1)))=$A5)*(ISNUMBER(SEARCH("Neige",SAISIE!$B$5:$B$504))*(NOT(ISNUMBER(SEARCH("accidentel",SAISIE!$B$5:$B$504)))))*(SAISIE!$E$5:$E$504<>"")),IF(COUNT(v)=0,"-",MIN(v))),"-")) | N5: =IF($A5="","",IFERROR(LET(v,FILTER(SAISIE!$C$5:$C$504,(VALUE(TRIM(LEFT(SAISIE!$A$5:$A$504,SEARCH("/",SAISIE!$A$5:$A$504&"/")-1)))=$A5)*(ISNUMBER(SEARCH("accidentel",SAISIE!$B$5:$B$504)))*(SAISIE!$E$5:$E$504<>"")),IF(COUNT(v)=0,"-",INDEX(v,1))),"-")) | O5: =IF($A5="","",IFERROR(LET(v,FILTER(SAISIE!$E$5:$E$504,(VALUE(TRIM(LEFT(SAISIE!$A$5:$A$504,SEARCH("/",SAISIE!$A$5:$A$504&"/")-1)))=$A5)*(ISNUMBER(SEARCH("accidentel",SAISIE!$B$5:$B$504)))*(SAISIE!$E$5:$E$504<>"")),IF(COUNT(v)=0,"-",INDEX(v,1))),"-"))
A6: =IFERROR(INDEX(IFERROR(UNIQUE(FILTER(VALUE(TRIM(LEFT(SAISIE!$A$5:$A$504,SEARCH("/",SAISIE!$A$5:$A$504&"/")-1))),SAISIE!$A$5:$A$504<>"")),""),2),"") | B6: =IF($A6="","",IFERROR(LET(v,FILTER(SAISIE!$C$5:$C$504,(VALUE(TRIM(LEFT(SAISIE!$A$5:$A$504,SEARCH("/",SAISIE!$A$5:$A$504&"/")-1)))=$A6)*(OR(ISNUMBER(SEARCH("Couverture",SAISIE!$B$5:$B$504)),LEFT(SAISIE!$B$5:$B$504,2)="G "))),IF(COUNT(v)=0,"-",INDEX(v,1))),"-")) | C6: =IF($A6="","",IFERROR(LET(v,FILTER(SAISIE!$E$5:$E$504,(VALUE(TRIM(LEFT(SAISIE!$A$5:$A$504,SEARCH("/",SAISIE!$A$5:$A$504&"/")-1)))=$A6)*(OR(ISNUMBER(SEARCH("Couverture",SAISIE!$B$5:$B$504)),LEFT(SAISIE!$B$5:$B$504,2)="G "))),IF(COUNT(v)=0,"-",INDEX(v,1))),"-")) | D6: =IF($A6="","",IFERROR(LET(fx,FILTER(SAISIE!$C$5:$C$504,(VALUE(TRIM(LEFT(SAISIE!$A$5:$A$504,SEARCH("/",SAISIE!$A$5:$A$504&"/")-1)))=$A6)*(ISNUMBER(SEARCH("Vent G/D",SAISIE!$B$5:$B$504)))*(SAISIE!$E$5:$E$504<>"")),fz,FILTER(SAISIE!$E$5:$E$504,(VALUE(TRIM(LEFT(SAISIE!$A$5:$A$504,SEARCH("/",SAISIE!$A$5:$A$504&"/")-1)))=$A6)*(ISNUMBER(SEARCH("Vent G/D",SAISIE!$B$5:$B$504)))*(SAISIE!$E$5:$E$504<>"")),mf,MIN(fz),IF(COUNT(fz)=0,"-",IF(MIN(fz)>=0,INDEX(fx,MATCH(MAX(fx),fx,0)),INDEX(fx,MATCH(mf,fz,0))))),"-")) | E6: =IF($A6="","",IFERROR(LET(fz,FILTER(SAISIE!$E$5:$E$504,(VALUE(TRIM(LEFT(SAISIE!$A$5:$A$504,SEARCH("/",SAISIE!$A$5:$A$504&"/")-1)))=$A6)*(ISNUMBER(SEARCH("Vent G/D",SAISIE!$B$5:$B$504)))*(SAISIE!$E$5:$E$504<>"")),IF(COUNT(fz)=0,"-",IF(MIN(fz)>=0,0,MIN(fz)))),"-")) | F6: =IF($A6="","",IFERROR(LET(fx,FILTER(SAISIE!$C$5:$C$504,(VALUE(TRIM(LEFT(SAISIE!$A$5:$A$504,SEARCH("/",SAISIE!$A$5:$A$504&"/")-1)))=$A6)*(ISNUMBER(SEARCH("Vent G/D",SAISIE!$B$5:$B$504)))*(SAISIE!$E$5:$E$504<>"")),fz,FILTER(SAISIE!$E$5:$E$504,(VALUE(TRIM(LEFT(SAISIE!$A$5:$A$504,SEARCH("/",SAISIE!$A$5:$A$504&"/")-1)))=$A6)*(ISNUMBER(SEARCH("Vent G/D",SAISIE!$B$5:$B$504)))*(SAISIE!$E$5:$E$504<>"")),Mf,MAX(fz),INDEX(fx,MATCH(Mf,fz,0))),"-")) | G6: =IF($A6="","",IFERROR(LET(fz,FILTER(SAISIE!$E$5:$E$504,(VALUE(TRIM(LEFT(SAISIE!$A$5:$A$504,SEARCH("/",SAISIE!$A$5:$A$504&"/")-1)))=$A6)*(ISNUMBER(SEARCH("Vent G/D",SAISIE!$B$5:$B$504)))*(SAISIE!$E$5:$E$504<>"")),IF(COUNT(fz)=0,"-",MAX(fz))),"-")) | H6: =IF($A6="","",IFERROR(LET(fx,FILTER(SAISIE!$C$5:$C$504,(VALUE(TRIM(LEFT(SAISIE!$A$5:$A$504,SEARCH("/",SAISIE!$A$5:$A$504&"/")-1)))=$A6)*(ISNUMBER(SEARCH("Vent D/G",SAISIE!$B$5:$B$504)))*(SAISIE!$E$5:$E$504<>"")),fz,FILTER(SAISIE!$E$5:$E$504,(VALUE(TRIM(LEFT(SAISIE!$A$5:$A$504,SEARCH("/",SAISIE!$A$5:$A$504&"/")-1)))=$A6)*(ISNUMBER(SEARCH("Vent D/G",SAISIE!$B$5:$B$504)))*(SAISIE!$E$5:$E$504<>"")),mf,MIN(fz),IF(COUNT(fz)=0,"-",IF(MIN(fz)>=0,INDEX(fx,MATCH(MAX(fx),fx,0)),INDEX(fx,MATCH(mf,fz,0))))),"-")) | I6: =IF($A6="","",IFERROR(LET(fz,FILTER(SAISIE!$E$5:$E$504,(VALUE(TRIM(LEFT(SAISIE!$A$5:$A$504,SEARCH("/",SAISIE!$A$5:$A$504&"/")-1)))=$A6)*(ISNUMBER(SEARCH("Vent D/G",SAISIE!$B$5:$B$504)))*(SAISIE!$E$5:$E$504<>"")),IF(COUNT(fz)=0,"-",IF(MIN(fz)>=0,0,MIN(fz)))),"-")) | J6: =IF($A6="","",IFERROR(LET(fx,FILTER(SAISIE!$C$5:$C$504,(VALUE(TRIM(LEFT(SAISIE!$A$5:$A$504,SEARCH("/",SAISIE!$A$5:$A$504&"/")-1)))=$A6)*(ISNUMBER(SEARCH("Vent D/G",SAISIE!$B$5:$B$504)))*(SAISIE!$E$5:$E$504<>"")),fz,FILTER(SAISIE!$E$5:$E$504,(VALUE(TRIM(LEFT(SAISIE!$A$5:$A$504,SEARCH("/",SAISIE!$A$5:$A$504&"/")-1)))=$A6)*(ISNUMBER(SEARCH("Vent D/G",SAISIE!$B$5:$B$504)))*(SAISIE!$E$5:$E$504<>"")),Mf,MAX(fz),INDEX(fx,MATCH(Mf,fz,0))),"-")) | K6: =IF($A6="","",IFERROR(LET(fz,FILTER(SAISIE!$E$5:$E$504,(VALUE(TRIM(LEFT(SAISIE!$A$5:$A$504,SEARCH("/",SAISIE!$A$5:$A$504&"/")-1)))=$A6)*(ISNUMBER(SEARCH("Vent D/G",SAISIE!$B$5:$B$504)))*(SAISIE!$E$5:$E$504<>"")),IF(COUNT(fz)=0,"-",MAX(fz))),"-")) | L6: =IF($A6="","",IFERROR(LET(v,FILTER(SAISIE!$C$5:$C$504,(VALUE(TRIM(LEFT(SAISIE!$A$5:$A$504,SEARCH("/",SAISIE!$A$5:$A$504&"/")-1)))=$A6)*(ISNUMBER(SEARCH("Neige",SAISIE!$B$5:$B$504))*(NOT(ISNUMBER(SEARCH("accidentel",SAISIE!$B$5:$B$504)))))*(SAISIE!$E$5:$E$504<>"")),fz,FILTER(SAISIE!$E$5:$E$504,(VALUE(TRIM(LEFT(SAISIE!$A$5:$A$504,SEARCH("/",SAISIE!$A$5:$A$504&"/")-1)))=$A6)*(ISNUMBER(SEARCH("Neige",SAISIE!$B$5:$B$504))*(NOT(ISNUMBER(SEARCH("accidentel",SAISIE!$B$5:$B$504)))))*(SAISIE!$E$5:$E$504<>"")),IF(COUNT(fz)=0,"-",INDEX(v,MATCH(MIN(fz),fz,0)))),"-")) | M6: =IF($A6="","",IFERROR(LET(v,FILTER(SAISIE!$E$5:$E$504,(VALUE(TRIM(LEFT(SAISIE!$A$5:$A$504,SEARCH("/",SAISIE!$A$5:$A$504&"/")-1)))=$A6)*(ISNUMBER(SEARCH("Neige",SAISIE!$B$5:$B$504))*(NOT(ISNUMBER(SEARCH("accidentel",SAISIE!$B$5:$B$504)))))*(SAISIE!$E$5:$E$504<>"")),IF(COUNT(v)=0,"-",MIN(v))),"-")) | N6: =IF($A6="","",IFERROR(LET(v,FILTER(SAISIE!$C$5:$C$504,(VALUE(TRIM(LEFT(SAISIE!$A$5:$A$504,SEARCH("/",SAISIE!$A$5:$A$504&"/")-1)))=$A6)*(ISNUMBER(SEARCH("accidentel",SAISIE!$B$5:$B$504)))*(SAISIE!$E$5:$E$504<>"")),IF(COUNT(v)=0,"-",INDEX(v,1))),"-")) | O6: =IF($A6="","",IFERROR(LET(v,FILTER(SAISIE!$E$5:$E$504,(VALUE(TRIM(LEFT(SAISIE!$A$5:$A$504,SEARCH("/",SAISIE!$A$5:$A$504&"/")-1)))=$A6)*(ISNUMBER(SEARCH("accidentel",SAISIE!$B$5:$B$504)))*(SAISIE!$E$5:$E$504<>"")),IF(COUNT(v)=0,"-",INDEX(v,1))),"-"))
A7: =IFERROR(INDEX(IFERROR(UNIQUE(FILTER(VALUE(TRIM(LEFT(SAISIE!$A$5:$A$504,SEARCH("/",SAISIE!$A$5:$A$504&"/")-1))),SAISIE!$A$5:$A$504<>"")),""),3),"") | B7: =IF($A7="","",IFERROR(LET(v,FILTER(SAISIE!$C$5:$C$504,(VALUE(TRIM(LEFT(SAISIE!$A$5:$A$504,SEARCH("/",SAISIE!$A$5:$A$504&"/")-1)))=$A7)*(OR(ISNUMBER(SEARCH("Couverture",SAISIE!$B$5:$B$504)),LEFT(SAISIE!$B$5:$B$504,2)="G "))),IF(COUNT(v)=0,"-",INDEX(v,1))),"-")) | C7: =IF($A7="","",IFERROR(LET(v,FILTER(SAISIE!$E$5:$E$504,(VALUE(TRIM(LEFT(SAISIE!$A$5:$A$504,SEARCH("/",SAISIE!$A$5:$A$504&"/")-1)))=$A7)*(OR(ISNUMBER(SEARCH("Couverture",SAISIE!$B$5:$B$504)),LEFT(SAISIE!$B$5:$B$504,2)="G "))),IF(COUNT(v)=0,"-",INDEX(v,1))),"-")) | D7: =IF($A7="","",IFERROR(LET(fx,FILTER(SAISIE!$C$5:$C$504,(VALUE(TRIM(LEFT(SAISIE!$A$5:$A$504,SEARCH("/",SAISIE!$A$5:$A$504&"/")-1)))=$A7)*(ISNUMBER(SEARCH("Vent G/D",SAISIE!$B$5:$B$504)))*(SAISIE!$E$5:$E$504<>"")),fz,FILTER(SAISIE!$E$5:$E$504,(VALUE(TRIM(LEFT(SAISIE!$A$5:$A$504,SEARCH("/",SAISIE!$A$5:$A$504&"/")-1)))=$A7)*(ISNUMBER(SEARCH("Vent G/D",SAISIE!$B$5:$B$504)))*(SAISIE!$E$5:$E$504<>"")),mf,MIN(fz),IF(COUNT(fz)=0,"-",IF(MIN(fz)>=0,INDEX(fx,MATCH(MAX(fx),fx,0)),INDEX(fx,MATCH(mf,fz,0))))),"-")) | E7: =IF($A7="","",IFERROR(LET(fz,FILTER(SAISIE!$E$5:$E$504,(VALUE(TRIM(LEFT(SAISIE!$A$5:$A$504,SEARCH("/",SAISIE!$A$5:$A$504&"/")-1)))=$A7)*(ISNUMBER(SEARCH("Vent G/D",SAISIE!$B$5:$B$504)))*(SAISIE!$E$5:$E$504<>"")),IF(COUNT(fz)=0,"-",IF(MIN(fz)>=0,0,MIN(fz)))),"-")) | F7: =IF($A7="","",IFERROR(LET(fx,FILTER(SAISIE!$C$5:$C$504,(VALUE(TRIM(LEFT(SAISIE!$A$5:$A$504,SEARCH("/",SAISIE!$A$5:$A$504&"/")-1)))=$A7)*(ISNUMBER(SEARCH("Vent G/D",SAISIE!$B$5:$B$504)))*(SAISIE!$E$5:$E$504<>"")),fz,FILTER(SAISIE!$E$5:$E$504,(VALUE(TRIM(LEFT(SAISIE!$A$5:$A$504,SEARCH("/",SAISIE!$A$5:$A$504&"/")-1)))=$A7)*(ISNUMBER(SEARCH("Vent G/D",SAISIE!$B$5:$B$504)))*(SAISIE!$E$5:$E$504<>"")),Mf,MAX(fz),INDEX(fx,MATCH(Mf,fz,0))),"-")) | G7: =IF($A7="","",IFERROR(LET(fz,FILTER(SAISIE!$E$5:$E$504,(VALUE(TRIM(LEFT(SAISIE!$A$5:$A$504,SEARCH("/",SAISIE!$A$5:$A$504&"/")-1)))=$A7)*(ISNUMBER(SEARCH("Vent G/D",SAISIE!$B$5:$B$504)))*(SAISIE!$E$5:$E$504<>"")),IF(COUNT(fz)=0,"-",MAX(fz))),"-")) | H7: =IF($A7="","",IFERROR(LET(fx,FILTER(SAISIE!$C$5:$C$504,(VALUE(TRIM(LEFT(SAISIE!$A$5:$A$504,SEARCH("/",SAISIE!$A$5:$A$504&"/")-1)))=$A7)*(ISNUMBER(SEARCH("Vent D/G",SAISIE!$B$5:$B$504)))*(SAISIE!$E$5:$E$504<>"")),fz,FILTER(SAISIE!$E$5:$E$504,(VALUE(TRIM(LEFT(SAISIE!$A$5:$A$504,SEARCH("/",SAISIE!$A$5:$A$504&"/")-1)))=$A7)*(ISNUMBER(SEARCH("Vent D/G",SAISIE!$B$5:$B$504)))*(SAISIE!$E$5:$E$504<>"")),mf,MIN(fz),IF(COUNT(fz)=0,"-",IF(MIN(fz)>=0,INDEX(fx,MATCH(MAX(fx),fx,0)),INDEX(fx,MATCH(mf,fz,0))))),"-")) | I7: =IF($A7="","",IFERROR(LET(fz,FILTER(SAISIE!$E$5:$E$504,(VALUE(TRIM(LEFT(SAISIE!$A$5:$A$504,SEARCH("/",SAISIE!$A$5:$A$504&"/")-1)))=$A7)*(ISNUMBER(SEARCH("Vent D/G",SAISIE!$B$5:$B$504)))*(SAISIE!$E$5:$E$504<>"")),IF(COUNT(fz)=0,"-",IF(MIN(fz)>=0,0,MIN(fz)))),"-")) | J7: =IF($A7="","",IFERROR(LET(fx,FILTER(SAISIE!$C$5:$C$504,(VALUE(TRIM(LEFT(SAISIE!$A$5:$A$504,SEARCH("/",SAISIE!$A$5:$A$504&"/")-1)))=$A7)*(ISNUMBER(SEARCH("Vent D/G",SAISIE!$B$5:$B$504)))*(SAISIE!$E$5:$E$504<>"")),fz,FILTER(SAISIE!$E$5:$E$504,(VALUE(TRIM(LEFT(SAISIE!$A$5:$A$504,SEARCH("/",SAISIE!$A$5:$A$504&"/")-1)))=$A7)*(ISNUMBER(SEARCH("Vent D/G",SAISIE!$B$5:$B$504)))*(SAISIE!$E$5:$E$504<>"")),Mf,MAX(fz),INDEX(fx,MATCH(Mf,fz,0))),"-")) | K7: =IF($A7="","",IFERROR(LET(fz,FILTER(SAISIE!$E$5:$E$504,(VALUE(TRIM(LEFT(SAISIE!$A$5:$A$504,SEARCH("/",SAISIE!$A$5:$A$504&"/")-1)))=$A7)*(ISNUMBER(SEARCH("Vent D/G",SAISIE!$B$5:$B$504)))*(SAISIE!$E$5:$E$504<>"")),IF(COUNT(fz)=0,"-",MAX(fz))),"-")) | L7: =IF($A7="","",IFERROR(LET(v,FILTER(SAISIE!$C$5:$C$504,(VALUE(TRIM(LEFT(SAISIE!$A$5:$A$504,SEARCH("/",SAISIE!$A$5:$A$504&"/")-1)))=$A7)*(ISNUMBER(SEARCH("Neige",SAISIE!$B$5:$B$504))*(NOT(ISNUMBER(SEARCH("accidentel",SAISIE!$B$5:$B$504)))))*(SAISIE!$E$5:$E$504<>"")),fz,FILTER(SAISIE!$E$5:$E$504,(VALUE(TRIM(LEFT(SAISIE!$A$5:$A$504,SEARCH("/",SAISIE!$A$5:$A$504&"/")-1)))=$A7)*(ISNUMBER(SEARCH("Neige",SAISIE!$B$5:$B$504))*(NOT(ISNUMBER(SEARCH("accidentel",SAISIE!$B$5:$B$504)))))*(SAISIE!$E$5:$E$504<>"")),IF(COUNT(fz)=0,"-",INDEX(v,MATCH(MIN(fz),fz,0)))),"-")) | M7: =IF($A7="","",IFERROR(LET(v,FILTER(SAISIE!$E$5:$E$504,(VALUE(TRIM(LEFT(SAISIE!$A$5:$A$504,SEARCH("/",SAISIE!$A$5:$A$504&"/")-1)))=$A7)*(ISNUMBER(SEARCH("Neige",SAISIE!$B$5:$B$504))*(NOT(ISNUMBER(SEARCH("accidentel",SAISIE!$B$5:$B$504)))))*(SAISIE!$E$5:$E$504<>"")),IF(COUNT(v)=0,"-",MIN(v))),"-")) | N7: =IF($A7="","",IFERROR(LET(v,FILTER(SAISIE!$C$5:$C$504,(VALUE(TRIM(LEFT(SAISIE!$A$5:$A$504,SEARCH("/",SAISIE!$A$5:$A$504&"/")-1)))=$A7)*(ISNUMBER(SEARCH("accidentel",SAISIE!$B$5:$B$504)))*(SAISIE!$E$5:$E$504<>"")),IF(COUNT(v)=0,"-",INDEX(v,1))),"-")) | O7: =IF($A7="","",IFERROR(LET(v,FILTER(SAISIE!$E$5:$E$504,(VALUE(TRIM(LEFT(SAISIE!$A$5:$A$504,SEARCH("/",SAISIE!$A$5:$A$504&"/")-1)))=$A7)*(ISNUMBER(SEARCH("accidentel",SAISIE!$B$5:$B$504)))*(SAISIE!$E$5:$E$504<>"")),IF(COUNT(v)=0,"-",INDEX(v,1))),"-"))
A8: =IFERROR(INDEX(IFERROR(UNIQUE(FILTER(VALUE(TRIM(LEFT(SAISIE!$A$5:$A$504,SEARCH("/",SAISIE!$A$5:$A$504&"/")-1))),SAISIE!$A$5:$A$504<>"")),""),4),"") | B8: =IF($A8="","",IFERROR(LET(v,FILTER(SAISIE!$C$5:$C$504,(VALUE(TRIM(LEFT(SAISIE!$A$5:$A$504,SEARCH("/",SAISIE!$A$5:$A$504&"/")-1)))=$A8)*(OR(ISNUMBER(SEARCH("Couverture",SAISIE!$B$5:$B$504)),LEFT(SAISIE!$B$5:$B$504,2)="G "))),IF(COUNT(v)=0,"-",INDEX(v,1))),"-")) | C8: =IF($A8="","",IFERROR(LET(v,FILTER(SAISIE!$E$5:$E$504,(VALUE(TRIM(LEFT(SAISIE!$A$5:$A$504,SEARCH("/",SAISIE!$A$5:$A$504&"/")-1)))=$A8)*(OR(ISNUMBER(SEARCH("Couverture",SAISIE!$B$5:$B$504)),LEFT(SAISIE!$B$5:$B$504,2)="G "))),IF(COUNT(v)=0,"-",INDEX(v,1))),"-")) | D8: =IF($A8="","",IFERROR(LET(fx,FILTER(SAISIE!$C$5:$C$504,(VALUE(TRIM(LEFT(SAISIE!$A$5:$A$504,SEARCH("/",SAISIE!$A$5:$A$504&"/")-1)))=$A8)*(ISNUMBER(SEARCH("Vent G/D",SAISIE!$B$5:$B$504)))*(SAISIE!$E$5:$E$504<>"")),fz,FILTER(SAISIE!$E$5:$E$504,(VALUE(TRIM(LEFT(SAISIE!$A$5:$A$504,SEARCH("/",SAISIE!$A$5:$A$504&"/")-1)))=$A8)*(ISNUMBER(SEARCH("Vent G/D",SAISIE!$B$5:$B$504)))*(SAISIE!$E$5:$E$504<>"")),mf,MIN(fz),IF(COUNT(fz)=0,"-",IF(MIN(fz)>=0,INDEX(fx,MATCH(MAX(fx),fx,0)),INDEX(fx,MATCH(mf,fz,0))))),"-")) | E8: =IF($A8="","",IFERROR(LET(fz,FILTER(SAISIE!$E$5:$E$504,(VALUE(TRIM(LEFT(SAISIE!$A$5:$A$504,SEARCH("/",SAISIE!$A$5:$A$504&"/")-1)))=$A8)*(ISNUMBER(SEARCH("Vent G/D",SAISIE!$B$5:$B$504)))*(SAISIE!$E$5:$E$504<>"")),IF(COUNT(fz)=0,"-",IF(MIN(fz)>=0,0,MIN(fz)))),"-")) | F8: =IF($A8="","",IFERROR(LET(fx,FILTER(SAISIE!$C$5:$C$504,(VALUE(TRIM(LEFT(SAISIE!$A$5:$A$504,SEARCH("/",SAISIE!$A$5:$A$504&"/")-1)))=$A8)*(ISNUMBER(SEARCH("Vent G/D",SAISIE!$B$5:$B$504)))*(SAISIE!$E$5:$E$504<>"")),fz,FILTER(SAISIE!$E$5:$E$504,(VALUE(TRIM(LEFT(SAISIE!$A$5:$A$504,SEARCH("/",SAISIE!$A$5:$A$504&"/")-1)))=$A8)*(ISNUMBER(SEARCH("Vent G/D",SAISIE!$B$5:$B$504)))*(SAISIE!$E$5:$E$504<>"")),Mf,MAX(fz),INDEX(fx,MATCH(Mf,fz,0))),"-")) | G8: =IF($A8="","",IFERROR(LET(fz,FILTER(SAISIE!$E$5:$E$504,(VALUE(TRIM(LEFT(SAISIE!$A$5:$A$504,SEARCH("/",SAISIE!$A$5:$A$504&"/")-1)))=$A8)*(ISNUMBER(SEARCH("Vent G/D",SAISIE!$B$5:$B$504)))*(SAISIE!$E$5:$E$504<>"")),IF(COUNT(fz)=0,"-",MAX(fz))),"-")) | H8: =IF($A8="","",IFERROR(LET(fx,FILTER(SAISIE!$C$5:$C$504,(VALUE(TRIM(LEFT(SAISIE!$A$5:$A$504,SEARCH("/",SAISIE!$A$5:$A$504&"/")-1)))=$A8)*(ISNUMBER(SEARCH("Vent D/G",SAISIE!$B$5:$B$504)))*(SAISIE!$E$5:$E$504<>"")),fz,FILTER(SAISIE!$E$5:$E$504,(VALUE(TRIM(LEFT(SAISIE!$A$5:$A$504,SEARCH("/",SAISIE!$A$5:$A$504&"/")-1)))=$A8)*(ISNUMBER(SEARCH("Vent D/G",SAISIE!$B$5:$B$504)))*(SAISIE!$E$5:$E$504<>"")),mf,MIN(fz),IF(COUNT(fz)=0,"-",IF(MIN(fz)>=0,INDEX(fx,MATCH(MAX(fx),fx,0)),INDEX(fx,MATCH(mf,fz,0))))),"-")) | I8: =IF($A8="","",IFERROR(LET(fz,FILTER(SAISIE!$E$5:$E$504,(VALUE(TRIM(LEFT(SAISIE!$A$5:$A$504,SEARCH("/",SAISIE!$A$5:$A$504&"/")-1)))=$A8)*(ISNUMBER(SEARCH("Vent D/G",SAISIE!$B$5:$B$504)))*(SAISIE!$E$5:$E$504<>"")),IF(COUNT(fz)=0,"-",IF(MIN(fz)>=0,0,MIN(fz)))),"-")) | J8: =IF($A8="","",IFERROR(LET(fx,FILTER(SAISIE!$C$5:$C$504,(VALUE(TRIM(LEFT(SAISIE!$A$5:$A$504,SEARCH("/",SAISIE!$A$5:$A$504&"/")-1)))=$A8)*(ISNUMBER(SEARCH("Vent D/G",SAISIE!$B$5:$B$504)))*(SAISIE!$E$5:$E$504<>"")),fz,FILTER(SAISIE!$E$5:$E$504,(VALUE(TRIM(LEFT(SAISIE!$A$5:$A$504,SEARCH("/",SAISIE!$A$5:$A$504&"/")-1)))=$A8)*(ISNUMBER(SEARCH("Vent D/G",SAISIE!$B$5:$B$504)))*(SAISIE!$E$5:$E$504<>"")),Mf,MAX(fz),INDEX(fx,MATCH(Mf,fz,0))),"-")) | K8: =IF($A8="","",IFERROR(LET(fz,FILTER(SAISIE!$E$5:$E$504,(VALUE(TRIM(LEFT(SAISIE!$A$5:$A$504,SEARCH("/",SAISIE!$A$5:$A$504&"/")-1)))=$A8)*(ISNUMBER(SEARCH("Vent D/G",SAISIE!$B$5:$B$504)))*(SAISIE!$E$5:$E$504<>"")),IF(COUNT(fz)=0,"-",MAX(fz))),"-")) | L8: =IF($A8="","",IFERROR(LET(v,FILTER(SAISIE!$C$5:$C$504,(VALUE(TRIM(LEFT(SAISIE!$A$5:$A$504,SEARCH("/",SAISIE!$A$5:$A$504&"/")-1)))=$A8)*(ISNUMBER(SEARCH("Neige",SAISIE!$B$5:$B$504))*(NOT(ISNUMBER(SEARCH("accidentel",SAISIE!$B$5:$B$504)))))*(SAISIE!$E$5:$E$504<>"")),fz,FILTER(SAISIE!$E$5:$E$504,(VALUE(TRIM(LEFT(SAISIE!$A$5:$A$504,SEARCH("/",SAISIE!$A$5:$A$504&"/")-1)))=$A8)*(ISNUMBER(SEARCH("Neige",SAISIE!$B$5:$B$504))*(NOT(ISNUMBER(SEARCH("accidentel",SAISIE!$B$5:$B$504)))))*(SAISIE!$E$5:$E$504<>"")),IF(COUNT(fz)=0,"-",INDEX(v,MATCH(MIN(fz),fz,0)))),"-")) | M8: =IF($A8="","",IFERROR(LET(v,FILTER(SAISIE!$E$5:$E$504,(VALUE(TRIM(LEFT(SAISIE!$A$5:$A$504,SEARCH("/",SAISIE!$A$5:$A$504&"/")-1)))=$A8)*(ISNUMBER(SEARCH("Neige",SAISIE!$B$5:$B$504))*(NOT(ISNUMBER(SEARCH("accidentel",SAISIE!$B$5:$B$504)))))*(SAISIE!$E$5:$E$504<>"")),IF(COUNT(v)=0,"-",MIN(v))),"-")) | N8: =IF($A8="","",IFERROR(LET(v,FILTER(SAISIE!$C$5:$C$504,(VALUE(TRIM(LEFT(SAISIE!$A$5:$A$504,SEARCH("/",SAISIE!$A$5:$A$504&"/")-1)))=$A8)*(ISNUMBER(SEARCH("accidentel",SAISIE!$B$5:$B$504)))*(SAISIE!$E$5:$E$504<>"")),IF(COUNT(v)=0,"-",INDEX(v,1))),"-")) | O8: =IF($A8="","",IFERROR(LET(v,FILTER(SAISIE!$E$5:$E$504,(VALUE(TRIM(LEFT(SAISIE!$A$5:$A$504,SEARCH("/",SAISIE!$A$5:$A$504&"/")-1)))=$A8)*(ISNUMBER(SEARCH("accidentel",SAISIE!$B$5:$B$504)))*(SAISIE!$E$5:$E$504<>"")),IF(COUNT(v)=0,"-",INDEX(v,1))),"-"))
A9: =IFERROR(INDEX(IFERROR(UNIQUE(FILTER(VALUE(TRIM(LEFT(SAISIE!$A$5:$A$504,SEARCH("/",SAISIE!$A$5:$A$504&"/")-1))),SAISIE!$A$5:$A$504<>"")),""),5),"") | B9: =IF($A9="","",IFERROR(LET(v,FILTER(SAISIE!$C$5:$C$504,(VALUE(TRIM(LEFT(SAISIE!$A$5:$A$504,SEARCH("/",SAISIE!$A$5:$A$504&"/")-1)))=$A9)*(OR(ISNUMBER(SEARCH("Couverture",SAISIE!$B$5:$B$504)),LEFT(SAISIE!$B$5:$B$504,2)="G "))),IF(COUNT(v)=0,"-",INDEX(v,1))),"-")) | C9: =IF($A9="","",IFERROR(LET(v,FILTER(SAISIE!$E$5:$E$504,(VALUE(TRIM(LEFT(SAISIE!$A$5:$A$504,SEARCH("/",SAISIE!$A$5:$A$504&"/")-1)))=$A9)*(OR(ISNUMBER(SEARCH("Couverture",SAISIE!$B$5:$B$504)),LEFT(SAISIE!$B$5:$B$504,2)="G "))),IF(COUNT(v)=0,"-",INDEX(v,1))),"-")) | D9: =IF($A9="","",IFERROR(LET(fx,FILTER(SAISIE!$C$5:$C$504,(VALUE(TRIM(LEFT(SAISIE!$A$5:$A$504,SEARCH("/",SAISIE!$A$5:$A$504&"/")-1)))=$A9)*(ISNUMBER(SEARCH("Vent G/D",SAISIE!$B$5:$B$504)))*(SAISIE!$E$5:$E$504<>"")),fz,FILTER(SAISIE!$E$5:$E$504,(VALUE(TRIM(LEFT(SAISIE!$A$5:$A$504,SEARCH("/",SAISIE!$A$5:$A$504&"/")-1)))=$A9)*(ISNUMBER(SEARCH("Vent G/D",SAISIE!$B$5:$B$504)))*(SAISIE!$E$5:$E$504<>"")),mf,MIN(fz),IF(COUNT(fz)=0,"-",IF(MIN(fz)>=0,INDEX(fx,MATCH(MAX(fx),fx,0)),INDEX(fx,MATCH(mf,fz,0))))),"-")) | E9: =IF($A9="","",IFERROR(LET(fz,FILTER(SAISIE!$E$5:$E$504,(VALUE(TRIM(LEFT(SAISIE!$A$5:$A$504,SEARCH("/",SAISIE!$A$5:$A$504&"/")-1)))=$A9)*(ISNUMBER(SEARCH("Vent G/D",SAISIE!$B$5:$B$504)))*(SAISIE!$E$5:$E$504<>"")),IF(COUNT(fz)=0,"-",IF(MIN(fz)>=0,0,MIN(fz)))),"-")) | F9: =IF($A9="","",IFERROR(LET(fx,FILTER(SAISIE!$C$5:$C$504,(VALUE(TRIM(LEFT(SAISIE!$A$5:$A$504,SEARCH("/",SAISIE!$A$5:$A$504&"/")-1)))=$A9)*(ISNUMBER(SEARCH("Vent G/D",SAISIE!$B$5:$B$504)))*(SAISIE!$E$5:$E$504<>"")),fz,FILTER(SAISIE!$E$5:$E$504,(VALUE(TRIM(LEFT(SAISIE!$A$5:$A$504,SEARCH("/",SAISIE!$A$5:$A$504&"/")-1)))=$A9)*(ISNUMBER(SEARCH("Vent G/D",SAISIE!$B$5:$B$504)))*(SAISIE!$E$5:$E$504<>"")),Mf,MAX(fz),INDEX(fx,MATCH(Mf,fz,0))),"-")) | G9: =IF($A9="","",IFERROR(LET(fz,FILTER(SAISIE!$E$5:$E$504,(VALUE(TRIM(LEFT(SAISIE!$A$5:$A$504,SEARCH("/",SAISIE!$A$5:$A$504&"/")-1)))=$A9)*(ISNUMBER(SEARCH("Vent G/D",SAISIE!$B$5:$B$504)))*(SAISIE!$E$5:$E$504<>"")),IF(COUNT(fz)=0,"-",MAX(fz))),"-")) | H9: =IF($A9="","",IFERROR(LET(fx,FILTER(SAISIE!$C$5:$C$504,(VALUE(TRIM(LEFT(SAISIE!$A$5:$A$504,SEARCH("/",SAISIE!$A$5:$A$504&"/")-1)))=$A9)*(ISNUMBER(SEARCH("Vent D/G",SAISIE!$B$5:$B$504)))*(SAISIE!$E$5:$E$504<>"")),fz,FILTER(SAISIE!$E$5:$E$504,(VALUE(TRIM(LEFT(SAISIE!$A$5:$A$504,SEARCH("/",SAISIE!$A$5:$A$504&"/")-1)))=$A9)*(ISNUMBER(SEARCH("Vent D/G",SAISIE!$B$5:$B$504)))*(SAISIE!$E$5:$E$504<>"")),mf,MIN(fz),IF(COUNT(fz)=0,"-",IF(MIN(fz)>=0,INDEX(fx,MATCH(MAX(fx),fx,0)),INDEX(fx,MATCH(mf,fz,0))))),"-")) | I9: =IF($A9="","",IFERROR(LET(fz,FILTER(SAISIE!$E$5:$E$504,(VALUE(TRIM(LEFT(SAISIE!$A$5:$A$504,SEARCH("/",SAISIE!$A$5:$A$504&"/")-1)))=$A9)*(ISNUMBER(SEARCH("Vent D/G",SAISIE!$B$5:$B$504)))*(SAISIE!$E$5:$E$504<>"")),IF(COUNT(fz)=0,"-",IF(MIN(fz)>=0,0,MIN(fz)))),"-")) | J9: =IF($A9="","",IFERROR(LET(fx,FILTER(SAISIE!$C$5:$C$504,(VALUE(TRIM(LEFT(SAISIE!$A$5:$A$504,SEARCH("/",SAISIE!$A$5:$A$504&"/")-1)))=$A9)*(ISNUMBER(SEARCH("Vent D/G",SAISIE!$B$5:$B$504)))*(SAISIE!$E$5:$E$504<>"")),fz,FILTER(SAISIE!$E$5:$E$504,(VALUE(TRIM(LEFT(SAISIE!$A$5:$A$504,SEARCH("/",SAISIE!$A$5:$A$504&"/")-1)))=$A9)*(ISNUMBER(SEARCH("Vent D/G",SAISIE!$B$5:$B$504)))*(SAISIE!$E$5:$E$504<>"")),Mf,MAX(fz),INDEX(fx,MATCH(Mf,fz,0))),"-")) | K9: =IF($A9="","",IFERROR(LET(fz,FILTER(SAISIE!$E$5:$E$504,(VALUE(TRIM(LEFT(SAISIE!$A$5:$A$504,SEARCH("/",SAISIE!$A$5:$A$504&"/")-1)))=$A9)*(ISNUMBER(SEARCH("Vent D/G",SAISIE!$B$5:$B$504)))*(SAISIE!$E$5:$E$504<>"")),IF(COUNT(fz)=0,"-",MAX(fz))),"-")) | L9: =IF($A9="","",IFERROR(LET(v,FILTER(SAISIE!$C$5:$C$504,(VALUE(TRIM(LEFT(SAISIE!$A$5:$A$504,SEARCH("/",SAISIE!$A$5:$A$504&"/")-1)))=$A9)*(ISNUMBER(SEARCH("Neige",SAISIE!$B$5:$B$504))*(NOT(ISNUMBER(SEARCH("accidentel",SAISIE!$B$5:$B$504)))))*(SAISIE!$E$5:$E$504<>"")),fz,FILTER(SAISIE!$E$5:$E$504,(VALUE(TRIM(LEFT(SAISIE!$A$5:$A$504,SEARCH("/",SAISIE!$A$5:$A$504&"/")-1)))=$A9)*(ISNUMBER(SEARCH("Neige",SAISIE!$B$5:$B$504))*(NOT(ISNUMBER(SEARCH("accidentel",SAISIE!$B$5:$B$504)))))*(SAISIE!$E$5:$E$504<>"")),IF(COUNT(fz)=0,"-",INDEX(v,MATCH(MIN(fz),fz,0)))),"-")) | M9: =IF($A9="","",IFERROR(LET(v,FILTER(SAISIE!$E$5:$E$504,(VALUE(TRIM(LEFT(SAISIE!$A$5:$A$504,SEARCH("/",SAISIE!$A$5:$A$504&"/")-1)))=$A9)*(ISNUMBER(SEARCH("Neige",SAISIE!$B$5:$B$504))*(NOT(ISNUMBER(SEARCH("accidentel",SAISIE!$B$5:$B$504)))))*(SAISIE!$E$5:$E$504<>"")),IF(COUNT(v)=0,"-",MIN(v))),"-")) | N9: =IF($A9="","",IFERROR(LET(v,FILTER(SAISIE!$C$5:$C$504,(VALUE(TRIM(LEFT(SAISIE!$A$5:$A$504,SEARCH("/",SAISIE!$A$5:$A$504&"/")-1)))=$A9)*(ISNUMBER(SEARCH("accidentel",SAISIE!$B$5:$B$504)))*(SAISIE!$E$5:$E$504<>"")),IF(COUNT(v)=0,"-",INDEX(v,1))),"-")) | O9: =IF($A9="","",IFERROR(LET(v,FILTER(SAISIE!$E$5:$E$504,(VALUE(TRIM(LEFT(SAISIE!$A$5:$A$504,SEARCH("/",SAISIE!$A$5:$A$504&"/")-1)))=$A9)*(ISNUMBER(SEARCH("accidentel",SAISIE!$B$5:$B$504)))*(SAISIE!$E$5:$E$504<>"")),IF(COUNT(v)=0,"-",INDEX(v,1))),"-"))
A10: =IFERROR(INDEX(IFERROR(UNIQUE(FILTER(VALUE(TRIM(LEFT(SAISIE!$A$5:$A$504,SEARCH("/",SAISIE!$A$5:$A$504&"/")-1))),SAISIE!$A$5:$A$504<>"")),""),6),"") | B10: =IF($A10="","",IFERROR(LET(v,FILTER(SAISIE!$C$5:$C$504,(VALUE(TRIM(LEFT(SAISIE!$A$5:$A$504,SEARCH("/",SAISIE!$A$5:$A$504&"/")-1)))=$A10)*(OR(ISNUMBER(SEARCH("Couverture",SAISIE!$B$5:$B$504)),LEFT(SAISIE!$B$5:$B$504,2)="G "))),IF(COUNT(v)=0,"-",INDEX(v,1))),"-")) | C10: =IF($A10="","",IFERROR(LET(v,FILTER(SAISIE!$E$5:$E$504,(VALUE(TRIM(LEFT(SAISIE!$A$5:$A$504,SEARCH("/",SAISIE!$A$5:$A$504&"/")-1)))=$A10)*(OR(ISNUMBER(SEARCH("Couverture",SAISIE!$B$5:$B$504)),LEFT(SAISIE!$B$5:$B$504,2)="G "))),IF(COUNT(v)=0,"-",INDEX(v,1))),"-")) | D10: =IF($A10="","",IFERROR(LET(fx,FILTER(SAISIE!$C$5:$C$504,(VALUE(TRIM(LEFT(SAISIE!$A$5:$A$504,SEARCH("/",SAISIE!$A$5:$A$504&"/")-1)))=$A10)*(ISNUMBER(SEARCH("Vent G/D",SAISIE!$B$5:$B$504)))*(SAISIE!$E$5:$E$504<>"")),fz,FILTER(SAISIE!$E$5:$E$504,(VALUE(TRIM(LEFT(SAISIE!$A$5:$A$504,SEARCH("/",SAISIE!$A$5:$A$504&"/")-1)))=$A10)*(ISNUMBER(SEARCH("Vent G/D",SAISIE!$B$5:$B$504)))*(SAISIE!$E$5:$E$504<>"")),mf,MIN(fz),IF(COUNT(fz)=0,"-",IF(MIN(fz)>=0,INDEX(fx,MATCH(MAX(fx),fx,0)),INDEX(fx,MATCH(mf,fz,0))))),"-")) | E10: =IF($A10="","",IFERROR(LET(fz,FILTER(SAISIE!$E$5:$E$504,(VALUE(TRIM(LEFT(SAISIE!$A$5:$A$504,SEARCH("/",SAISIE!$A$5:$A$504&"/")-1)))=$A10)*(ISNUMBER(SEARCH("Vent G/D",SAISIE!$B$5:$B$504)))*(SAISIE!$E$5:$E$504<>"")),IF(COUNT(fz)=0,"-",IF(MIN(fz)>=0,0,MIN(fz)))),"-")) | F10: =IF($A10="","",IFERROR(LET(fx,FILTER(SAISIE!$C$5:$C$504,(VALUE(TRIM(LEFT(SAISIE!$A$5:$A$504,SEARCH("/",SAISIE!$A$5:$A$504&"/")-1)))=$A10)*(ISNUMBER(SEARCH("Vent G/D",SAISIE!$B$5:$B$504)))*(SAISIE!$E$5:$E$504<>"")),fz,FILTER(SAISIE!$E$5:$E$504,(VALUE(TRIM(LEFT(SAISIE!$A$5:$A$504,SEARCH("/",SAISIE!$A$5:$A$504&"/")-1)))=$A10)*(ISNUMBER(SEARCH("Vent G/D",SAISIE!$B$5:$B$504)))*(SAISIE!$E$5:$E$504<>"")),Mf,MAX(fz),INDEX(fx,MATCH(Mf,fz,0))),"-")) | G10: =IF($A10="","",IFERROR(LET(fz,FILTER(SAISIE!$E$5:$E$504,(VALUE(TRIM(LEFT(SAISIE!$A$5:$A$504,SEARCH("/",SAISIE!$A$5:$A$504&"/")-1)))=$A10)*(ISNUMBER(SEARCH("Vent G/D",SAISIE!$B$5:$B$504)))*(SAISIE!$E$5:$E$504<>"")),IF(COUNT(fz)=0,"-",MAX(fz))),"-")) | H10: =IF($A10="","",IFERROR(LET(fx,FILTER(SAISIE!$C$5:$C$504,(VALUE(TRIM(LEFT(SAISIE!$A$5:$A$504,SEARCH("/",SAISIE!$A$5:$A$504&"/")-1)))=$A10)*(ISNUMBER(SEARCH("Vent D/G",SAISIE!$B$5:$B$504)))*(SAISIE!$E$5:$E$504<>"")),fz,FILTER(SAISIE!$E$5:$E$504,(VALUE(TRIM(LEFT(SAISIE!$A$5:$A$504,SEARCH("/",SAISIE!$A$5:$A$504&"/")-1)))=$A10)*(ISNUMBER(SEARCH("Vent D/G",SAISIE!$B$5:$B$504)))*(SAISIE!$E$5:$E$504<>"")),mf,MIN(fz),IF(COUNT(fz)=0,"-",IF(MIN(fz)>=0,INDEX(fx,MATCH(MAX(fx),fx,0)),INDEX(fx,MATCH(mf,fz,0))))),"-")) | I10: =IF($A10="","",IFERROR(LET(fz,FILTER(SAISIE!$E$5:$E$504,(VALUE(TRIM(LEFT(SAISIE!$A$5:$A$504,SEARCH("/",SAISIE!$A$5:$A$504&"/")-1)))=$A10)*(ISNUMBER(SEARCH("Vent D/G",SAISIE!$B$5:$B$504)))*(SAISIE!$E$5:$E$504<>"")),IF(COUNT(fz)=0,"-",IF(MIN(fz)>=0,0,MIN(fz)))),"-")) | J10: =IF($A10="","",IFERROR(LET(fx,FILTER(SAISIE!$C$5:$C$504,(VALUE(TRIM(LEFT(SAISIE!$A$5:$A$504,SEARCH("/",SAISIE!$A$5:$A$504&"/")-1)))=$A10)*(ISNUMBER(SEARCH("Vent D/G",SAISIE!$B$5:$B$504)))*(SAISIE!$E$5:$E$504<>"")),fz,FILTER(SAISIE!$E$5:$E$504,(VALUE(TRIM(LEFT(SAISIE!$A$5:$A$504,SEARCH("/",SAISIE!$A$5:$A$504&"/")-1)))=$A10)*(ISNUMBER(SEARCH("Vent D/G",SAISIE!$B$5:$B$504)))*(SAISIE!$E$5:$E$504<>"")),Mf,MAX(fz),INDEX(fx,MATCH(Mf,fz,0))),"-")) | K10: =IF($A10="","",IFERROR(LET(fz,FILTER(SAISIE!$E$5:$E$504,(VALUE(TRIM(LEFT(SAISIE!$A$5:$A$504,SEARCH("/",SAISIE!$A$5:$A$504&"/")-1)))=$A10)*(ISNUMBER(SEARCH("Vent D/G",SAISIE!$B$5:$B$504)))*(SAISIE!$E$5:$E$504<>"")),IF(COUNT(fz)=0,"-",MAX(fz))),"-")) | L10: =IF($A10="","",IFERROR(LET(v,FILTER(SAISIE!$C$5:$C$504,(VALUE(TRIM(LEFT(SAISIE!$A$5:$A$504,SEARCH("/",SAISIE!$A$5:$A$504&"/")-1)))=$A10)*(ISNUMBER(SEARCH("Neige",SAISIE!$B$5:$B$504))*(NOT(ISNUMBER(SEARCH("accidentel",SAISIE!$B$5:$B$504)))))*(SAISIE!$E$5:$E$504<>"")),fz,FILTER(SAISIE!$E$5:$E$504,(VALUE(TRIM(LEFT(SAISIE!$A$5:$A$504,SEARCH("/",SAISIE!$A$5:$A$504&"/")-1)))=$A10)*(ISNUMBER(SEARCH("Neige",SAISIE!$B$5:$B$504))*(NOT(ISNUMBER(SEARCH("accidentel",SAISIE!$B$5:$B$504)))))*(SAISIE!$E$5:$E$504<>"")),IF(COUNT(fz)=0,"-",INDEX(v,MATCH(MIN(fz),fz,0)))),"-")) | M10: =IF($A10="","",IFERROR(LET(v,FILTER(SAISIE!$E$5:$E$504,(VALUE(TRIM(LEFT(SAISIE!$A$5:$A$504,SEARCH("/",SAISIE!$A$5:$A$504&"/")-1)))=$A10)*(ISNUMBER(SEARCH("Neige",SAISIE!$B$5:$B$504))*(NOT(ISNUMBER(SEARCH("accidentel",SAISIE!$B$5:$B$504)))))*(SAISIE!$E$5:$E$504<>"")),IF(COUNT(v)=0,"-",MIN(v))),"-")) | N10: =IF($A10="","",IFERROR(LET(v,FILTER(SAISIE!$C$5:$C$504,(VALUE(TRIM(LEFT(SAISIE!$A$5:$A$504,SEARCH("/",SAISIE!$A$5:$A$504&"/")-1)))=$A10)*(ISNUMBER(SEARCH("accidentel",SAISIE!$B$5:$B$504)))*(SAISIE!$E$5:$E$504<>"")),IF(COUNT(v)=0,"-",INDEX(v,1))),"-")) | O10: =IF($A10="","",IFERROR(LET(v,FILTER(SAISIE!$E$5:$E$504,(VALUE(TRIM(LEFT(SAISIE!$A$5:$A$504,SEARCH("/",SAISIE!$A$5:$A$504&"/")-1)))=$A10)*(ISNUMBER(SEARCH("accidentel",SAISIE!$B$5:$B$504)))*(SAISIE!$E$5:$E$504<>"")),IF(COUNT(v)=0,"-",INDEX(v,1))),"-"))
A11: =IFERROR(INDEX(IFERROR(UNIQUE(FILTER(VALUE(TRIM(LEFT(SAISIE!$A$5:$A$504,SEARCH("/",SAISIE!$A$5:$A$504&"/")-1))),SAISIE!$A$5:$A$504<>"")),""),7),"") | B11: =IF($A11="","",IFERROR(LET(v,FILTER(SAISIE!$C$5:$C$504,(VALUE(TRIM(LEFT(SAISIE!$A$5:$A$504,SEARCH("/",SAISIE!$A$5:$A$504&"/")-1)))=$A11)*(OR(ISNUMBER(SEARCH("Couverture",SAISIE!$B$5:$B$504)),LEFT(SAISIE!$B$5:$B$504,2)="G "))),IF(COUNT(v)=0,"-",INDEX(v,1))),"-")) | C11: =IF($A11="","",IFERROR(LET(v,FILTER(SAISIE!$E$5:$E$504,(VALUE(TRIM(LEFT(SAISIE!$A$5:$A$504,SEARCH("/",SAISIE!$A$5:$A$504&"/")-1)))=$A11)*(OR(ISNUMBER(SEARCH("Couverture",SAISIE!$B$5:$B$504)),LEFT(SAISIE!$B$5:$B$504,2)="G "))),IF(COUNT(v)=0,"-",INDEX(v,1))),"-")) | D11: =IF($A11="","",IFERROR(LET(fx,FILTER(SAISIE!$C$5:$C$504,(VALUE(TRIM(LEFT(SAISIE!$A$5:$A$504,SEARCH("/",SAISIE!$A$5:$A$504&"/")-1)))=$A11)*(ISNUMBER(SEARCH("Vent G/D",SAISIE!$B$5:$B$504)))*(SAISIE!$E$5:$E$504<>"")),fz,FILTER(SAISIE!$E$5:$E$504,(VALUE(TRIM(LEFT(SAISIE!$A$5:$A$504,SEARCH("/",SAISIE!$A$5:$A$504&"/")-1)))=$A11)*(ISNUMBER(SEARCH("Vent G/D",SAISIE!$B$5:$B$504)))*(SAISIE!$E$5:$E$504<>"")),mf,MIN(fz),IF(COUNT(fz)=0,"-",IF(MIN(fz)>=0,INDEX(fx,MATCH(MAX(fx),fx,0)),INDEX(fx,MATCH(mf,fz,0))))),"-")) | E11: =IF($A11="","",IFERROR(LET(fz,FILTER(SAISIE!$E$5:$E$504,(VALUE(TRIM(LEFT(SAISIE!$A$5:$A$504,SEARCH("/",SAISIE!$A$5:$A$504&"/")-1)))=$A11)*(ISNUMBER(SEARCH("Vent G/D",SAISIE!$B$5:$B$504)))*(SAISIE!$E$5:$E$504<>"")),IF(COUNT(fz)=0,"-",IF(MIN(fz)>=0,0,MIN(fz)))),"-")) | F11: =IF($A11="","",IFERROR(LET(fx,FILTER(SAISIE!$C$5:$C$504,(VALUE(TRIM(LEFT(SAISIE!$A$5:$A$504,SEARCH("/",SAISIE!$A$5:$A$504&"/")-1)))=$A11)*(ISNUMBER(SEARCH("Vent G/D",SAISIE!$B$5:$B$504)))*(SAISIE!$E$5:$E$504<>"")),fz,FILTER(SAISIE!$E$5:$E$504,(VALUE(TRIM(LEFT(SAISIE!$A$5:$A$504,SEARCH("/",SAISIE!$A$5:$A$504&"/")-1)))=$A11)*(ISNUMBER(SEARCH("Vent G/D",SAISIE!$B$5:$B$504)))*(SAISIE!$E$5:$E$504<>"")),Mf,MAX(fz),INDEX(fx,MATCH(Mf,fz,0))),"-")) | G11: =IF($A11="","",IFERROR(LET(fz,FILTER(SAISIE!$E$5:$E$504,(VALUE(TRIM(LEFT(SAISIE!$A$5:$A$504,SEARCH("/",SAISIE!$A$5:$A$504&"/")-1)))=$A11)*(ISNUMBER(SEARCH("Vent G/D",SAISIE!$B$5:$B$504)))*(SAISIE!$E$5:$E$504<>"")),IF(COUNT(fz)=0,"-",MAX(fz))),"-")) | H11: =IF($A11="","",IFERROR(LET(fx,FILTER(SAISIE!$C$5:$C$504,(VALUE(TRIM(LEFT(SAISIE!$A$5:$A$504,SEARCH("/",SAISIE!$A$5:$A$504&"/")-1)))=$A11)*(ISNUMBER(SEARCH("Vent D/G",SAISIE!$B$5:$B$504)))*(SAISIE!$E$5:$E$504<>"")),fz,FILTER(SAISIE!$E$5:$E$504,(VALUE(TRIM(LEFT(SAISIE!$A$5:$A$504,SEARCH("/",SAISIE!$A$5:$A$504&"/")-1)))=$A11)*(ISNUMBER(SEARCH("Vent D/G",SAISIE!$B$5:$B$504)))*(SAISIE!$E$5:$E$504<>"")),mf,MIN(fz),IF(COUNT(fz)=0,"-",IF(MIN(fz)>=0,INDEX(fx,MATCH(MAX(fx),fx,0)),INDEX(fx,MATCH(mf,fz,0))))),"-")) | I11: =IF($A11="","",IFERROR(LET(fz,FILTER(SAISIE!$E$5:$E$504,(VALUE(TRIM(LEFT(SAISIE!$A$5:$A$504,SEARCH("/",SAISIE!$A$5:$A$504&"/")-1)))=$A11)*(ISNUMBER(SEARCH("Vent D/G",SAISIE!$B$5:$B$504)))*(SAISIE!$E$5:$E$504<>"")),IF(COUNT(fz)=0,"-",IF(MIN(fz)>=0,0,MIN(fz)))),"-")) | J11: =IF($A11="","",IFERROR(LET(fx,FILTER(SAISIE!$C$5:$C$504,(VALUE(TRIM(LEFT(SAISIE!$A$5:$A$504,SEARCH("/",SAISIE!$A$5:$A$504&"/")-1)))=$A11)*(ISNUMBER(SEARCH("Vent D/G",SAISIE!$B$5:$B$504)))*(SAISIE!$E$5:$E$504<>"")),fz,FILTER(SAISIE!$E$5:$E$504,(VALUE(TRIM(LEFT(SAISIE!$A$5:$A$504,SEARCH("/",SAISIE!$A$5:$A$504&"/")-1)))=$A11)*(ISNUMBER(SEARCH("Vent D/G",SAISIE!$B$5:$B$504)))*(SAISIE!$E$5:$E$504<>"")),Mf,MAX(fz),INDEX(fx,MATCH(Mf,fz,0))),"-")) | K11: =IF($A11="","",IFERROR(LET(fz,FILTER(SAISIE!$E$5:$E$504,(VALUE(TRIM(LEFT(SAISIE!$A$5:$A$504,SEARCH("/",SAISIE!$A$5:$A$504&"/")-1)))=$A11)*(ISNUMBER(SEARCH("Vent D/G",SAISIE!$B$5:$B$504)))*(SAISIE!$E$5:$E$504<>"")),IF(COUNT(fz)=0,"-",MAX(fz))),"-")) | L11: =IF($A11="","",IFERROR(LET(v,FILTER(SAISIE!$C$5:$C$504,(VALUE(TRIM(LEFT(SAISIE!$A$5:$A$504,SEARCH("/",SAISIE!$A$5:$A$504&"/")-1)))=$A11)*(ISNUMBER(SEARCH("Neige",SAISIE!$B$5:$B$504))*(NOT(ISNUMBER(SEARCH("accidentel",SAISIE!$B$5:$B$504)))))*(SAISIE!$E$5:$E$504<>"")),fz,FILTER(SAISIE!$E$5:$E$504,(VALUE(TRIM(LEFT(SAISIE!$A$5:$A$504,SEARCH("/",SAISIE!$A$5:$A$504&"/")-1)))=$A11)*(ISNUMBER(SEARCH("Neige",SAISIE!$B$5:$B$504))*(NOT(ISNUMBER(SEARCH("accidentel",SAISIE!$B$5:$B$504)))))*(SAISIE!$E$5:$E$504<>"")),IF(COUNT(fz)=0,"-",INDEX(v,MATCH(MIN(fz),fz,0)))),"-")) | M11: =IF($A11="","",IFERROR(LET(v,FILTER(SAISIE!$E$5:$E$504,(VALUE(TRIM(LEFT(SAISIE!$A$5:$A$504,SEARCH("/",SAISIE!$A$5:$A$504&"/")-1)))=$A11)*(ISNUMBER(SEARCH("Neige",SAISIE!$B$5:$B$504))*(NOT(ISNUMBER(SEARCH("accidentel",SAISIE!$B$5:$B$504)))))*(SAISIE!$E$5:$E$504<>"")),IF(COUNT(v)=0,"-",MIN(v))),"-")) | N11: =IF($A11="","",IFERROR(LET(v,FILTER(SAISIE!$C$5:$C$504,(VALUE(TRIM(LEFT(SAISIE!$A$5:$A$504,SEARCH("/",SAISIE!$A$5:$A$504&"/")-1)))=$A11)*(ISNUMBER(SEARCH("accidentel",SAISIE!$B$5:$B$504)))*(SAISIE!$E$5:$E$504<>"")),IF(COUNT(v)=0,"-",INDEX(v,1))),"-")) | O11: =IF($A11="","",IFERROR(LET(v,FILTER(SAISIE!$E$5:$E$504,(VALUE(TRIM(LEFT(SAISIE!$A$5:$A$504,SEARCH("/",SAISIE!$A$5:$A$504&"/")-1)))=$A11)*(ISNUMBER(SEARCH("accidentel",SAISIE!$B$5:$B$504)))*(SAISIE!$E$5:$E$504<>"")),IF(COUNT(v)=0,"-",INDEX(v,1))),"-"))
A12: =IFERROR(INDEX(IFERROR(UNIQUE(FILTER(VALUE(TRIM(LEFT(SAISIE!$A$5:$A$504,SEARCH("/",SAISIE!$A$5:$A$504&"/")-1))),SAISIE!$A$5:$A$504<>"")),""),8),"") | B12: =IF($A12="","",IFERROR(LET(v,FILTER(SAISIE!$C$5:$C$504,(VALUE(TRIM(LEFT(SAISIE!$A$5:$A$504,SEARCH("/",SAISIE!$A$5:$A$504&"/")-1)))=$A12)*(OR(ISNUMBER(SEARCH("Couverture",SAISIE!$B$5:$B$504)),LEFT(SAISIE!$B$5:$B$504,2)="G "))),IF(COUNT(v)=0,"-",INDEX(v,1))),"-")) | C12: =IF($A12="","",IFERROR(LET(v,FILTER(SAISIE!$E$5:$E$504,(VALUE(TRIM(LEFT(SAISIE!$A$5:$A$504,SEARCH("/",SAISIE!$A$5:$A$504&"/")-1)))=$A12)*(OR(ISNUMBER(SEARCH("Couverture",SAISIE!$B$5:$B$504)),LEFT(SAISIE!$B$5:$B$504,2)="G "))),IF(COUNT(v)=0,"-",INDEX(v,1))),"-")) | D12: =IF($A12="","",IFERROR(LET(fx,FILTER(SAISIE!$C$5:$C$504,(VALUE(TRIM(LEFT(SAISIE!$A$5:$A$504,SEARCH("/",SAISIE!$A$5:$A$504&"/")-1)))=$A12)*(ISNUMBER(SEARCH("Vent G/D",SAISIE!$B$5:$B$504)))*(SAISIE!$E$5:$E$504<>"")),fz,FILTER(SAISIE!$E$5:$E$504,(VALUE(TRIM(LEFT(SAISIE!$A$5:$A$504,SEARCH("/",SAISIE!$A$5:$A$504&"/")-1)))=$A12)*(ISNUMBER(SEARCH("Vent G/D",SAISIE!$B$5:$B$504)))*(SAISIE!$E$5:$E$504<>"")),mf,MIN(fz),IF(COUNT(fz)=0,"-",IF(MIN(fz)>=0,INDEX(fx,MATCH(MAX(fx),fx,0)),INDEX(fx,MATCH(mf,fz,0))))),"-")) | E12: =IF($A12="","",IFERROR(LET(fz,FILTER(SAISIE!$E$5:$E$504,(VALUE(TRIM(LEFT(SAISIE!$A$5:$A$504,SEARCH("/",SAISIE!$A$5:$A$504&"/")-1)))=$A12)*(ISNUMBER(SEARCH("Vent G/D",SAISIE!$B$5:$B$504)))*(SAISIE!$E$5:$E$504<>"")),IF(COUNT(fz)=0,"-",IF(MIN(fz)>=0,0,MIN(fz)))),"-")) | F12: =IF($A12="","",IFERROR(LET(fx,FILTER(SAISIE!$C$5:$C$504,(VALUE(TRIM(LEFT(SAISIE!$A$5:$A$504,SEARCH("/",SAISIE!$A$5:$A$504&"/")-1)))=$A12)*(ISNUMBER(SEARCH("Vent G/D",SAISIE!$B$5:$B$504)))*(SAISIE!$E$5:$E$504<>"")),fz,FILTER(SAISIE!$E$5:$E$504,(VALUE(TRIM(LEFT(SAISIE!$A$5:$A$504,SEARCH("/",SAISIE!$A$5:$A$504&"/")-1)))=$A12)*(ISNUMBER(SEARCH("Vent G/D",SAISIE!$B$5:$B$504)))*(SAISIE!$E$5:$E$504<>"")),Mf,MAX(fz),INDEX(fx,MATCH(Mf,fz,0))),"-")) | G12: =IF($A12="","",IFERROR(LET(fz,FILTER(SAISIE!$E$5:$E$504,(VALUE(TRIM(LEFT(SAISIE!$A$5:$A$504,SEARCH("/",SAISIE!$A$5:$A$504&"/")-1)))=$A12)*(ISNUMBER(SEARCH("Vent G/D",SAISIE!$B$5:$B$504)))*(SAISIE!$E$5:$E$504<>"")),IF(COUNT(fz)=0,"-",MAX(fz))),"-")) | H12: =IF($A12="","",IFERROR(LET(fx,FILTER(SAISIE!$C$5:$C$504,(VALUE(TRIM(LEFT(SAISIE!$A$5:$A$504,SEARCH("/",SAISIE!$A$5:$A$504&"/")-1)))=$A12)*(ISNUMBER(SEARCH("Vent D/G",SAISIE!$B$5:$B$504)))*(SAISIE!$E$5:$E$504<>"")),fz,FILTER(SAISIE!$E$5:$E$504,(VALUE(TRIM(LEFT(SAISIE!$A$5:$A$504,SEARCH("/",SAISIE!$A$5:$A$504&"/")-1)))=$A12)*(ISNUMBER(SEARCH("Vent D/G",SAISIE!$B$5:$B$504)))*(SAISIE!$E$5:$E$504<>"")),mf,MIN(fz),IF(COUNT(fz)=0,"-",IF(MIN(fz)>=0,INDEX(fx,MATCH(MAX(fx),fx,0)),INDEX(fx,MATCH(mf,fz,0))))),"-")) | I12: =IF($A12="","",IFERROR(LET(fz,FILTER(SAISIE!$E$5:$E$504,(VALUE(TRIM(LEFT(SAISIE!$A$5:$A$504,SEARCH("/",SAISIE!$A$5:$A$504&"/")-1)))=$A12)*(ISNUMBER(SEARCH("Vent D/G",SAISIE!$B$5:$B$504)))*(SAISIE!$E$5:$E$504<>"")),IF(COUNT(fz)=0,"-",IF(MIN(fz)>=0,0,MIN(fz)))),"-")) | J12: =IF($A12="","",IFERROR(LET(fx,FILTER(SAISIE!$C$5:$C$504,(VALUE(TRIM(LEFT(SAISIE!$A$5:$A$504,SEARCH("/",SAISIE!$A$5:$A$504&"/")-1)))=$A12)*(ISNUMBER(SEARCH("Vent D/G",SAISIE!$B$5:$B$504)))*(SAISIE!$E$5:$E$504<>"")),fz,FILTER(SAISIE!$E$5:$E$504,(VALUE(TRIM(LEFT(SAISIE!$A$5:$A$504,SEARCH("/",SAISIE!$A$5:$A$504&"/")-1)))=$A12)*(ISNUMBER(SEARCH("Vent D/G",SAISIE!$B$5:$B$504)))*(SAISIE!$E$5:$E$504<>"")),Mf,MAX(fz),INDEX(fx,MATCH(Mf,fz,0))),"-")) | K12: =IF($A12="","",IFERROR(LET(fz,FILTER(SAISIE!$E$5:$E$504,(VALUE(TRIM(LEFT(SAISIE!$A$5:$A$504,SEARCH("/",SAISIE!$A$5:$A$504&"/")-1)))=$A12)*(ISNUMBER(SEARCH("Vent D/G",SAISIE!$B$5:$B$504)))*(SAISIE!$E$5:$E$504<>"")),IF(COUNT(fz)=0,"-",MAX(fz))),"-")) | L12: =IF($A12="","",IFERROR(LET(v,FILTER(SAISIE!$C$5:$C$504,(VALUE(TRIM(LEFT(SAISIE!$A$5:$A$504,SEARCH("/",SAISIE!$A$5:$A$504&"/")-1)))=$A12)*(ISNUMBER(SEARCH("Neige",SAISIE!$B$5:$B$504))*(NOT(ISNUMBER(SEARCH("accidentel",SAISIE!$B$5:$B$504)))))*(SAISIE!$E$5:$E$504<>"")),fz,FILTER(SAISIE!$E$5:$E$504,(VALUE(TRIM(LEFT(SAISIE!$A$5:$A$504,SEARCH("/",SAISIE!$A$5:$A$504&"/")-1)))=$A12)*(ISNUMBER(SEARCH("Neige",SAISIE!$B$5:$B$504))*(NOT(ISNUMBER(SEARCH("accidentel",SAISIE!$B$5:$B$504)))))*(SAISIE!$E$5:$E$504<>"")),IF(COUNT(fz)=0,"-",INDEX(v,MATCH(MIN(fz),fz,0)))),"-")) | M12: =IF($A12="","",IFERROR(LET(v,FILTER(SAISIE!$E$5:$E$504,(VALUE(TRIM(LEFT(SAISIE!$A$5:$A$504,SEARCH("/",SAISIE!$A$5:$A$504&"/")-1)))=$A12)*(ISNUMBER(SEARCH("Neige",SAISIE!$B$5:$B$504))*(NOT(ISNUMBER(SEARCH("accidentel",SAISIE!$B$5:$B$504)))))*(SAISIE!$E$5:$E$504<>"")),IF(COUNT(v)=0,"-",MIN(v))),"-")) | N12: =IF($A12="","",IFERROR(LET(v,FILTER(SAISIE!$C$5:$C$504,(VALUE(TRIM(LEFT(SAISIE!$A$5:$A$504,SEARCH("/",SAISIE!$A$5:$A$504&"/")-1)))=$A12)*(ISNUMBER(SEARCH("accidentel",SAISIE!$B$5:$B$504)))*(SAISIE!$E$5:$E$504<>"")),IF(COUNT(v)=0,"-",INDEX(v,1))),"-")) | O12: =IF($A12="","",IFERROR(LET(v,FILTER(SAISIE!$E$5:$E$504,(VALUE(TRIM(LEFT(SAISIE!$A$5:$A$504,SEARCH("/",SAISIE!$A$5:$A$504&"/")-1)))=$A12)*(ISNUMBER(SEARCH("accidentel",SAISIE!$B$5:$B$504)))*(SAISIE!$E$5:$E$504<>"")),IF(COUNT(v)=0,"-",INDEX(v,1))),"-"))
