Workbook

Sheet MODE EMPLOI
A1: DDC Calculateur — 2 tableaux côte à côte
A4: SAISIE et SYNTHESE : 2 tableaux côte à côte, séparés par les colonnes G-H.
A6: GAUCHE (A-F) : AVEC FY — Noeud_Cas, Nom_cas, FX, FY, FZ
A7: DROITE (I-M) : SANS FY — Noeud_Cas, Nom_cas, FX, FZ
A9: Collez vos données dans UN seul côté (pas les deux).
A10: Note : FZ > 0 = soulèvement, FZ < 0 = compression. F9 si besoin.

Sheet SAISIE
A1: SAISIE — Collez vos cas de charge
A2: Gauche = avec FY | Droite = sans FY | Colonnes G-H = espace
A3: TABLEAU — AVEC FY | I3: TABLEAU — SANS FY
A4: Noeud_Cas | B4: Nom_cas | C4: FX_daN | D4: FY_daN | E4: FZ_daN | F4: Noeud | I4: Noeud_Cas | J4: Nom_cas | K4: FX_daN | L4: FZ_daN | M4: Noeud
A5: 47/1 | B5: G : Couverture : PA 6 BS 10 PV15 | C5: -116 | D5: 7 | E5: -1285 | F5: =IF(A5="","",VALUE(LEFT(A5,FIND("/",A5&"/")-1))) | M5: =IF(I5="","",VALUE(LEFT(I5,FIND("/",I5&"/")-1)))
A6: 47/2 | B6: Vent G/D dep.(-) Portique 2 | C6: 905 | D6: 40 | E6: 1422 | F6: =IF(A6="","",VALUE(LEFT(A6,FIND("/",A6&"/")-1))) | M6: =IF(I6="","",VALUE(LEFT(I6,FIND("/",I6&"/")-1)))
A7: 47/3 | B7: Vent G/D sur.(+) Portique 2 | C7: 900 | D7: 32 | E7: 1444 | F7: =IF(A7="","",VALUE(LEFT(A7,FIND("/",A7&"/")-1))) | M7: =IF(I7="","",VALUE(LEFT(I7,FIND("/",I7&"/")-1)))
A8: 47/4 | B8: Vent D/G dep.(-) Cpe - Portique 2 | C8: -345 | D8: 5 | E8: 462 | F8: =IF(A8="","",VALUE(LEFT(A8,FIND("/",A8&"/")-1))) | M8: =IF(I8="","",VALUE(LEFT(I8,FIND("/",I8&"/")-1)))
A9: 47/5 | B9: Vent D/G dep.(-) Cpe + Portique 2 | C9: -513 | D9: -11 | E9: -281 | F9: =IF(A9="","",VALUE(LEFT(A9,FIND("/",A9&"/")-1))) | M9: =IF(I9="","",VALUE(LEFT(I9,FIND("/",I9&"/")-1)))
A10: 47/6 | B10: Vent D/G sur.(+) Cpe - Portique 2 | C10: -349 | D10: -2 | E10: 485 | F10: =IF(A10="","",VALUE(LEFT(A10,FIND("/",A10&"/")-1))) | M10: =IF(I10="","",VALUE(LEFT(I10,FIND("/",I10&"/")-1)))
A11: 47/7 | B11: Vent D/G sur.(+) Cpe + Portique 2 | C11: -518 | D11: -22 | E11: -258 | F11: =IF(A11="","",VALUE(LEFT(A11,FIND("/",A11&"/")-1))) | M11: =IF(I11="","",VALUE(LEFT(I11,FIND("/",I11&"/")-1)))
A12: 47/8 | B12: Vent Av./Arr. dep.(-) Portique 2 | C12: -241 | D12: 205 | E12: 815 | F12: =IF(A12="","",VALUE(LEFT(A12,FIND("/",A12&"/")-1))) | M12: =IF(I12="","",VALUE(LEFT(I12,FIND("/",I12&"/")-1)))
A13: 47/9 | B13: Vent Av./Arr. sur.(+) Portique 2 | C13: -198 | D13: 195 | E13: 598 | F13: =IF(A13="","",VALUE(LEFT(A13,FIND("/",A13&"/")-1))) | M13: =IF(I13="","",VALUE(LEFT(I13,FIND("/",I13&"/")-1)))
A14: 47/10 | B14: Vent Arr./Av. dep.(-) Portique 2 | C14: -105 | D14: 0 | E14: 400 | F14: =IF(A14="","",VALUE(LEFT(A14,FIND("/",A14&"/")-1))) | M14: =IF(I14="","",VALUE(LEFT(I14,FIND("/",I14&"/")-1)))
A15: 47/11 | B15: Vent Arr./Av. sur.(+) Portique 2 | C15: -37 | D15: -11 | E15: 56 | F15: =IF(A15="","",VALUE(LEFT(A15,FIND("/",A15&"/")-1))) | M15: =IF(I15="","",VALUE(LEFT(I15,FIND("/",I15&"/")-1)))
A16: 47/12 | B16: Neige cas I | C16: -113 | D16: 0 | E16: -1010 | F16: =IF(A16="","",VALUE(LEFT(A16,FIND("/",A16&"/")-1))) | M16: =IF(I16="","",VALUE(LEFT(I16,FIND("/",I16&"/")-1)))
... A18: 47/14 | B18: Neige accidentel | C18: -251 | D18: 0 | E18: -2244 | F18: =IF(A18="","",VALUE(LEFT(A18,FIND("/",A18&"/")-1))) | M18: =IF(I18="","",VALUE(LEFT(I18,FIND("/",I18&"/")-1)))
F19: =IF(A19="","",VALUE(LEFT(A19,FIND("/",A19&"/")-1))) | M19: =IF(I19="","",VALUE(LEFT(I19,FIND("/",I19&"/")-1)))
F20: =IF(A20="","",VALUE(LEFT(A20,FIND("/",A20&"/")-1))) | M20: =IF(I20="","",VALUE(LEFT(I20,FIND("/",I20&"/")-1)))
F21: =IF(A21="","",VALUE(LEFT(A21,FIND("/",A21&"/")-1))) | M21: =IF(I21="","",VALUE(LEFT(I21,FIND("/",I21&"/")-1)))
F22: =IF(A22="","",VALUE(LEFT(A22,FIND("/",A22&"/")-1))) | M22: =IF(I22="","",VALUE(LEFT(I22,FIND("/",I22&"/")-1)))
F23: =IF(A23="","",VALUE(LEFT(A23,FIND("/",A23&"/")-1))) | M23: =IF(I23="","",VALUE(LEFT(I23,FIND("/",I23&"/")-1)))
F24: =IF(A24="","",VALUE(LEFT(A24,FIND("/",A24&"/")-1))) | M24: =IF(I24="","",VALUE(LEFT(I24,FIND("/",I24&"/")-1)))
F25: =IF(A25="","",VALUE(LEFT(A25,FIND("/",A25&"/")-1))) | M25: =IF(I25="","",VALUE(LEFT(I25,FIND("/",I25&"/")-1)))
F26: =IF(A26="","",VALUE(LEFT(A26,FIND("/",A26&"/")-1))) | M26: =IF(I26="","",VALUE(LEFT(I26,FIND("/",I26&"/")-1)))
F27: =IF(A27="","",VALUE(LEFT(A27,FIND("/",A27&"/")-1))) | M27: =IF(I27="","",VALUE(LEFT(I27,FIND("/",I27&"/")-1)))
F28: =IF(A28="","",VALUE(LEFT(A28,FIND("/",A28&"/")-1))) | M28: =IF(I28="","",VALUE(LEFT(I28,FIND("/",I28&"/")-1)))
F29: =IF(A29="","",VALUE(LEFT(A29,FIND("/",A29&"/")-1))) | M29: =IF(I29="","",VALUE(LEFT(I29,FIND("/",I29&"/")-1)))
F30: =IF(A30="","",VALUE(LEFT(A30,FIND("/",A30&"/")-1))) | M30: =IF(I30="","",VALUE(LEFT(I30,FIND("/",I30&"/")-1)))
... F204: =IF(A204="","",VALUE(LEFT(A204,FIND("/",A204&"/")-1))) | M204: =IF(I204="","",VALUE(LEFT(I204,FIND("/",I204&"/")-1)))

Sheet SYNTHESE
A1: SYNTHESE — Calcul automatique
A2: ="Avec FY : "&COUNTA(SAISIE!$A$5:$A$204)&" cas | "&SUMPRODUCT(--(MOD(ROW($F$5:$F$244)-5,12)=0)*($F$5:$F$244<>""))&" noeud(s) || "&"Sans FY : "&COUNTA(SAISIE!$I$5:$I$204)&" cas | "&SUMPRODUCT(--(MOD(ROW($M$5:$M$244)-5,12)=0)*($M$5:$M$244<>""))&" noeud(s)"
A3: SYNTHESE — AVEC FY | I3: SYNTHESE — SANS FY
A4: Nom du cas | B4: FX [daN] | C4: FY [daN] | D4: FZ [daN] | E4: Note | I4: Nom du cas | J4: FX [daN] | K4: FZ [daN] | L4: Note
A5: =IF($F$5="","","Noeud "&$F$5) | F5: =IFERROR(INDEX(SAISIE!$F$5:$F$204,AGGREGATE(15,6,ROW(SAISIE!$F$5:$F$204)-ROW(SAISIE!$F$5)+1/(SAISIE!$F$5:$F$204<>"")/(COUNTIF($F$4:$F4,SAISIE!$F$5:$F$204)=0),1)),"") | I5: =IF($M$5="","","Noeud "&$M$5) | M5: =IFERROR(INDEX(SAISIE!$M$5:$M$204,AGGREGATE(15,6,ROW(SAISIE!$M$5:$M$204)-ROW(SAISIE!$M$5)+1/(SAISIE!$M$5:$M$204<>"")/(COUNTIF($M$4:$M4,SAISIE!$M$5:$M$204)=0),1)),"")
A6: =IF(OR($F$5="",NOT(TRUE)),"","Couverture") | B6: =IF($F$5="","",IFERROR(IFERROR(LOOKUP(2,1/((SAISIE!$F$5:$F$204=$F$5)*(LEFT(SAISIE!$B$5:$B$204,2)="G ")),SAISIE!$C$5:$C$204),LOOKUP(2,1/((SAISIE!$F$5:$F$204=$F$5)*(ISNUMBER(SEARCH("Couverture",SAISIE!$B$5:$B$204)))),SAISIE!$C$5:$C$204)),"-")) | C6: =IF($F$5="","",IFERROR(IFERROR(LOOKUP(2,1/((SAISIE!$F$5:$F$204=$F$5)*(LEFT(SAISIE!$B$5:$B$204,2)="G ")),SAISIE!$D$5:$D$204),LOOKUP(2,1/((SAISIE!$F$5:$F$204=$F$5)*(ISNUMBER(SEARCH("Couverture",SAISIE!$B$5:$B$204)))),SAISIE!$D$5:$D$204)),"-")) | D6: =IF($F$5="","",IFERROR(IFERROR(LOOKUP(2,1/((SAISIE!$F$5:$F$204=$F$5)*(LEFT(SAISIE!$B$5:$B$204,2)="G ")),SAISIE!$E$5:$E$204),LOOKUP(2,1/((SAISIE!$F$5:$F$204=$F$5)*(ISNUMBER(SEARCH("Couverture",SAISIE!$B$5:$B$204)))),SAISIE!$E$5:$E$204)),"-")) | E6: =IF($F$5="","",IF(OR(D6="",D6="-"),"",IF(D6>0,"(soulevement)",IF(D6<0,"(compression)","-")))) | I6: =IF(OR($M$5="",NOT(TRUE)),"","Couverture") | J6: =IF($M$5="","",IFERROR(IFERROR(LOOKUP(2,1/((SAISIE!$M$5:$M$204=$M$5)*(LEFT(SAISIE!$J$5:$J$204,2)="G ")),SAISIE!$K$5:$K$204),LOOKUP(2,1/((SAISIE!$M$5:$M$204=$M$5)*(ISNUMBER(SEARCH("Couverture",SAISIE!$J$5:$J$204)))),SAISIE!$K$5:$K$204)),"-")) | K6: =IF($M$5="","",IFERROR(IFERROR(LOOKUP(2,1/((SAISIE!$M$5:$M$204=$M$5)*(LEFT(SAISIE!$J$5:$J$204,2)="G ")),SAISIE!$L$5:$L$204),LOOKUP(2,1/((SAISIE!$M$5:$M$204=$M$5)*(ISNUMBER(SEARCH("Couverture",SAISIE!$J$5:$J$204)))),SAISIE!$L$5:$L$204)),"-")) | L6: =IF($M$5="","",IF(OR(K6="",K6="-"),"",IF(K6>0,"(soulevement)",IF(K6<0,"(compression)","-"))))
A7: =IF(OR($F$5="",NOT(COUNTIFS(SAISIE!$B$5:$B$204,"*Vent G/D*",SAISIE!$F$5:$F$204,$F$5)>0)),"","Vent G/D") | B7: =IF(OR($F$5="",NOT(COUNTIFS(SAISIE!$B$5:$B$204,"*Vent G/D*",SAISIE!$F$5:$F$204,$F$5)>0)),"",IFERROR(IF(MINIFS(SAISIE!$E$5:$E$204,SAISIE!$B$5:$B$204,"*Vent G/D*",SAISIE!$F$5:$F$204,$F$5)>=0,MAXIFS(SAISIE!$C$5:$C$204,SAISIE!$B$5:$B$204,"*Vent G/D*",SAISIE!$F$5:$F$204,$F$5),INDEX(SAISIE!$C$5:$C$204,MATCH(MINIFS(SAISIE!$E$5:$E$204,SAISIE!$B$5:$B$204,"*Vent G/D*",SAISIE!$F$5:$F$204,$F$5),SAISIE!$E$5:$E$204,0))),"-")) | C7: =IF(OR($F$5="",NOT(COUNTIFS(SAISIE!$B$5:$B$204,"*Vent G/D*",SAISIE!$F$5:$F$204,$F$5)>0)),"",IFERROR(IF(MINIFS(SAISIE!$E$5:$E$204,SAISIE!$B$5:$B$204,"*Vent G/D*",SAISIE!$F$5:$F$204,$F$5)>=0,INDEX(SAISIE!$D$5:$D$204,MATCH(MAXIFS(SAISIE!$C$5:$C$204,SAISIE!$B$5:$B$204,"*Vent G/D*",SAISIE!$F$5:$F$204,$F$5),SAISIE!$C$5:$C$204,0)),INDEX(SAISIE!$D$5:$D$204,MATCH(MINIFS(SAISIE!$E$5:$E$204,SAISIE!$B$5:$B$204,"*Vent G/D*",SAISIE!$F$5:$F$204,$F$5),SAISIE!$E$5:$E$204,0))),"-")) | D7: =IF(OR($F$5="",NOT(COUNTIFS(SAISIE!$B$5:$B$204,"*Vent G/D*",SAISIE!$F$5:$F$204,$F$5)>0)),"",IFERROR(IF(MINIFS(SAISIE!$E$5:$E$204,SAISIE!$B$5:$B$204,"*Vent G/D*",SAISIE!$F$5:$F$204,$F$5)>=0,0,MINIFS(SAISIE!$E$5:$E$204,SAISIE!$B$5:$B$204,"*Vent G/D*",SAISIE!$F$5:$F$204,$F$5)),"-")) | E7: =IF($F$5="","",IF(OR(D7="",D7="-"),"",IF(D7>0,"(soulevement)",IF(D7<0,"(compression)","-")))) | I7: =IF(OR($M$5="",NOT(COUNTIFS(SAISIE!$J$5:$J$204,"*Vent G/D*",SAISIE!$M$5:$M$204,$M$5)>0)),"","Vent G/D") | J7: =IF(OR($M$5="",NOT(COUNTIFS(SAISIE!$J$5:$J$204,"*Vent G/D*",SAISIE!$M$5:$M$204,$M$5)>0)),"",IFERROR(IF(MINIFS(SAISIE!$L$5:$L$204,SAISIE!$J$5:$J$204,"*Vent G/D*",SAISIE!$M$5:$M$204,$M$5)>=0,MAXIFS(SAISIE!$K$5:$K$204,SAISIE!$J$5:$J$204,"*Vent G/D*",SAISIE!$M$5:$M$204,$M$5),INDEX(SAISIE!$K$5:$K$204,MATCH(MINIFS(SAISIE!$L$5:$L$204,SAISIE!$J$5:$J$204,"*Vent G/D*",SAISIE!$M$5:$M$204,$M$5),SAISIE!$L$5:$L$204,0))),"-")) | K7: =IF(OR($M$5="",NOT(COUNTIFS(SAISIE!$J$5:$J$204,"*Vent G/D*",SAISIE!$M$5:$M$204,$M$5)>0)),"",IFERROR(IF(MINIFS(SAISIE!$L$5:$L$204,SAISIE!$J$5:$J$204,"*Vent G/D*",SAISIE!$M$5:$M$204,$M$5)>=0,0,MINIFS(SAISIE!$L$5:$L$204,SAISIE!$J$5:$J$204,"*Vent G/D*",SAISIE!$M$5:$M$204,$M$5)),"-")) | L7: =IF($M$5="","",IF(OR(K7="",K7="-"),"",IF(K7>0,"(soulevement)",IF(K7<0,"(compression)","-"))))
A8: =IF(OR($F$5="",NOT(MAXIFS(SAISIE!$E$5:$E$204,SAISIE!$B$5:$B$204,"*Vent G/D*",SAISIE!$F$5:$F$204,$F$5)>0)),"","Vent G/D") | B8: =IF(OR($F$5="",NOT(MAXIFS(SAISIE!$E$5:$E$204,SAISIE!$B$5:$B$204,"*Vent G/D*",SAISIE!$F$5:$F$204,$F$5)>0)),"",IFERROR(INDEX(SAISIE!$C$5:$C$204,MATCH(MAXIFS(SAISIE!$E$5:$E$204,SAISIE!$B$5:$B$204,"*Vent G/D*",SAISIE!$F$5:$F$204,$F$5),SAISIE!$E$5:$E$204,0)),"-")) | C8: =IF(OR($F$5="",NOT(MAXIFS(SAISIE!$E$5:$E$204,SAISIE!$B$5:$B$204,"*Vent G/D*",SAISIE!$F$5:$F$204,$F$5)>0)),"",IFERROR(INDEX(SAISIE!$D$5:$D$204,MATCH(MAXIFS(SAISIE!$E$5:$E$204,SAISIE!$B$5:$B$204,"*Vent G/D*",SAISIE!$F$5:$F$204,$F$5),SAISIE!$E$5:$E$204,0)),"-")) | D8: =IF(OR($F$5="",NOT(MAXIFS(SAISIE!$E$5:$E$204,SAISIE!$B$5:$B$204,"*Vent G/D*",SAISIE!$F$5:$F$204,$F$5)>0)),"",IFERROR(MAXIFS(SAISIE!$E$5:$E$204,SAISIE!$B$5:$B$204,"*Vent G/D*",SAISIE!$F$5:$F$204,$F$5),"-")) | E8: =IF($F$5="","",IF(OR(D8="",D8="-"),"",IF(D8>0,"(soulevement)",IF(D8<0,"(compression)","-")))) | I8: =IF(OR($M$5="",NOT(MAXIFS(SAISIE!$L$5:$L$204,SAISIE!$J$5:$J$204,"*Vent G/D*",SAISIE!$M$5:$M$204,$M$5)>0)),"","Vent G/D") | J8: =IF(OR($M$5="",NOT(MAXIFS(SAISIE!$L$5:$L$204,SAISIE!$J$5:$J$204,"*Vent G/D*",SAISIE!$M$5:$M$204,$M$5)>0)),"",IFERROR(INDEX(SAISIE!$K$5:$K$204,MATCH(MAXIFS(SAISIE!$L$5:$L$204,SAISIE!$J$5:$J$204,"*Vent G/D*",SAISIE!$M$5:$M$204,$M$5),SAISIE!$L$5:$L$204,0)),"-")) | K8: =IF(OR($M$5="",NOT(MAXIFS(SAISIE!$L$5:$L$204,SAISIE!$J$5:$J$204,"*Vent G/D*",SAISIE!$M$5:$M$204,$M$5)>0)),"",IFERROR(MAXIFS(SAISIE!$L$5:$L$204,SAISIE!$J$5:$J$204,"*Vent G/D*",SAISIE!$M$5:$M$204,$M$5),"-")) | L8: =IF($M$5="","",IF(OR(K8="",K8="-"),"",IF(K8>0,"(soulevement)",IF(K8<0,"(compression)","-"))))
A9: =IF(OR($F$5="",NOT(COUNTIFS(SAISIE!$B$5:$B$204,"*Vent D/G*",SAISIE!$F$5:$F$204,$F$5)>0)),"","Vent D/G") | B9: =IF(OR($F$5="",NOT(COUNTIFS(SAISIE!$B$5:$B$204,"*Vent D/G*",SAISIE!$F$5:$F$204,$F$5)>0)),"",IFERROR(IF(MINIFS(SAISIE!$E$5:$E$204,SAISIE!$B$5:$B$204,"*Vent D/G*",SAISIE!$F$5:$F$204,$F$5)>=0,MAXIFS(SAISIE!$C$5:$C$204,SAISIE!$B$5:$B$204,"*Vent D/G*",SAISIE!$F$5:$F$204,$F$5),INDEX(SAISIE!$C$5:$C$204,MATCH(MINIFS(SAISIE!$E$5:$E$204,SAISIE!$B$5:$B$204,"*Vent D/G*",SAISIE!$F$5:$F$204,$F$5),SAISIE!$E$5:$E$204,0))),"-")) | C9: =IF(OR($F$5="",NOT(COUNTIFS(SAISIE!$B$5:$B$204,"*Vent D/G*",SAISIE!$F$5:$F$204,$F$5)>0)),"",IFERROR(IF(MINIFS(SAISIE!$E$5:$E$204,SAISIE!$B$5:$B$204,"*Vent D/G*",SAISIE!$F$5:$F$204,$F$5)>=0,INDEX(SAISIE!$D$5:$D$204,MATCH(MAXIFS(SAISIE!$C$5:$C$204,SAISIE!$B$5:$B$204,"*Vent D/G*",SAISIE!$F$5:$F$204,$F$5),SAISIE!$C$5:$C$204,0)),INDEX(SAISIE!$D$5:$D$204,MATCH(MINIFS(SAISIE!$E$5:$E$204,SAISIE!$B$5:$B$204,"*Vent D/G*",SAISIE!$F$5:$F$204,$F$5),SAISIE!$E$5:$E$204,0))),"-")) | D9: =IF(OR($F$5="",NOT(COUNTIFS(SAISIE!$B$5:$B$204,"*Vent D/G*",SAISIE!$F$5:$F$204,$F$5)>0)),"",IFERROR(IF(MINIFS(SAISIE!$E$5:$E$204,SAISIE!$B$5:$B$204,"*Vent D/G*",SAISIE!$F$5:$F$204,$F$5)>=0,0,MINIFS(SAISIE!$E$5:$E$204,SAISIE!$B$5:$B$204,"*Vent D/G*",SAISIE!$F$5:$F$204,$F$5)),"-")) | E9: =IF($F$5="","",IF(OR(D9="",D9="-"),"",IF(D9>0,"(soulevement)",IF(D9<0,"(compression)","-")))) | I9: =IF(OR($M$5="",NOT(COUNTIFS(SAISIE!$J$5:$J$204,"*Vent D/G*",SAISIE!$M$5:$M$204,$M$5)>0)),"","Vent D/G") | J9: =IF(OR($M$5="",NOT(COUNTIFS(SAISIE!$J$5:$J$204,"*Vent D/G*",SAISIE!$M$5:$M$204,$M$5)>0)),"",IFERROR(IF(MINIFS(SAISIE!$L$5:$L$204,SAISIE!$J$5:$J$204,"*Vent D/G*",SAISIE!$M$5:$M$204,$M$5)>=0,MAXIFS(SAISIE!$K$5:$K$204,SAISIE!$J$5:$J$204,"*Vent D/G*",SAISIE!$M$5:$M$204,$M$5),INDEX(SAISIE!$K$5:$K$204,MATCH(MINIFS(SAISIE!$L$5:$L$204,SAISIE!$J$5:$J$204,"*Vent D/G*",SAISIE!$M$5:$M$204,$M$5),SAISIE!$L$5:$L$204,0))),"-")) | K9: =IF(OR($M$5="",NOT(COUNTIFS(SAISIE!$J$5:$J$204,"*Vent D/G*",SAISIE!$M$5:$M$204,$M$5)>0)),"",IFERROR(IF(MINIFS(SAISIE!$L$5:$L$204,SAISIE!$J$5:$J$204,"*Vent D/G*",SAISIE!$M$5:$M$204,$M$5)>=0,0,MINIFS(SAISIE!$L$5:$L$204,SAISIE!$J$5:$J$204,"*Vent D/G*",SAISIE!$M$5:$M$204,$M$5)),"-")) | L9: =IF($M$5="","",IF(OR(K9="",K9="-"),"",IF(K9>0,"(soulevement)",IF(K9<0,"(compression)","-"))))
A10: =IF(OR($F$5="",NOT(MAXIFS(SAISIE!$E$5:$E$204,SAISIE!$B$5:$B$204,"*Vent D/G*",SAISIE!$F$5:$F$204,$F$5)>0)),"","Vent D/G") | B10: =IF(OR($F$5="",NOT(MAXIFS(SAISIE!$E$5:$E$204,SAISIE!$B$5:$B$204,"*Vent D/G*",SAISIE!$F$5:$F$204,$F$5)>0)),"",IFERROR(INDEX(SAISIE!$C$5:$C$204,MATCH(MAXIFS(SAISIE!$E$5:$E$204,SAISIE!$B$5:$B$204,"*Vent D/G*",SAISIE!$F$5:$F$204,$F$5),SAISIE!$E$5:$E$204,0)),"-")) | C10: =IF(OR($F$5="",NOT(MAXIFS(SAISIE!$E$5:$E$204,SAISIE!$B$5:$B$204,"*Vent D/G*",SAISIE!$F$5:$F$204,$F$5)>0)),"",IFERROR(INDEX(SAISIE!$D$5:$D$204,MATCH(MAXIFS(SAISIE!$E$5:$E$204,SAISIE!$B$5:$B$204,"*Vent D/G*",SAISIE!$F$5:$F$204,$F$5),SAISIE!$E$5:$E$204,0)),"-")) | D10: =IF(OR($F$5="",NOT(MAXIFS(SAISIE!$E$5:$E$204,SAISIE!$B$5:$B$204,"*Vent D/G*",SAISIE!$F$5:$F$204,$F$5)>0)),"",IFERROR(MAXIFS(SAISIE!$E$5:$E$204,SAISIE!$B$5:$B$204,"*Vent D/G*",SAISIE!$F$5:$F$204,$F$5),"-")) | E10: =IF($F$5="","",IF(OR(D10="",D10="-"),"",IF(D10>0,"(soulevement)",IF(D10<0,"(compression)","-")))) | I10: =IF(OR($M$5="",NOT(MAXIFS(SAISIE!$L$5:$L$204,SAISIE!$J$5:$J$204,"*Vent D/G*",SAISIE!$M$5:$M$204,$M$5)>0)),"","Vent D/G") | J10: =IF(OR($M$5="",NOT(MAXIFS(SAISIE!$L$5:$L$204,SAISIE!$J$5:$J$204,"*Vent D/G*",SAISIE!$M$5:$M$204,$M$5)>0)),"",IFERROR(INDEX(SAISIE!$K$5:$K$204,MATCH(MAXIFS(SAISIE!$L$5:$L$204,SAISIE!$J$5:$J$204,"*Vent D/G*",SAISIE!$M$5:$M$204,$M$5),SAISIE!$L$5:$L$204,0)),"-")) | K10: =IF(OR($M$5="",NOT(MAXIFS(SAISIE!$L$5:$L$204,SAISIE!$J$5:$J$204,"*Vent D/G*",SAISIE!$M$5:$M$204,$M$5)>0)),"",IFERROR(MAXIFS(SAISIE!$L$5:$L$204,SAISIE!$J$5:$J$204,"*Vent D/G*",SAISIE!$M$5:$M$204,$M$5),"-")) | L10: =IF($M$5="","",IF(OR(K10="",K10="-"),"",IF(K10>0,"(soulevement)",IF(K10<0,"(compression)","-"))))
A11: =IF(OR($F$5="",NOT(COUNTIFS(SAISIE!$B$5:$B$204,"*Vent Av./Arr.*",SAISIE!$F$5:$F$204,$F$5)>0)),"","Vent Av./Arr.") | B11: =IF(OR($F$5="",NOT(COUNTIFS(SAISIE!$B$5:$B$204,"*Vent Av./Arr.*",SAISIE!$F$5:$F$204,$F$5)>0)),"",IFERROR(IF(MINIFS(SAISIE!$E$5:$E$204,SAISIE!$B$5:$B$204,"*Vent Av./Arr.*",SAISIE!$F$5:$F$204,$F$5)>=0,MAXIFS(SAISIE!$C$5:$C$204,SAISIE!$B$5:$B$204,"*Vent Av./Arr.*",SAISIE!$F$5:$F$204,$F$5),INDEX(SAISIE!$C$5:$C$204,MATCH(MINIFS(SAISIE!$E$5:$E$204,SAISIE!$B$5:$B$204,"*Vent Av./Arr.*",SAISIE!$F$5:$F$204,$F$5),SAISIE!$E$5:$E$204,0))),"-")) | C11: =IF(OR($F$5="",NOT(COUNTIFS(SAISIE!$B$5:$B$204,"*Vent Av./Arr.*",SAISIE!$F$5:$F$204,$F$5)>0)),"",IFERROR(IF(MINIFS(SAISIE!$E$5:$E$204,SAISIE!$B$5:$B$204,"*Vent Av./Arr.*",SAISIE!$F$5:$F$204,$F$5)>=0,INDEX(SAISIE!$D$5:$D$204,MATCH(MAXIFS(SAISIE!$C$5:$C$204,SAISIE!$B$5:$B$204,"*Vent Av./Arr.*",SAISIE!$F$5:$F$204,$F$5),SAISIE!$C$5:$C$204,0)),INDEX(SAISIE!$D$5:$D$204,MATCH(MINIFS(SAISIE!$E$5:$E$204,SAISIE!$B$5:$B$204,"*Vent Av./Arr.*",SAISIE!$F$5:$F$204,$F$5),SAISIE!$E$5:$E$204,0))),"-")) | D11: =IF(OR($F$5="",NOT(COUNTIFS(SAISIE!$B$5:$B$204,"*Vent Av./Arr.*",SAISIE!$F$5:$F$204,$F$5)>0)),"",IFERROR(IF(MINIFS(SAISIE!$E$5:$E$204,SAISIE!$B$5:$B$204,"*Vent Av./Arr.*",SAISIE!$F$5:$F$204,$F$5)>=0,0,MINIFS(SAISIE!$E$5:$E$204,SAISIE!$B$5:$B$204,"*Vent Av./Arr.*",SAISIE!$F$5:$F$204,$F$5)),"-")) | E11: =IF($F$5="","",IF(OR(D11="",D11="-"),"",IF(D11>0,"(soulevement)",IF(D11<0,"(compression)","-")))) | I11: =IF(OR($M$5="",NOT(COUNTIFS(SAISIE!$J$5:$J$204,"*Vent Av./Arr.*",SAISIE!$M$5:$M$204,$M$5)>0)),"","Vent Av./Arr.") | J11: =IF(OR($M$5="",NOT(COUNTIFS(SAISIE!$J$5:$J$204,"*Vent Av./Arr.*",SAISIE!$M$5:$M$204,$M$5)>0)),"",IFERROR(IF(MINIFS(SAISIE!$L$5:$L$204,SAISIE!$J$5:$J$204,"*Vent Av./Arr.*",SAISIE!$M$5:$M$204,$M$5)>=0,MAXIFS(SAISIE!$K$5:$K$204,SAISIE!$J$5:$J$204,"*Vent Av./Arr.*",SAISIE!$M$5:$M$204,$M$5),INDEX(SAISIE!$K$5:$K$204,MATCH(MINIFS(SAISIE!$L$5:$L$204,SAISIE!$J$5:$J$204,"*Vent Av./Arr.*",SAISIE!$M$5:$M$204,$M$5),SAISIE!$L$5:$L$204,0))),"-")) | K11: =IF(OR($M$5="",NOT(COUNTIFS(SAISIE!$J$5:$J$204,"*Vent Av./Arr.*",SAISIE!$M$5:$M$204,$M$5)>0)),"",IFERROR(IF(MINIFS(SAISIE!$L$5:$L$204,SAISIE!$J$5:$J$204,"*Vent Av./Arr.*",SAISIE!$M$5:$M$204,$M$5)>=0,0,MINIFS(SAISIE!$L$5:$L$204,SAISIE!$J$5:$J$204,"*Vent Av./Arr.*",SAISIE!$M$5:$M$204,$M$5)),"-")) | L11: =IF($M$5="","",IF(OR(K11="",K11="-"),"",IF(K11>0,"(soulevement)",IF(K11<0,"(compression)","-"))))
A12: =IF(OR($F$5="",NOT(MAXIFS(SAISIE!$E$5:$E$204,SAISIE!$B$5:$B$204,"*Vent Av./Arr.*",SAISIE!$F$5:$F$204,$F$5)>0)),"","Vent Av./Arr.") | B12: =IF(OR($F$5="",NOT(MAXIFS(SAISIE!$E$5:$E$204,SAISIE!$B$5:$B$204,"*Vent Av./Arr.*",SAISIE!$F$5:$F$204,$F$5)>0)),"",IFERROR(INDEX(SAISIE!$C$5:$C$204,MATCH(MAXIFS(SAISIE!$E$5:$E$204,SAISIE!$B$5:$B$204,"*Vent Av./Arr.*",SAISIE!$F$5:$F$204,$F$5),SAISIE!$E$5:$E$204,0)),"-")) | C12: =IF(OR($F$5="",NOT(MAXIFS(SAISIE!$E$5:$E$204,SAISIE!$B$5:$B$204,"*Vent Av./Arr.*",SAISIE!$F$5:$F$204,$F$5)>0)),"",IFERROR(INDEX(SAISIE!$D$5:$D$204,MATCH(MAXIFS(SAISIE!$E$5:$E$204,SAISIE!$B$5:$B$204,"*Vent Av./Arr.*",SAISIE!$F$5:$F$204,$F$5),SAISIE!$E$5:$E$204,0)),"-")) | D12: =IF(OR($F$5="",NOT(MAXIFS(SAISIE!$E$5:$E$204,SAISIE!$B$5:$B$204,"*Vent Av./Arr.*",SAISIE!$F$5:$F$204,$F$5)>0)),"",IFERROR(MAXIFS(SAISIE!$E$5:$E$204,SAISIE!$B$5:$B$204,"*Vent Av./Arr.*",SAISIE!$F$5:$F$204,$F$5),"-")) | E12: =IF($F$5="","",IF(OR(D12="",D12="-"),"",IF(D12>0,"(soulevement)",IF(D12<0,"(compression)","-")))) | I12: =IF(OR($M$5="",NOT(MAXIFS(SAISIE!$L$5:$L$204,SAISIE!$J$5:$J$204,"*Vent Av./Arr.*",SAISIE!$M$5:$M$204,$M$5)>0)),"","Vent Av./Arr.") | J12: =IF(OR($M$5="",NOT(MAXIFS(SAISIE!$L$5:$L$204,SAISIE!$J$5:$J$204,"*Vent Av./Arr.*",SAISIE!$M$5:$M$204,$M$5)>0)),"",IFERROR(INDEX(SAISIE!$K$5:$K$204,MATCH(MAXIFS(SAISIE!$L$5:$L$204,SAISIE!$J$5:$J$204,"*Vent Av./Arr.*",SAISIE!$M$5:$M$204,$M$5),SAISIE!$L$5:$L$204,0)),"-")) | K12: =IF(OR($M$5="",NOT(MAXIFS(SAISIE!$L$5:$L$204,SAISIE!$J$5:$J$204,"*Vent Av./Arr.*",SAISIE!$M$5:$M$204,$M$5)>0)),"",IFERROR(MAXIFS(SAISIE!$L$5:$L$204,SAISIE!$J$5:$J$204,"*Vent Av./Arr.*",SAISIE!$M$5:$M$204,$M$5),"-")) | L12: =IF($M$5="","",IF(OR(K12="",K12="-"),"",IF(K12>0,"(soulevement)",IF(K12<0,"(compression)","-"))))
A13: =IF(OR($F$5="",NOT(COUNTIFS(SAISIE!$B$5:$B$204,"*Vent Arr./Av.*",SAISIE!$F$5:$F$204,$F$5)>0)),"","Vent Arr./Av.") | B13: =IF(OR($F$5="",NOT(COUNTIFS(SAISIE!$B$5:$B$204,"*Vent Arr./Av.*",SAISIE!$F$5:$F$204,$F$5)>0)),"",IFERROR(IF(MINIFS(SAISIE!$E$5:$E$204,SAISIE!$B$5:$B$204,"*Vent Arr./Av.*",SAISIE!$F$5:$F$204,$F$5)>=0,MAXIFS(SAISIE!$C$5:$C$204,SAISIE!$B$5:$B$204,"*Vent Arr./Av.*",SAISIE!$F$5:$F$204,$F$5),INDEX(SAISIE!$C$5:$C$204,MATCH(MINIFS(SAISIE!$E$5:$E$204,SAISIE!$B$5:$B$204,"*Vent Arr./Av.*",SAISIE!$F$5:$F$204,$F$5),SAISIE!$E$5:$E$204,0))),"-")) | C13: =IF(OR($F$5="",NOT(COUNTIFS(SAISIE!$B$5:$B$204,"*Vent Arr./Av.*",SAISIE!$F$5:$F$204,$F$5)>0)),"",IFERROR(IF(MINIFS(SAISIE!$E$5:$E$204,SAISIE!$B$5:$B$204,"*Vent Arr./Av.*",SAISIE!$F$5:$F$204,$F$5)>=0,INDEX(SAISIE!$D$5:$D$204,MATCH(MAXIFS(SAISIE!$C$5:$C$204,SAISIE!$B$5:$B$204,"*Vent Arr./Av.*",SAISIE!$F$5:$F$204,$F$5),SAISIE!$C$5:$C$204,0)),INDEX(SAISIE!$D$5:$D$204,MATCH(MINIFS(SAISIE!$E$5:$E$204,SAISIE!$B$5:$B$204,"*Vent Arr./Av.*",SAISIE!$F$5:$F$204,$F$5),SAISIE!$E$5:$E$204,0))),"-")) | D13: =IF(OR($F$5="",NOT(COUNTIFS(SAISIE!$B$5:$B$204,"*Vent Arr./Av.*",SAISIE!$F$5:$F$204,$F$5)>0)),"",IFERROR(IF(MINIFS(SAISIE!$E$5:$E$204,SAISIE!$B$5:$B$204,"*Vent Arr./Av.*",SAISIE!$F$5:$F$204,$F$5)>=0,0,MINIFS(SAISIE!$E$5:$E$204,SAISIE!$B$5:$B$204,"*Vent Arr./Av.*",SAISIE!$F$5:$F$204,$F$5)),"-")) | E13: =IF($F$5="","",IF(OR(D13="",D13="-"),"",IF(D13>0,"(soulevement)",IF(D13<0,"(compression)","-")))) | I13: =IF(OR($M$5="",NOT(COUNTIFS(SAISIE!$J$5:$J$204,"*Vent Arr./Av.*",SAISIE!$M$5:$M$204,$M$5)>0)),"","Vent Arr./Av.") | J13: =IF(OR($M$5="",NOT(COUNTIFS(SAISIE!$J$5:$J$204,"*Vent Arr./Av.*",SAISIE!$M$5:$M$204,$M$5)>0)),"",IFERROR(IF(MINIFS(SAISIE!$L$5:$L$204,SAISIE!$J$5:$J$204,"*Vent Arr./Av.*",SAISIE!$M$5:$M$204,$M$5)>=0,MAXIFS(SAISIE!$K$5:$K$204,SAISIE!$J$5:$J$204,"*Vent Arr./Av.*",SAISIE!$M$5:$M$204,$M$5),INDEX(SAISIE!$K$5:$K$204,MATCH(MINIFS(SAISIE!$L$5:$L$204,SAISIE!$J$5:$J$204,"*Vent Arr./Av.*",SAISIE!$M$5:$M$204,$M$5),SAISIE!$L$5:$L$204,0))),"-")) | K13: =IF(OR($M$5="",NOT(COUNTIFS(SAISIE!$J$5:$J$204,"*Vent Arr./Av.*",SAISIE!$M$5:$M$204,$M$5)>0)),"",IFERROR(IF(MINIFS(SAISIE!$L$5:$L$204,SAISIE!$J$5:$J$204,"*Vent Arr./Av.*",SAISIE!$M$5:$M$204,$M$5)>=0,0,MINIFS(SAISIE!$L$5:$L$204,SAISIE!$J$5:$J$204,"*Vent Arr./Av.*",SAISIE!$M$5:$M$204,$M$5)),"-")) | L13: =IF($M$5="","",IF(OR(K13="",K13="-"),"",IF(K13>0,"(soulevement)",IF(K13<0,"(compression)","-"))))
A14: =IF(OR($F$5="",NOT(MAXIFS(SAISIE!$E$5:$E$204,SAISIE!$B$5:$B$204,"*Vent Arr./Av.*",SAISIE!$F$5:$F$204,$F$5)>0)),"","Vent Arr./Av.") | B14: =IF(OR($F$5="",NOT(MAXIFS(SAISIE!$E$5:$E$204,SAISIE!$B$5:$B$204,"*Vent Arr./Av.*",SAISIE!$F$5:$F$204,$F$5)>0)),"",IFERROR(INDEX(SAISIE!$C$5:$C$204,MATCH(MAXIFS(SAISIE!$E$5:$E$204,SAISIE!$B$5:$B$204,"*Vent Arr./Av.*",SAISIE!$F$5:$F$204,$F$5),SAISIE!$E$5:$E$204,0)),"-")) | C14: =IF(OR($F$5="",NOT(MAXIFS(SAISIE!$E$5:$E$204,SAISIE!$B$5:$B$204,"*Vent Arr./Av.*",SAISIE!$F$5:$F$204,$F$5)>0)),"",IFERROR(INDEX(SAISIE!$D$5:$D$204,MATCH(MAXIFS(SAISIE!$E$5:$E$204,SAISIE!$B$5:$B$204,"*Vent Arr./Av.*",SAISIE!$F$5:$F$204,$F$5),SAISIE!$E$5:$E$204,0)),"-")) | D14: =IF(OR($F$5="",NOT(MAXIFS(SAISIE!$E$5:$E$204,SAISIE!$B$5:$B$204,"*Vent Arr./Av.*",SAISIE!$F$5:$F$204,$F$5)>0)),"",IFERROR(MAXIFS(SAISIE!$E$5:$E$204,SAISIE!$B$5:$B$204,"*Vent Arr./Av.*",SAISIE!$F$5:$F$204,$F$5),"-")) | E14: =IF($F$5="","",IF(OR(D14="",D14="-"),"",IF(D14>0,"(soulevement)",IF(D14<0,"(compression)","-")))) | I14: =IF(OR($M$5="",NOT(MAXIFS(SAISIE!$L$5:$L$204,SAISIE!$J$5:$J$204,"*Vent Arr./Av.*",SAISIE!$M$5:$M$204,$M$5)>0)),"","Vent Arr./Av.") | J14: =IF(OR($M$5="",NOT(MAXIFS(SAISIE!$L$5:$L$204,SAISIE!$J$5:$J$204,"*Vent Arr./Av.*",SAISIE!$M$5:$M$204,$M$5)>0)),"",IFERROR(INDEX(SAISIE!$K$5:$K$204,MATCH(MAXIFS(SAISIE!$L$5:$L$204,SAISIE!$J$5:$J$204,"*Vent Arr./Av.*",SAISIE!$M$5:$M$204,$M$5),SAISIE!$L$5:$L$204,0)),"-")) | K14: =IF(OR($M$5="",NOT(MAXIFS(SAISIE!$L$5:$L$204,SAISIE!$J$5:$J$204,"*Vent Arr./Av.*",SAISIE!$M$5:$M$204,$M$5)>0)),"",IFERROR(MAXIFS(SAISIE!$L$5:$L$204,SAISIE!$J$5:$J$204,"*Vent Arr./Av.*",SAISIE!$M$5:$M$204,$M$5),"-")) | L14: =IF($M$5="","",IF(OR(K14="",K14="-"),"",IF(K14>0,"(soulevement)",IF(K14<0,"(compression)","-"))))
A15: =IF(OR($F$5="",NOT(TRUE)),"","Neige normale") | B15: =IF($F$5="","",IFERROR(INDEX(SAISIE!$C$5:$C$204,MATCH(MINIFS(SAISIE!$E$5:$E$204,SAISIE!$B$5:$B$204,"*Neige*",SAISIE!$B$5:$B$204,"<>*accidentel*",SAISIE!$F$5:$F$204,$F$5),SAISIE!$E$5:$E$204,0)),"-")) | C15: =IF($F$5="","",IFERROR(INDEX(SAISIE!$D$5:$D$204,MATCH(MINIFS(SAISIE!$E$5:$E$204,SAISIE!$B$5:$B$204,"*Neige*",SAISIE!$B$5:$B$204,"<>*accidentel*",SAISIE!$F$5:$F$204,$F$5),SAISIE!$E$5:$E$204,0)),"-")) | D15: =IF($F$5="","",IFERROR(INDEX(SAISIE!$E$5:$E$204,MATCH(MINIFS(SAISIE!$E$5:$E$204,SAISIE!$B$5:$B$204,"*Neige*",SAISIE!$B$5:$B$204,"<>*accidentel*",SAISIE!$F$5:$F$204,$F$5),SAISIE!$E$5:$E$204,0)),"-")) | E15: =IF($F$5="","",IF(OR(D15="",D15="-"),"",IF(D15>0,"(soulevement)",IF(D15<0,"(compression)","-")))) | I15: =IF(OR($M$5="",NOT(TRUE)),"","Neige normale") | J15: =IF($M$5="","",IFERROR(INDEX(SAISIE!$K$5:$K$204,MATCH(MINIFS(SAISIE!$L$5:$L$204,SAISIE!$J$5:$J$204,"*Neige*",SAISIE!$J$5:$J$204,"<>*accidentel*",SAISIE!$M$5:$M$204,$M$5),SAISIE!$L$5:$L$204,0)),"-")) | K15: =IF($M$5="","",IFERROR(INDEX(SAISIE!$L$5:$L$204,MATCH(MINIFS(SAISIE!$L$5:$L$204,SAISIE!$J$5:$J$204,"*Neige*",SAISIE!$J$5:$J$204,"<>*accidentel*",SAISIE!$M$5:$M$204,$M$5),SAISIE!$L$5:$L$204,0)),"-")) | L15: =IF($M$5="","",IF(OR(K15="",K15="-"),"",IF(K15>0,"(soulevement)",IF(K15<0,"(compression)","-"))))
A16: =IF(OR($F$5="",NOT(TRUE)),"","Neige accidentelle") | B16: =IF($F$5="","",IFERROR(LOOKUP(2,1/((SAISIE!$F$5:$F$204=$F$5)*(ISNUMBER(SEARCH("accidentel",SAISIE!$B$5:$B$204)))),SAISIE!$C$5:$C$204),"-")) | C16: =IF($F$5="","",IFERROR(LOOKUP(2,1/((SAISIE!$F$5:$F$204=$F$5)*(ISNUMBER(SEARCH("accidentel",SAISIE!$B$5:$B$204)))),SAISIE!$D$5:$D$204),"-")) | D16: =IF($F$5="","",IFERROR(LOOKUP(2,1/((SAISIE!$F$5:$F$204=$F$5)*(ISNUMBER(SEARCH("accidentel",SAISIE!$B$5:$B$204)))),SAISIE!$E$5:$E$204),"-")) | E16: =IF($F$5="","",IF(OR(D16="",D16="-"),"",IF(D16>0,"(soulevement)",IF(D16<0,"(compression)","-")))) | I16: =IF(OR($M$5="",NOT(TRUE)),"","Neige accidentelle") | J16: =IF($M$5="","",IFERROR(LOOKUP(2,1/((SAISIE!$M$5:$M$204=$M$5)*(ISNUMBER(SEARCH("accidentel",SAISIE!$J$5:$J$204)))),SAISIE!$K$5:$K$204),"-")) | K16: =IF($M$5="","",IFERROR(LOOKUP(2,1/((SAISIE!$M$5:$M$204=$M$5)*(ISNUMBER(SEARCH("accidentel",SAISIE!$J$5:$J$204)))),SAISIE!$L$5:$L$204),"-")) | L16: =IF($M$5="","",IF(OR(K16="",K16="-"),"",IF(K16>0,"(soulevement)",IF(K16<0,"(compression)","-"))))
A17: =IF($F$17="","","Noeud "&$F$17) | F17: =IFERROR(INDEX(SAISIE!$F$5:$F$204,AGGREGATE(15,6,ROW(SAISIE!$F$5:$F$204)-ROW(SAISIE!$F$5)+1/(SAISIE!$F$5:$F$204<>"")/(COUNTIF($F$4:F16,SAISIE!$F$5:$F$204)=0),1)),"") | I17: =IF($M$17="","","Noeud "&$M$17) | M17: =IFERROR(INDEX(SAISIE!$M$5:$M$204,AGGREGATE(15,6,ROW(SAISIE!$M$5:$M$204)-ROW(SAISIE!$M$5)+1/(SAISIE!$M$5:$M$204<>"")/(COUNTIF($M$4:M16,SAISIE!$M$5:$M$204)=0),1)),"")
A18: =IF(OR($F$17="",NOT(TRUE)),"","Couverture") | B18: =IF($F$17="","",IFERROR(IFERROR(LOOKUP(2,1/((SAISIE!$F$5:$F$204=$F$17)*(LEFT(SAISIE!$B$5:$B$204,2)="G ")),SAISIE!$C$5:$C$204),LOOKUP(2,1/((SAISIE!$F$5:$F$204=$F$17)*(ISNUMBER(SEARCH("Couverture",SAISIE!$B$5:$B$204)))),SAISIE!$C$5:$C$204)),"-")) | C18: =IF($F$17="","",IFERROR(IFERROR(LOOKUP(2,1/((SAISIE!$F$5:$F$204=$F$17)*(LEFT(SAISIE!$B$5:$B$204,2)="G ")),SAISIE!$D$5:$D$204),LOOKUP(2,1/((SAISIE!$F$5:$F$204=$F$17)*(ISNUMBER(SEARCH("Couverture",SAISIE!$B$5:$B$204)))),SAISIE!$D$5:$D$204)),"-")) | D18: =IF($F$17="","",IFERROR(IFERROR(LOOKUP(2,1/((SAISIE!$F$5:$F$204=$F$17)*(LEFT(SAISIE!$B$5:$B$204,2)="G ")),SAISIE!$E$5:$E$204),LOOKUP(2,1/((SAISIE!$F$5:$F$204=$F$17)*(ISNUMBER(SEARCH("Couverture",SAISIE!$B$5:$B$204)))),SAISIE!$E$5:$E$204)),"-")) | E18: =IF($F$17="","",IF(OR(D18="",D18="-"),"",IF(D18>0,"(soulevement)",IF(D18<0,"(compression)","-")))) | I18: =IF(OR($M$17="",NOT(TRUE)),"","Couverture") | J18: =IF($M$17="","",IFERROR(IFERROR(LOOKUP(2,1/((SAISIE!$M$5:$M$204=$M$17)*(LEFT(SAISIE!$J$5:$J$204,2)="G ")),SAISIE!$K$5:$K$204),LOOKUP(2,1/((SAISIE!$M$5:$M$204=$M$17)*(ISNUMBER(SEARCH("Couverture",SAISIE!$J$5:$J$204)))),SAISIE!$K$5:$K$204)),"-")) | K18: =IF($M$17="","",IFERROR(IFERROR(LOOKUP(2,1/((SAISIE!$M$5:$M$204=$M$17)*(LEFT(SAISIE!$J$5:$J$204,2)="G ")),SAISIE!$L$5:$L$204),LOOKUP(2,1/((SAISIE!$M$5:$M$204=$M$17)*(ISNUMBER(SEARCH("Couverture",SAISIE!$J$5:$J$204)))),SAISIE!$L$5:$L$204)),"-")) | L18: =IF($M$17="","",IF(OR(K18="",K18="-"),"",IF(K18>0,"(soulevement)",IF(K18<0,"(compression)","-"))))
A19: =IF(OR($F$17="",NOT(COUNTIFS(SAISIE!$B$5:$B$204,"*Vent G/D*",SAISIE!$F$5:$F$204,$F$17)>0)),"","Vent G/D") | B19: =IF(OR($F$17="",NOT(COUNTIFS(SAISIE!$B$5:$B$204,"*Vent G/D*",SAISIE!$F$5:$F$204,$F$17)>0)),"",IFERROR(IF(MINIFS(SAISIE!$E$5:$E$204,SAISIE!$B$5:$B$204,"*Vent G/D*",SAISIE!$F$5:$F$204,$F$17)>=0,MAXIFS(SAISIE!$C$5:$C$204,SAISIE!$B$5:$B$204,"*Vent G/D*",SAISIE!$F$5:$F$204,$F$17),INDEX(SAISIE!$C$5:$C$204,MATCH(MINIFS(SAISIE!$E$5:$E$204,SAISIE!$B$5:$B$204,"*Vent G/D*",SAISIE!$F$5:$F$204,$F$17),SAISIE!$E$5:$E$204,0))),"-")) | C19: =IF(OR($F$17="",NOT(COUNTIFS(SAISIE!$B$5:$B$204,"*Vent G/D*",SAISIE!$F$5:$F$204,$F$17)>0)),"",IFERROR(IF(MINIFS(SAISIE!$E$5:$E$204,SAISIE!$B$5:$B$204,"*Vent G/D*",SAISIE!$F$5:$F$204,$F$17)>=0,INDEX(SAISIE!$D$5:$D$204,MATCH(MAXIFS(SAISIE!$C$5:$C$204,SAISIE!$B$5:$B$204,"*Vent G/D*",SAISIE!$F$5:$F$204,$F$17),SAISIE!$C$5:$C$204,0)),INDEX(SAISIE!$D$5:$D$204,MATCH(MINIFS(SAISIE!$E$5:$E$204,SAISIE!$B$5:$B$204,"*Vent G/D*",SAISIE!$F$5:$F$204,$F$17),SAISIE!$E$5:$E$204,0))),"-")) | D19: =IF(OR($F$17="",NOT(COUNTIFS(SAISIE!$B$5:$B$204,"*Vent G/D*",SAISIE!$F$5:$F$204,$F$17)>0)),"",IFERROR(IF(MINIFS(SAISIE!$E$5:$E$204,SAISIE!$B$5:$B$204,"*Vent G/D*",SAISIE!$F$5:$F$204,$F$17)>=0,0,MINIFS(SAISIE!$E$5:$E$204,SAISIE!$B$5:$B$204,"*Vent G/D*",SAISIE!$F$5:$F$204,$F$17)),"-")) | E19: =IF($F$17="","",IF(OR(D19="",D19="-"),"",IF(D19>0,"(soulevement)",IF(D19<0,"(compression)","-")))) | I19: =IF(OR($M$17="",NOT(COUNTIFS(SAISIE!$J$5:$J$204,"*Vent G/D*",SAISIE!$M$5:$M$204,$M$17)>0)),"","Vent G/D") | J19: =IF(OR($M$17="",NOT(COUNTIFS(SAISIE!$J$5:$J$204,"*Vent G/D*",SAISIE!$M$5:$M$204,$M$17)>0)),"",IFERROR(IF(MINIFS(SAISIE!$L$5:$L$204,SAISIE!$J$5:$J$204,"*Vent G/D*",SAISIE!$M$5:$M$204,$M$17)>=0,MAXIFS(SAISIE!$K$5:$K$204,SAISIE!$J$5:$J$204,"*Vent G/D*",SAISIE!$M$5:$M$204,$M$17),INDEX(SAISIE!$K$5:$K$204,MATCH(MINIFS(SAISIE!$L$5:$L$204,SAISIE!$J$5:$J$204,"*Vent G/D*",SAISIE!$M$5:$M$204,$M$17),SAISIE!$L$5:$L$204,0))),"-")) | K19: =IF(OR($M$17="",NOT(COUNTIFS(SAISIE!$J$5:$J$204,"*Vent G/D*",SAISIE!$M$5:$M$204,$M$17)>0)),"",IFERROR(IF(MINIFS(SAISIE!$L$5:$L$204,SAISIE!$J$5:$J$204,"*Vent G/D*",SAISIE!$M$5:$M$204,$M$17)>=0,0,MINIFS(SAISIE!$L$5:$L$204,SAISIE!$J$5:$J$204,"*Vent G/D*",SAISIE!$M$5:$M$204,$M$17)),"-")) | L19: =IF($M$17="","",IF(OR(K19="",K19="-"),"",IF(K19>0,"(soulevement)",IF(K19<0,"(compression)","-"))))
A20: =IF(OR($F$17="",NOT(MAXIFS(SAISIE!$E$5:$E$204,SAISIE!$B$5:$B$204,"*Vent G/D*",SAISIE!$F$5:$F$204,$F$17)>0)),"","Vent G/D") | B20: =IF(OR($F$17="",NOT(MAXIFS(SAISIE!$E$5:$E$204,SAISIE!$B$5:$B$204,"*Vent G/D*",SAISIE!$F$5:$F$204,$F$17)>0)),"",IFERROR(INDEX(SAISIE!$C$5:$C$204,MATCH(MAXIFS(SAISIE!$E$5:$E$204,SAISIE!$B$5:$B$204,"*Vent G/D*",SAISIE!$F$5:$F$204,$F$17),SAISIE!$E$5:$E$204,0)),"-")) | C20: =IF(OR($F$17="",NOT(MAXIFS(SAISIE!$E$5:$E$204,SAISIE!$B$5:$B$204,"*Vent G/D*",SAISIE!$F$5:$F$204,$F$17)>0)),"",IFERROR(INDEX(SAISIE!$D$5:$D$204,MATCH(MAXIFS(SAISIE!$E$5:$E$204,SAISIE!$B$5:$B$204,"*Vent G/D*",SAISIE!$F$5:$F$204,$F$17),SAISIE!$E$5:$E$204,0)),"-")) | D20: =IF(OR($F$17="",NOT(MAXIFS(SAISIE!$E$5:$E$204,SAISIE!$B$5:$B$204,"*Vent G/D*",SAISIE!$F$5:$F$204,$F$17)>0)),"",IFERROR(MAXIFS(SAISIE!$E$5:$E$204,SAISIE!$B$5:$B$204,"*Vent G/D*",SAISIE!$F$5:$F$204,$F$17),"-")) | E20: =IF($F$17="","",IF(OR(D20="",D20="-"),"",IF(D20>0,"(soulevement)",IF(D20<0,"(compression)","-")))) | I20: =IF(OR($M$17="",NOT(MAXIFS(SAISIE!$L$5:$L$204,SAISIE!$J$5:$J$204,"*Vent G/D*",SAISIE!$M$5:$M$204,$M$17)>0)),"","Vent G/D") | J20: =IF(OR($M$17="",NOT(MAXIFS(SAISIE!$L$5:$L$204,SAISIE!$J$5:$J$204,"*Vent G/D*",SAISIE!$M$5:$M$204,$M$17)>0)),"",IFERROR(INDEX(SAISIE!$K$5:$K$204,MATCH(MAXIFS(SAISIE!$L$5:$L$204,SAISIE!$J$5:$J$204,"*Vent G/D*",SAISIE!$M$5:$M$204,$M$17),SAISIE!$L$5:$L$204,0)),"-")) | K20: =IF(OR($M$17="",NOT(MAXIFS(SAISIE!$L$5:$L$204,SAISIE!$J$5:$J$204,"*Vent G/D*",SAISIE!$M$5:$M$204,$M$17)>0)),"",IFERROR(MAXIFS(SAISIE!$L$5:$L$204,SAISIE!$J$5:$J$204,"*Vent G/D*",SAISIE!$M$5:$M$204,$M$17),"-")) | L20: =IF($M$17="","",IF(OR(K20="",K20="-"),"",IF(K20>0,"(soulevement)",IF(K20<0,"(compression)","-"))))
A21: =IF(OR($F$17="",NOT(COUNTIFS(SAISIE!$B$5:$B$204,"*Vent D/G*",SAISIE!$F$5:$F$204,$F$17)>0)),"","Vent D/G") | B21: =IF(OR($F$17="",NOT(COUNTIFS(SAISIE!$B$5:$B$204,"*Vent D/G*",SAISIE!$F$5:$F$204,$F$17)>0)),"",IFERROR(IF(MINIFS(SAISIE!$E$5:$E$204,SAISIE!$B$5:$B$204,"*Vent D/G*",SAISIE!$F$5:$F$204,$F$17)>=0,MAXIFS(SAISIE!$C$5:$C$204,SAISIE!$B$5:$B$204,"*Vent D/G*",SAISIE!$F$5:$F$204,$F$17),INDEX(SAISIE!$C$5:$C$204,MATCH(MINIFS(SAISIE!$E$5:$E$204,SAISIE!$B$5:$B$204,"*Vent D/G*",SAISIE!$F$5:$F$204,$F$17),SAISIE!$E$5:$E$204,0))),"-")) | C21: =IF(OR($F$17="",NOT(COUNTIFS(SAISIE!$B$5:$B$204,"*Vent D/G*",SAISIE!$F$5:$F$204,$F$17)>0)),"",IFERROR(IF(MINIFS(SAISIE!$E$5:$E$204,SAISIE!$B$5:$B$204,"*Vent D/G*",SAISIE!$F$5:$F$204,$F$17)>=0,INDEX(SAISIE!$D$5:$D$204,MATCH(MAXIFS(SAISIE!$C$5:$C$204,SAISIE!$B$5:$B$204,"*Vent D/G*",SAISIE!$F$5:$F$204,$F$17),SAISIE!$C$5:$C$204,0)),INDEX(SAISIE!$D$5:$D$204,MATCH(MINIFS(SAISIE!$E$5:$E$204,SAISIE!$B$5:$B$204,"*Vent D/G*",SAISIE!$F$5:$F$204,$F$17),SAISIE!$E$5:$E$204,0))),"-")) | D21: =IF(OR($F$17="",NOT(COUNTIFS(SAISIE!$B$5:$B$204,"*Vent D/G*",SAISIE!$F$5:$F$204,$F$17)>0)),"",IFERROR(IF(MINIFS(SAISIE!$E$5:$E$204,SAISIE!$B$5:$B$204,"*Vent D/G*",SAISIE!$F$5:$F$204,$F$17)>=0,0,MINIFS(SAISIE!$E$5:$E$204,SAISIE!$B$5:$B$204,"*Vent D/G*",SAISIE!$F$5:$F$204,$F$17)),"-")) | E21: =IF($F$17="","",IF(OR(D21="",D21="-"),"",IF(D21>0,"(soulevement)",IF(D21<0,"(compression)","-")))) | I21: =IF(OR($M$17="",NOT(COUNTIFS(SAISIE!$J$5:$J$204,"*Vent D/G*",SAISIE!$M$5:$M$204,$M$17)>0)),"","Vent D/G") | J21: =IF(OR($M$17="",NOT(COUNTIFS(SAISIE!$J$5:$J$204,"*Vent D/G*",SAISIE!$M$5:$M$204,$M$17)>0)),"",IFERROR(IF(MINIFS(SAISIE!$L$5:$L$204,SAISIE!$J$5:$J$204,"*Vent D/G*",SAISIE!$M$5:$M$204,$M$17)>=0,MAXIFS(SAISIE!$K$5:$K$204,SAISIE!$J$5:$J$204,"*Vent D/G*",SAISIE!$M$5:$M$204,$M$17),INDEX(SAISIE!$K$5:$K$204,MATCH(MINIFS(SAISIE!$L$5:$L$204,SAISIE!$J$5:$J$204,"*Vent D/G*",SAISIE!$M$5:$M$204,$M$17),SAISIE!$L$5:$L$204,0))),"-")) | K21: =IF(OR($M$17="",NOT(COUNTIFS(SAISIE!$J$5:$J$204,"*Vent D/G*",SAISIE!$M$5:$M$204,$M$17)>0)),"",IFERROR(IF(MINIFS(SAISIE!$L$5:$L$204,SAISIE!$J$5:$J$204,"*Vent D/G*",SAISIE!$M$5:$M$204,$M$17)>=0,0,MINIFS(SAISIE!$L$5:$L$204,SAISIE!$J$5:$J$204,"*Vent D/G*",SAISIE!$M$5:$M$204,$M$17)),"-")) | L21: =IF($M$17="","",IF(OR(K21="",K21="-"),"",IF(K21>0,"(soulevement)",IF(K21<0,"(compression)","-"))))
A22: =IF(OR($F$17="",NOT(MAXIFS(SAISIE!$E$5:$E$204,SAISIE!$B$5:$B$204,"*Vent D/G*",SAISIE!$F$5:$F$204,$F$17)>0)),"","Vent D/G") | B22: =IF(OR($F$17="",NOT(MAXIFS(SAISIE!$E$5:$E$204,SAISIE!$B$5:$B$204,"*Vent D/G*",SAISIE!$F$5:$F$204,$F$17)>0)),"",IFERROR(INDEX(SAISIE!$C$5:$C$204,MATCH(MAXIFS(SAISIE!$E$5:$E$204,SAISIE!$B$5:$B$204,"*Vent D/G*",SAISIE!$F$5:$F$204,$F$17),SAISIE!$E$5:$E$204,0)),"-")) | C22: =IF(OR($F$17="",NOT(MAXIFS(SAISIE!$E$5:$E$204,SAISIE!$B$5:$B$204,"*Vent D/G*",SAISIE!$F$5:$F$204,$F$17)>0)),"",IFERROR(INDEX(SAISIE!$D$5:$D$204,MATCH(MAXIFS(SAISIE!$E$5:$E$204,SAISIE!$B$5:$B$204,"*Vent D/G*",SAISIE!$F$5:$F$204,$F$17),SAISIE!$E$5:$E$204,0)),"-")) | D22: =IF(OR($F$17="",NOT(MAXIFS(SAISIE!$E$5:$E$204,SAISIE!$B$5:$B$204,"*Vent D/G*",SAISIE!$F$5:$F$204,$F$17)>0)),"",IFERROR(MAXIFS(SAISIE!$E$5:$E$204,SAISIE!$B$5:$B$204,"*Vent D/G*",SAISIE!$F$5:$F$204,$F$17),"-")) | E22: =IF($F$17="","",IF(OR(D22="",D22="-"),"",IF(D22>0,"(soulevement)",IF(D22<0,"(compression)","-")))) | I22: =IF(OR($M$17="",NOT(MAXIFS(SAISIE!$L$5:$L$204,SAISIE!$J$5:$J$204,"*Vent D/G*",SAISIE!$M$5:$M$204,$M$17)>0)),"","Vent D/G") | J22: =IF(OR($M$17="",NOT(MAXIFS(SAISIE!$L$5:$L$204,SAISIE!$J$5:$J$204,"*Vent D/G*",SAISIE!$M$5:$M$204,$M$17)>0)),"",IFERROR(INDEX(SAISIE!$K$5:$K$204,MATCH(MAXIFS(SAISIE!$L$5:$L$204,SAISIE!$J$5:$J$204,"*Vent D/G*",SAISIE!$M$5:$M$204,$M$17),SAISIE!$L$5:$L$204,0)),"-")) | K22: =IF(OR($M$17="",NOT(MAXIFS(SAISIE!$L$5:$L$204,SAISIE!$J$5:$J$204,"*Vent D/G*",SAISIE!$M$5:$M$204,$M$17)>0)),"",IFERROR(MAXIFS(SAISIE!$L$5:$L$204,SAISIE!$J$5:$J$204,"*Vent D/G*",SAISIE!$M$5:$M$204,$M$17),"-")) | L22: =IF($M$17="","",IF(OR(K22="",K22="-"),"",IF(K22>0,"(soulevement)",IF(K22<0,"(compression)","-"))))
A23: =IF(OR($F$17="",NOT(COUNTIFS(SAISIE!$B$5:$B$204,"*Vent Av./Arr.*",SAISIE!$F$5:$F$204,$F$17)>0)),"","Vent Av./Arr.") | B23: =IF(OR($F$17="",NOT(COUNTIFS(SAISIE!$B$5:$B$204,"*Vent Av./Arr.*",SAISIE!$F$5:$F$204,$F$17)>0)),"",IFERROR(IF(MINIFS(SAISIE!$E$5:$E$204,SAISIE!$B$5:$B$204,"*Vent Av./Arr.*",SAISIE!$F$5:$F$204,$F$17)>=0,MAXIFS(SAISIE!$C$5:$C$204,SAISIE!$B$5:$B$204,"*Vent Av./Arr.*",SAISIE!$F$5:$F$204,$F$17),INDEX(SAISIE!$C$5:$C$204,MATCH(MINIFS(SAISIE!$E$5:$E$204,SAISIE!$B$5:$B$204,"*Vent Av./Arr.*",SAISIE!$F$5:$F$204,$F$17),SAISIE!$E$5:$E$204,0))),"-")) | C23: =IF(OR($F$17="",NOT(COUNTIFS(SAISIE!$B$5:$B$204,"*Vent Av./Arr.*",SAISIE!$F$5:$F$204,$F$17)>0)),"",IFERROR(IF(MINIFS(SAISIE!$E$5:$E$204,SAISIE!$B$5:$B$204,"*Vent Av./Arr.*",SAISIE!$F$5:$F$204,$F$17)>=0,INDEX(SAISIE!$D$5:$D$204,MATCH(MAXIFS(SAISIE!$C$5:$C$204,SAISIE!$B$5:$B$204,"*Vent Av./Arr.*",SAISIE!$F$5:$F$204,$F$17),SAISIE!$C$5:$C$204,0)),INDEX(SAISIE!$D$5:$D$204,MATCH(MINIFS(SAISIE!$E$5:$E$204,SAISIE!$B$5:$B$204,"*Vent Av./Arr.*",SAISIE!$F$5:$F$204,$F$17),SAISIE!$E$5:$E$204,0))),"-")) | D23: =IF(OR($F$17="",NOT(COUNTIFS(SAISIE!$B$5:$B$204,"*Vent Av./Arr.*",SAISIE!$F$5:$F$204,$F$17)>0)),"",IFERROR(IF(MINIFS(SAISIE!$E$5:$E$204,SAISIE!$B$5:$B$204,"*Vent Av./Arr.*",SAISIE!$F$5:$F$204,$F$17)>=0,0,MINIFS(SAISIE!$E$5:$E$204,SAISIE!$B$5:$B$204,"*Vent Av./Arr.*",SAISIE!$F$5:$F$204,$F$17)),"-")) | E23: =IF($F$17="","",IF(OR(D23="",D23="-"),"",IF(D23>0,"(soulevement)",IF(D23<0,"(compression)","-")))) | I23: =IF(OR($M$17="",NOT(COUNTIFS(SAISIE!$J$5:$J$204,"*Vent Av./Arr.*",SAISIE!$M$5:$M$204,$M$17)>0)),"","Vent Av./Arr.") | J23: =IF(OR($M$17="",NOT(COUNTIFS(SAISIE!$J$5:$J$204,"*Vent Av./Arr.*",SAISIE!$M$5:$M$204,$M$17)>0)),"",IFERROR(IF(MINIFS(SAISIE!$L$5:$L$204,SAISIE!$J$5:$J$204,"*Vent Av./Arr.*",SAISIE!$M$5:$M$204,$M$17)>=0,MAXIFS(SAISIE!$K$5:$K$204,SAISIE!$J$5:$J$204,"*Vent Av./Arr.*",SAISIE!$M$5:$M$204,$M$17),INDEX(SAISIE!$K$5:$K$204,MATCH(MINIFS(SAISIE!$L$5:$L$204,SAISIE!$J$5:$J$204,"*Vent Av./Arr.*",SAISIE!$M$5:$M$204,$M$17),SAISIE!$L$5:$L$204,0))),"-")) | K23: =IF(OR($M$17="",NOT(COUNTIFS(SAISIE!$J$5:$J$204,"*Vent Av./Arr.*",SAISIE!$M$5:$M$204,$M$17)>0)),"",IFERROR(IF(MINIFS(SAISIE!$L$5:$L$204,SAISIE!$J$5:$J$204,"*Vent Av./Arr.*",SAISIE!$M$5:$M$204,$M$17)>=0,0,MINIFS(SAISIE!$L$5:$L$204,SAISIE!$J$5:$J$204,"*Vent Av./Arr.*",SAISIE!$M$5:$M$204,$M$17)),"-")) | L23: =IF($M$17="","",IF(OR(K23="",K23="-"),"",IF(K23>0,"(soulevement)",IF(K23<0,"(compression)","-"))))
A24: =IF(OR($F$17="",NOT(MAXIFS(SAISIE!$E$5:$E$204,SAISIE!$B$5:$B$204,"*Vent Av./Arr.*",SAISIE!$F$5:$F$204,$F$17)>0)),"","Vent Av./Arr.") | B24: =IF(OR($F$17="",NOT(MAXIFS(SAISIE!$E$5:$E$204,SAISIE!$B$5:$B$204,"*Vent Av./Arr.*",SAISIE!$F$5:$F$204,$F$17)>0)),"",IFERROR(INDEX(SAISIE!$C$5:$C$204,MATCH(MAXIFS(SAISIE!$E$5:$E$204,SAISIE!$B$5:$B$204,"*Vent Av./Arr.*",SAISIE!$F$5:$F$204,$F$17),SAISIE!$E$5:$E$204,0)),"-")) | C24: =IF(OR($F$17="",NOT(MAXIFS(SAISIE!$E$5:$E$204,SAISIE!$B$5:$B$204,"*Vent Av./Arr.*",SAISIE!$F$5:$F$204,$F$17)>0)),"",IFERROR(INDEX(SAISIE!$D$5:$D$204,MATCH(MAXIFS(SAISIE!$E$5:$E$204,SAISIE!$B$5:$B$204,"*Vent Av./Arr.*",SAISIE!$F$5:$F$204,$F$17),SAISIE!$E$5:$E$204,0)),"-")) | D24: =IF(OR($F$17="",NOT(MAXIFS(SAISIE!$E$5:$E$204,SAISIE!$B$5:$B$204,"*Vent Av./Arr.*",SAISIE!$F$5:$F$204,$F$17)>0)),"",IFERROR(MAXIFS(SAISIE!$E$5:$E$204,SAISIE!$B$5:$B$204,"*Vent Av./Arr.*",SAISIE!$F$5:$F$204,$F$17),"-")) | E24: =IF($F$17="","",IF(OR(D24="",D24="-"),"",IF(D24>0,"(soulevement)",IF(D24<0,"(compression)","-")))) | I24: =IF(OR($M$17="",NOT(MAXIFS(SAISIE!$L$5:$L$204,SAISIE!$J$5:$J$204,"*Vent Av./Arr.*",SAISIE!$M$5:$M$204,$M$17)>0)),"","Vent Av./Arr.") | J24: =IF(OR($M$17="",NOT(MAXIFS(SAISIE!$L$5:$L$204,SAISIE!$J$5:$J$204,"*Vent Av./Arr.*",SAISIE!$M$5:$M$204,$M$17)>0)),"",IFERROR(INDEX(SAISIE!$K$5:$K$204,MATCH(MAXIFS(SAISIE!$L$5:$L$204,SAISIE!$J$5:$J$204,"*Vent Av./Arr.*",SAISIE!$M$5:$M$204,$M$17),SAISIE!$L$5:$L$204,0)),"-")) | K24: =IF(OR($M$17="",NOT(MAXIFS(SAISIE!$L$5:$L$204,SAISIE!$J$5:$J$204,"*Vent Av./Arr.*",SAISIE!$M$5:$M$204,$M$17)>0)),"",IFERROR(MAXIFS(SAISIE!$L$5:$L$204,SAISIE!$J$5:$J$204,"*Vent Av./Arr.*",SAISIE!$M$5:$M$204,$M$17),"-")) | L24: =IF($M$17="","",IF(OR(K24="",K24="-"),"",IF(K24>0,"(soulevement)",IF(K24<0,"(compression)","-"))))
A25: =IF(OR($F$17="",NOT(COUNTIFS(SAISIE!$B$5:$B$204,"*Vent Arr./Av.*",SAISIE!$F$5:$F$204,$F$17)>0)),"","Vent Arr./Av.") | B25: =IF(OR($F$17="",NOT(COUNTIFS(SAISIE!$B$5:$B$204,"*Vent Arr./Av.*",SAISIE!$F$5:$F$204,$F$17)>0)),"",IFERROR(IF(MINIFS(SAISIE!$E$5:$E$204,SAISIE!$B$5:$B$204,"*Vent Arr./Av.*",SAISIE!$F$5:$F$204,$F$17)>=0,MAXIFS(SAISIE!$C$5:$C$204,SAISIE!$B$5:$B$204,"*Vent Arr./Av.*",SAISIE!$F$5:$F$204,$F$17),INDEX(SAISIE!$C$5:$C$204,MATCH(MINIFS(SAISIE!$E$5:$E$204,SAISIE!$B$5:$B$204,"*Vent Arr./Av.*",SAISIE!$F$5:$F$204,$F$17),SAISIE!$E$5:$E$204,0))),"-")) | C25: =IF(OR($F$17="",NOT(COUNTIFS(SAISIE!$B$5:$B$204,"*Vent Arr./Av.*",SAISIE!$F$5:$F$204,$F$17)>0)),"",IFERROR(IF(MINIFS(SAISIE!$E$5:$E$204,SAISIE!$B$5:$B$204,"*Vent Arr./Av.*",SAISIE!$F$5:$F$204,$F$17)>=0,INDEX(SAISIE!$D$5:$D$204,MATCH(MAXIFS(SAISIE!$C$5:$C$204,SAISIE!$B$5:$B$204,"*Vent Arr./Av.*",SAISIE!$F$5:$F$204,$F$17),SAISIE!$C$5:$C$204,0)),INDEX(SAISIE!$D$5:$D$204,MATCH(MINIFS(SAISIE!$E$5:$E$204,SAISIE!$B$5:$B$204,"*Vent Arr./Av.*",SAISIE!$F$5:$F$204,$F$17),SAISIE!$E$5:$E$204,0))),"-")) | D25: =IF(OR($F$17="",NOT(COUNTIFS(SAISIE!$B$5:$B$204,"*Vent Arr./Av.*",SAISIE!$F$5:$F$204,$F$17)>0)),"",IFERROR(IF(MINIFS(SAISIE!$E$5:$E$204,SAISIE!$B$5:$B$204,"*Vent Arr./Av.*",SAISIE!$F$5:$F$204,$F$17)>=0,0,MINIFS(SAISIE!$E$5:$E$204,SAISIE!$B$5:$B$204,"*Vent Arr./Av.*",SAISIE!$F$5:$F$204,$F$17)),"-")) | E25: =IF($F$17="","",IF(OR(D25="",D25="-"),"",IF(D25>0,"(soulevement)",IF(D25<0,"(compression)","-")))) | I25: =IF(OR($M$17="",NOT(COUNTIFS(SAISIE!$J$5:$J$204,"*Vent Arr./Av.*",SAISIE!$M$5:$M$204,$M$17)>0)),"","Vent Arr./Av.") | J25: =IF(OR($M$17="",NOT(COUNTIFS(SAISIE!$J$5:$J$204,"*Vent Arr./Av.*",SAISIE!$M$5:$M$204,$M$17)>0)),"",IFERROR(IF(MINIFS(SAISIE!$L$5:$L$204,SAISIE!$J$5:$J$204,"*Vent Arr./Av.*",SAISIE!$M$5:$M$204,$M$17)>=0,MAXIFS(SAISIE!$K$5:$K$204,SAISIE!$J$5:$J$204,"*Vent Arr./Av.*",SAISIE!$M$5:$M$204,$M$17),INDEX(SAISIE!$K$5:$K$204,MATCH(MINIFS(SAISIE!$L$5:$L$204,SAISIE!$J$5:$J$204,"*Vent Arr./Av.*",SAISIE!$M$5:$M$204,$M$17),SAISIE!$L$5:$L$204,0))),"-")) | K25: =IF(OR($M$17="",NOT(COUNTIFS(SAISIE!$J$5:$J$204,"*Vent Arr./Av.*",SAISIE!$M$5:$M$204,$M$17)>0)),"",IFERROR(IF(MINIFS(SAISIE!$L$5:$L$204,SAISIE!$J$5:$J$204,"*Vent Arr./Av.*",SAISIE!$M$5:$M$204,$M$17)>=0,0,MINIFS(SAISIE!$L$5:$L$204,SAISIE!$J$5:$J$204,"*Vent Arr./Av.*",SAISIE!$M$5:$M$204,$M$17)),"-")) | L25: =IF($M$17="","",IF(OR(K25="",K25="-"),"",IF(K25>0,"(soulevement)",IF(K25<0,"(compression)","-"))))
A26: =IF(OR($F$17="",NOT(MAXIFS(SAISIE!$E$5:$E$204,SAISIE!$B$5:$B$204,"*Vent Arr./Av.*",SAISIE!$F$5:$F$204,$F$17)>0)),"","Vent Arr./Av.") | B26: =IF(OR($F$17="",NOT(MAXIFS(SAISIE!$E$5:$E$204,SAISIE!$B$5:$B$204,"*Vent Arr./Av.*",SAISIE!$F$5:$F$204,$F$17)>0)),"",IFERROR(INDEX(SAISIE!$C$5:$C$204,MATCH(MAXIFS(SAISIE!$E$5:$E$204,SAISIE!$B$5:$B$204,"*Vent Arr./Av.*",SAISIE!$F$5:$F$204,$F$17),SAISIE!$E$5:$E$204,0)),"-")) | C26: =IF(OR($F$17="",NOT(MAXIFS(SAISIE!$E$5:$E$204,SAISIE!$B$5:$B$204,"*Vent Arr./Av.*",SAISIE!$F$5:$F$204,$F$17)>0)),"",IFERROR(INDEX(SAISIE!$D$5:$D$204,MATCH(MAXIFS(SAISIE!$E$5:$E$204,SAISIE!$B$5:$B$204,"*Vent Arr./Av.*",SAISIE!$F$5:$F$204,$F$17),SAISIE!$E$5:$E$204,0)),"-")) | D26: =IF(OR($F$17="",NOT(MAXIFS(SAISIE!$E$5:$E$204,SAISIE!$B$5:$B$204,"*Vent Arr./Av.*",SAISIE!$F$5:$F$204,$F$17)>0)),"",IFERROR(MAXIFS(SAISIE!$E$5:$E$204,SAISIE!$B$5:$B$204,"*Vent Arr./Av.*",SAISIE!$F$5:$F$204,$F$17),"-")) | E26: =IF($F$17="","",IF(OR(D26="",D26="-"),"",IF(D26>0,"(soulevement)",IF(D26<0,"(compression)","-")))) | I26: =IF(OR($M$17="",NOT(MAXIFS(SAISIE!$L$5:$L$204,SAISIE!$J$5:$J$204,"*Vent Arr./Av.*",SAISIE!$M$5:$M$204,$M$17)>0)),"","Vent Arr./Av.") | J26: =IF(OR($M$17="",NOT(MAXIFS(SAISIE!$L$5:$L$204,SAISIE!$J$5:$J$204,"*Vent Arr./Av.*",SAISIE!$M$5:$M$204,$M$17)>0)),"",IFERROR(INDEX(SAISIE!$K$5:$K$204,MATCH(MAXIFS(SAISIE!$L$5:$L$204,SAISIE!$J$5:$J$204,"*Vent Arr./Av.*",SAISIE!$M$5:$M$204,$M$17),SAISIE!$L$5:$L$204,0)),"-")) | K26: =IF(OR($M$17="",NOT(MAXIFS(SAISIE!$L$5:$L$204,SAISIE!$J$5:$J$204,"*Vent Arr./Av.*",SAISIE!$M$5:$M$204,$M$17)>0)),"",IFERROR(MAXIFS(SAISIE!$L$5:$L$204,SAISIE!$J$5:$J$204,"*Vent Arr./Av.*",SAISIE!$M$5:$M$204,$M$17),"-")) | L26: =IF($M$17="","",IF(OR(K26="",K26="-"),"",IF(K26>0,"(soulevement)",IF(K26<0,"(compression)","-"))))
A27: =IF(OR($F$17="",NOT(TRUE)),"","Neige normale") | B27: =IF($F$17="","",IFERROR(INDEX(SAISIE!$C$5:$C$204,MATCH(MINIFS(SAISIE!$E$5:$E$204,SAISIE!$B$5:$B$204,"*Neige*",SAISIE!$B$5:$B$204,"<>*accidentel*",SAISIE!$F$5:$F$204,$F$17),SAISIE!$E$5:$E$204,0)),"-")) | C27: =IF($F$17="","",IFERROR(INDEX(SAISIE!$D$5:$D$204,MATCH(MINIFS(SAISIE!$E$5:$E$204,SAISIE!$B$5:$B$204,"*Neige*",SAISIE!$B$5:$B$204,"<>*accidentel*",SAISIE!$F$5:$F$204,$F$17),SAISIE!$E$5:$E$204,0)),"-")) | D27: =IF($F$17="","",IFERROR(INDEX(SAISIE!$E$5:$E$204,MATCH(MINIFS(SAISIE!$E$5:$E$204,SAISIE!$B$5:$B$204,"*Neige*",SAISIE!$B$5:$B$204,"<>*accidentel*",SAISIE!$F$5:$F$204,$F$17),SAISIE!$E$5:$E$204,0)),"-")) | E27: =IF($F$17="","",IF(OR(D27="",D27="-"),"",IF(D27>0,"(soulevement)",IF(D27<0,"(compression)","-")))) | I27: =IF(OR($M$17="",NOT(TRUE)),"","Neige normale") | J27: =IF($M$17="","",IFERROR(INDEX(SAISIE!$K$5:$K$204,MATCH(MINIFS(SAISIE!$L$5:$L$204,SAISIE!$J$5:$J$204,"*Neige*",SAISIE!$J$5:$J$204,"<>*accidentel*",SAISIE!$M$5:$M$204,$M$17),SAISIE!$L$5:$L$204,0)),"-")) | K27: =IF($M$17="","",IFERROR(INDEX(SAISIE!$L$5:$L$204,MATCH(MINIFS(SAISIE!$L$5:$L$204,SAISIE!$J$5:$J$204,"*Neige*",SAISIE!$J$5:$J$204,"<>*accidentel*",SAISIE!$M$5:$M$204,$M$17),SAISIE!$L$5:$L$204,0)),"-")) | L27: =IF($M$17="","",IF(OR(K27="",K27="-"),"",IF(K27>0,"(soulevement)",IF(K27<0,"(compression)","-"))))
A28: =IF(OR($F$17="",NOT(TRUE)),"","Neige accidentelle") | B28: =IF($F$17="","",IFERROR(LOOKUP(2,1/((SAISIE!$F$5:$F$204=$F$17)*(ISNUMBER(SEARCH("accidentel",SAISIE!$B$5:$B$204)))),SAISIE!$C$5:$C$204),"-")) | C28: =IF($F$17="","",IFERROR(LOOKUP(2,1/((SAISIE!$F$5:$F$204=$F$17)*(ISNUMBER(SEARCH("accidentel",SAISIE!$B$5:$B$204)))),SAISIE!$D$5:$D$204),"-")) | D28: =IF($F$17="","",IFERROR(LOOKUP(2,1/((SAISIE!$F$5:$F$204=$F$17)*(ISNUMBER(SEARCH("accidentel",SAISIE!$B$5:$B$204)))),SAISIE!$E$5:$E$204),"-")) | E28: =IF($F$17="","",IF(OR(D28="",D28="-"),"",IF(D28>0,"(soulevement)",IF(D28<0,"(compression)","-")))) | I28: =IF(OR($M$17="",NOT(TRUE)),"","Neige accidentelle") | J28: =IF($M$17="","",IFERROR(LOOKUP(2,1/((SAISIE!$M$5:$M$204=$M$17)*(ISNUMBER(SEARCH("accidentel",SAISIE!$J$5:$J$204)))),SAISIE!$K$5:$K$204),"-")) | K28: =IF($M$17="","",IFERROR(LOOKUP(2,1/((SAISIE!$M$5:$M$204=$M$17)*(ISNUMBER(SEARCH("accidentel",SAISIE!$J$5:$J$204)))),SAISIE!$L$5:$L$204),"-")) | L28: =IF($M$17="","",IF(OR(K28="",K28="-"),"",IF(K28>0,"(soulevement)",IF(K28<0,"(compression)","-"))))
A29: =IF($F$29="","","Noeud "&$F$29) | F29: =IFERROR(INDEX(SAISIE!$F$5:$F$204,AGGREGATE(15,6,ROW(SAISIE!$F$5:$F$204)-ROW(SAISIE!$F$5)+1/(SAISIE!$F$5:$F$204<>"")/(COUNTIF($F$4:F28,SAISIE!$F$5:$F$204)=0),1)),"") | I29: =IF($M$29="","","Noeud "&$M$29) | M29: =IFERROR(INDEX(SAISIE!$M$5:$M$204,AGGREGATE(15,6,ROW(SAISIE!$M$5:$M$204)-ROW(SAISIE!$M$5)+1/(SAISIE!$M$5:$M$204<>"")/(COUNTIF($M$4:M28,SAISIE!$M$5:$M$204)=0),1)),"")
A30: =IF(OR($F$29="",NOT(TRUE)),"","Couverture") | B30: =IF($F$29="","",IFERROR(IFERROR(LOOKUP(2,1/((SAISIE!$F$5:$F$204=$F$29)*(LEFT(SAISIE!$B$5:$B$204,2)="G ")),SAISIE!$C$5:$C$204),LOOKUP(2,1/((SAISIE!$F$5:$F$204=$F$29)*(ISNUMBER(SEARCH("Couverture",SAISIE!$B$5:$B$204)))),SAISIE!$C$5:$C$204)),"-")) | C30: =IF($F$29="","",IFERROR(IFERROR(LOOKUP(2,1/((SAISIE!$F$5:$F$204=$F$29)*(LEFT(SAISIE!$B$5:$B$204,2)="G ")),SAISIE!$D$5:$D$204),LOOKUP(2,1/((SAISIE!$F$5:$F$204=$F$29)*(ISNUMBER(SEARCH("Couverture",SAISIE!$B$5:$B$204)))),SAISIE!$D$5:$D$204)),"-")) | D30: =IF($F$29="","",IFERROR(IFERROR(LOOKUP(2,1/((SAISIE!$F$5:$F$204=$F$29)*(LEFT(SAISIE!$B$5:$B$204,2)="G ")),SAISIE!$E$5:$E$204),LOOKUP(2,1/((SAISIE!$F$5:$F$204=$F$29)*(ISNUMBER(SEARCH("Couverture",SAISIE!$B$5:$B$204)))),SAISIE!$E$5:$E$204)),"-")) | E30: =IF($F$29="","",IF(OR(D30="",D30="-"),"",IF(D30>0,"(soulevement)",IF(D30<0,"(compression)","-")))) | I30: =IF(OR($M$29="",NOT(TRUE)),"","Couverture") | J30: =IF($M$29="","",IFERROR(IFERROR(LOOKUP(2,1/((SAISIE!$M$5:$M$204=$M$29)*(LEFT(SAISIE!$J$5:$J$204,2)="G ")),SAISIE!$K$5:$K$204),LOOKUP(2,1/((SAISIE!$M$5:$M$204=$M$29)*(ISNUMBER(SEARCH("Couverture",SAISIE!$J$5:$J$204)))),SAISIE!$K$5:$K$204)),"-")) | K30: =IF($M$29="","",IFERROR(IFERROR(LOOKUP(2,1/((SAISIE!$M$5:$M$204=$M$29)*(LEFT(SAISIE!$J$5:$J$204,2)="G ")),SAISIE!$L$5:$L$204),LOOKUP(2,1/((SAISIE!$M$5:$M$204=$M$29)*(ISNUMBER(SEARCH("Couverture",SAISIE!$J$5:$J$204)))),SAISIE!$L$5:$L$204)),"-")) | L30: =IF($M$29="","",IF(OR(K30="",K30="-"),"",IF(K30>0,"(soulevement)",IF(K30<0,"(compression)","-"))))
A31: =IF(OR($F$29="",NOT(COUNTIFS(SAISIE!$B$5:$B$204,"*Vent G/D*",SAISIE!$F$5:$F$204,$F$29)>0)),"","Vent G/D") | B31: =IF(OR($F$29="",NOT(COUNTIFS(SAISIE!$B$5:$B$204,"*Vent G/D*",SAISIE!$F$5:$F$204,$F$29)>0)),"",IFERROR(IF(MINIFS(SAISIE!$E$5:$E$204,SAISIE!$B$5:$B$204,"*Vent G/D*",SAISIE!$F$5:$F$204,$F$29)>=0,MAXIFS(SAISIE!$C$5:$C$204,SAISIE!$B$5:$B$204,"*Vent G/D*",SAISIE!$F$5:$F$204,$F$29),INDEX(SAISIE!$C$5:$C$204,MATCH(MINIFS(SAISIE!$E$5:$E$204,SAISIE!$B$5:$B$204,"*Vent G/D*",SAISIE!$F$5:$F$204,$F$29),SAISIE!$E$5:$E$204,0))),"-")) | C31: =IF(OR($F$29="",NOT(COUNTIFS(SAISIE!$B$5:$B$204,"*Vent G/D*",SAISIE!$F$5:$F$204,$F$29)>0)),"",IFERROR(IF(MINIFS(SAISIE!$E$5:$E$204,SAISIE!$B$5:$B$204,"*Vent G/D*",SAISIE!$F$5:$F$204,$F$29)>=0,INDEX(SAISIE!$D$5:$D$204,MATCH(MAXIFS(SAISIE!$C$5:$C$204,SAISIE!$B$5:$B$204,"*Vent G/D*",SAISIE!$F$5:$F$204,$F$29),SAISIE!$C$5:$C$204,0)),INDEX(SAISIE!$D$5:$D$204,MATCH(MINIFS(SAISIE!$E$5:$E$204,SAISIE!$B$5:$B$204,"*Vent G/D*",SAISIE!$F$5:$F$204,$F$29),SAISIE!$E$5:$E$204,0))),"-")) | D31: =IF(OR($F$29="",NOT(COUNTIFS(SAISIE!$B$5:$B$204,"*Vent G/D*",SAISIE!$F$5:$F$204,$F$29)>0)),"",IFERROR(IF(MINIFS(SAISIE!$E$5:$E$204,SAISIE!$B$5:$B$204,"*Vent G/D*",SAISIE!$F$5:$F$204,$F$29)>=0,0,MINIFS(SAISIE!$E$5:$E$204,SAISIE!$B$5:$B$204,"*Vent G/D*",SAISIE!$F$5:$F$204,$F$29)),"-")) | E31: =IF($F$29="","",IF(OR(D31="",D31="-"),"",IF(D31>0,"(soulevement)",IF(D31<0,"(compression)","-")))) | I31: =IF(OR($M$29="",NOT(COUNTIFS(SAISIE!$J$5:$J$204,"*Vent G/D*",SAISIE!$M$5:$M$204,$M$29)>0)),"","Vent G/D") | J31: =IF(OR($M$29="",NOT(COUNTIFS(SAISIE!$J$5:$J$204,"*Vent G/D*",SAISIE!$M$5:$M$204,$M$29)>0)),"",IFERROR(IF(MINIFS(SAISIE!$L$5:$L$204,SAISIE!$J$5:$J$204,"*Vent G/D*",SAISIE!$M$5:$M$204,$M$29)>=0,MAXIFS(SAISIE!$K$5:$K$204,SAISIE!$J$5:$J$204,"*Vent G/D*",SAISIE!$M$5:$M$204,$M$29),INDEX(SAISIE!$K$5:$K$204,MATCH(MINIFS(SAISIE!$L$5:$L$204,SAISIE!$J$5:$J$204,"*Vent G/D*",SAISIE!$M$5:$M$204,$M$29),SAISIE!$L$5:$L$204,0))),"-")) | K31: =IF(OR($M$29="",NOT(COUNTIFS(SAISIE!$J$5:$J$204,"*Vent G/D*",SAISIE!$M$5:$M$204,$M$29)>0)),"",IFERROR(IF(MINIFS(SAISIE!$L$5:$L$204,SAISIE!$J$5:$J$204,"*Vent G/D*",SAISIE!$M$5:$M$204,$M$29)>=0,0,MINIFS(SAISIE!$L$5:$L$204,SAISIE!$J$5:$J$204,"*Vent G/D*",SAISIE!$M$5:$M$204,$M$29)),"-")) | L31: =IF($M$29="","",IF(OR(K31="",K31="-"),"",IF(K31>0,"(soulevement)",IF(K31<0,"(compression)","-"))))
A32: =IF(OR($F$29="",NOT(MAXIFS(SAISIE!$E$5:$E$204,SAISIE!$B$5:$B$204,"*Vent G/D*",SAISIE!$F$5:$F$204,$F$29)>0)),"","Vent G/D") | B32: =IF(OR($F$29="",NOT(MAXIFS(SAISIE!$E$5:$E$204,SAISIE!$B$5:$B$204,"*Vent G/D*",SAISIE!$F$5:$F$204,$F$29)>0)),"",IFERROR(INDEX(SAISIE!$C$5:$C$204,MATCH(MAXIFS(SAISIE!$E$5:$E$204,SAISIE!$B$5:$B$204,"*Vent G/D*",SAISIE!$F$5:$F$204,$F$29),SAISIE!$E$5:$E$204,0)),"-")) | C32: =IF(OR($F$29="",NOT(MAXIFS(SAISIE!$E$5:$E$204,SAISIE!$B$5:$B$204,"*Vent G/D*",SAISIE!$F$5:$F$204,$F$29)>0)),"",IFERROR(INDEX(SAISIE!$D$5:$D$204,MATCH(MAXIFS(SAISIE!$E$5:$E$204,SAISIE!$B$5:$B$204,"*Vent G/D*",SAISIE!$F$5:$F$204,$F$29),SAISIE!$E$5:$E$204,0)),"-")) | D32: =IF(OR($F$29="",NOT(MAXIFS(SAISIE!$E$5:$E$204,SAISIE!$B$5:$B$204,"*Vent G/D*",SAISIE!$F$5:$F$204,$F$29)>0)),"",IFERROR(MAXIFS(SAISIE!$E$5:$E$204,SAISIE!$B$5:$B$204,"*Vent G/D*",SAISIE!$F$5:$F$204,$F$29),"-")) | E32: =IF($F$29="","",IF(OR(D32="",D32="-"),"",IF(D32>0,"(soulevement)",IF(D32<0,"(compression)","-")))) | I32: =IF(OR($M$29="",NOT(MAXIFS(SAISIE!$L$5:$L$204,SAISIE!$J$5:$J$204,"*Vent G/D*",SAISIE!$M$5:$M$204,$M$29)>0)),"","Vent G/D") | J32: =IF(OR($M$29="",NOT(MAXIFS(SAISIE!$L$5:$L$204,SAISIE!$J$5:$J$204,"*Vent G/D*",SAISIE!$M$5:$M$204,$M$29)>0)),"",IFERROR(INDEX(SAISIE!$K$5:$K$204,MATCH(MAXIFS(SAISIE!$L$5:$L$204,SAISIE!$J$5:$J$204,"*Vent G/D*",SAISIE!$M$5:$M$204,$M$29),SAISIE!$L$5:$L$204,0)),"-")) | K32: =IF(OR($M$29="",NOT(MAXIFS(SAISIE!$L$5:$L$204,SAISIE!$J$5:$J$204,"*Vent G/D*",SAISIE!$M$5:$M$204,$M$29)>0)),"",IFERROR(MAXIFS(SAISIE!$L$5:$L$204,SAISIE!$J$5:$J$204,"*Vent G/D*",SAISIE!$M$5:$M$204,$M$29),"-")) | L32: =IF($M$29="","",IF(OR(K32="",K32="-"),"",IF(K32>0,"(soulevement)",IF(K32<0,"(compression)","-"))))
A33: =IF(OR($F$29="",NOT(COUNTIFS(SAISIE!$B$5:$B$204,"*Vent D/G*",SAISIE!$F$5:$F$204,$F$29)>0)),"","Vent D/G") | B33: =IF(OR($F$29="",NOT(COUNTIFS(SAISIE!$B$5:$B$204,"*Vent D/G*",SAISIE!$F$5:$F$204,$F$29)>0)),"",IFERROR(IF(MINIFS(SAISIE!$E$5:$E$204,SAISIE!$B$5:$B$204,"*Vent D/G*",SAISIE!$F$5:$F$204,$F$29)>=0,MAXIFS(SAISIE!$C$5:$C$204,SAISIE!$B$5:$B$204,"*Vent D/G*",SAISIE!$F$5:$F$204,$F$29),INDEX(SAISIE!$C$5:$C$204,MATCH(MINIFS(SAISIE!$E$5:$E$204,SAISIE!$B$5:$B$204,"*Vent D/G*",SAISIE!$F$5:$F$204,$F$29),SAISIE!$E$5:$E$204,0))),"-")) | C33: =IF(OR($F$29="",NOT(COUNTIFS(SAISIE!$B$5:$B$204,"*Vent D/G*",SAISIE!$F$5:$F$204,$F$29)>0)),"",IFERROR(IF(MINIFS(SAISIE!$E$5:$E$204,SAISIE!$B$5:$B$204,"*Vent D/G*",SAISIE!$F$5:$F$204,$F$29)>=0,INDEX(SAISIE!$D$5:$D$204,MATCH(MAXIFS(SAISIE!$C$5:$C$204,SAISIE!$B$5:$B$204,"*Vent D/G*",SAISIE!$F$5:$F$204,$F$29),SAISIE!$C$5:$C$204,0)),INDEX(SAISIE!$D$5:$D$204,MATCH(MINIFS(SAISIE!$E$5:$E$204,SAISIE!$B$5:$B$204,"*Vent D/G*",SAISIE!$F$5:$F$204,$F$29),SAISIE!$E$5:$E$204,0))),"-")) | D33: =IF(OR($F$29="",NOT(COUNTIFS(SAISIE!$B$5:$B$204,"*Vent D/G*",SAISIE!$F$5:$F$204,$F$29)>0)),"",IFERROR(IF(MINIFS(SAISIE!$E$5:$E$204,SAISIE!$B$5:$B$204,"*Vent D/G*",SAISIE!$F$5:$F$204,$F$29)>=0,0,MINIFS(SAISIE!$E$5:$E$204,SAISIE!$B$5:$B$204,"*Vent D/G*",SAISIE!$F$5:$F$204,$F$29)),"-")) | E33: =IF($F$29="","",IF(OR(D33="",D33="-"),"",IF(D33>0,"(soulevement)",IF(D33<0,"(compression)","-")))) | I33: =IF(OR($M$29="",NOT(COUNTIFS(SAISIE!$J$5:$J$204,"*Vent D/G*",SAISIE!$M$5:$M$204,$M$29)>0)),"","Vent D/G") | J33: =IF(OR($M$29="",NOT(COUNTIFS(SAISIE!$J$5:$J$204,"*Vent D/G*",SAISIE!$M$5:$M$204,$M$29)>0)),"",IFERROR(IF(MINIFS(SAISIE!$L$5:$L$204,SAISIE!$J$5:$J$204,"*Vent D/G*",SAISIE!$M$5:$M$204,$M$29)>=0,MAXIFS(SAISIE!$K$5:$K$204,SAISIE!$J$5:$J$204,"*Vent D/G*",SAISIE!$M$5:$M$204,$M$29),INDEX(SAISIE!$K$5:$K$204,MATCH(MINIFS(SAISIE!$L$5:$L$204,SAISIE!$J$5:$J$204,"*Vent D/G*",SAISIE!$M$5:$M$204,$M$29),SAISIE!$L$5:$L$204,0))),"-")) | K33: =IF(OR($M$29="",NOT(COUNTIFS(SAISIE!$J$5:$J$204,"*Vent D/G*",SAISIE!$M$5:$M$204,$M$29)>0)),"",IFERROR(IF(MINIFS(SAISIE!$L$5:$L$204,SAISIE!$J$5:$J$204,"*Vent D/G*",SAISIE!$M$5:$M$204,$M$29)>=0,0,MINIFS(SAISIE!$L$5:$L$204,SAISIE!$J$5:$J$204,"*Vent D/G*",SAISIE!$M$5:$M$204,$M$29)),"-")) | L33: =IF($M$29="","",IF(OR(K33="",K33="-"),"",IF(K33>0,"(soulevement)",IF(K33<0,"(compression)","-"))))
A34: =IF(OR($F$29="",NOT(MAXIFS(SAISIE!$E$5:$E$204,SAISIE!$B$5:$B$204,"*Vent D/G*",SAISIE!$F$5:$F$204,$F$29)>0)),"","Vent D/G") | B34: =IF(OR($F$29="",NOT(MAXIFS(SAISIE!$E$5:$E$204,SAISIE!$B$5:$B$204,"*Vent D/G*",SAISIE!$F$5:$F$204,$F$29)>0)),"",IFERROR(INDEX(SAISIE!$C$5:$C$204,MATCH(MAXIFS(SAISIE!$E$5:$E$204,SAISIE!$B$5:$B$204,"*Vent D/G*",SAISIE!$F$5:$F$204,$F$29),SAISIE!$E$5:$E$204,0)),"-")) | C34: =IF(OR($F$29="",NOT(MAXIFS(SAISIE!$E$5:$E$204,SAISIE!$B$5:$B$204,"*Vent D/G*",SAISIE!$F$5:$F$204,$F$29)>0)),"",IFERROR(INDEX(SAISIE!$D$5:$D$204,MATCH(MAXIFS(SAISIE!$E$5:$E$204,SAISIE!$B$5:$B$204,"*Vent D/G*",SAISIE!$F$5:$F$204,$F$29),SAISIE!$E$5:$E$204,0)),"-")) | D34: =IF(OR($F$29="",NOT(MAXIFS(SAISIE!$E$5:$E$204,SAISIE!$B$5:$B$204,"*Vent D/G*",SAISIE!$F$5:$F$204,$F$29)>0)),"",IFERROR(MAXIFS(SAISIE!$E$5:$E$204,SAISIE!$B$5:$B$204,"*Vent D/G*",SAISIE!$F$5:$F$204,$F$29),"-")) | E34: =IF($F$29="","",IF(OR(D34="",D34="-"),"",IF(D34>0,"(soulevement)",IF(D34<0,"(compression)","-")))) | I34: =IF(OR($M$29="",NOT(MAXIFS(SAISIE!$L$5:$L$204,SAISIE!$J$5:$J$204,"*Vent D/G*",SAISIE!$M$5:$M$204,$M$29)>0)),"","Vent D/G") | J34: =IF(OR($M$29="",NOT(MAXIFS(SAISIE!$L$5:$L$204,SAISIE!$J$5:$J$204,"*Vent D/G*",SAISIE!$M$5:$M$204,$M$29)>0)),"",IFERROR(INDEX(SAISIE!$K$5:$K$204,MATCH(MAXIFS(SAISIE!$L$5:$L$204,SAISIE!$J$5:$J$204,"*Vent D/G*",SAISIE!$M$5:$M$204,$M$29),SAISIE!$L$5:$L$204,0)),"-")) | K34: =IF(OR($M$29="",NOT(MAXIFS(SAISIE!$L$5:$L$204,SAISIE!$J$5:$J$204,"*Vent D/G*",SAISIE!$M$5:$M$204,$M$29)>0)),"",IFERROR(MAXIFS(SAISIE!$L$5:$L$204,SAISIE!$J$5:$J$204,"*Vent D/G*",SAISIE!$M$5:$M$204,$M$29),"-")) | L34: =IF($M$29="","",IF(OR(K34="",K34="-"),"",IF(K34>0,"(soulevement)",IF(K34<0,"(compression)","-"))))
A35: =IF(OR($F$29="",NOT(COUNTIFS(SAISIE!$B$5:$B$204,"*Vent Av./Arr.*",SAISIE!$F$5:$F$204,$F$29)>0)),"","Vent Av./Arr.") | B35: =IF(OR($F$29="",NOT(COUNTIFS(SAISIE!$B$5:$B$204,"*Vent Av./Arr.*",SAISIE!$F$5:$F$204,$F$29)>0)),"",IFERROR(IF(MINIFS(SAISIE!$E$5:$E$204,SAISIE!$B$5:$B$204,"*Vent Av./Arr.*",SAISIE!$F$5:$F$204,$F$29)>=0,MAXIFS(SAISIE!$C$5:$C$204,SAISIE!$B$5:$B$204,"*Vent Av./Arr.*",SAISIE!$F$5:$F$204,$F$29),INDEX(SAISIE!$C$5:$C$204,MATCH(MINIFS(SAISIE!$E$5:$E$204,SAISIE!$B$5:$B$204,"*Vent Av./Arr.*",SAISIE!$F$5:$F$204,$F$29),SAISIE!$E$5:$E$204,0))),"-")) | C35: =IF(OR($F$29="",NOT(COUNTIFS(SAISIE!$B$5:$B$204,"*Vent Av./Arr.*",SAISIE!$F$5:$F$204,$F$29)>0)),"",IFERROR(IF(MINIFS(SAISIE!$E$5:$E$204,SAISIE!$B$5:$B$204,"*Vent Av./Arr.*",SAISIE!$F$5:$F$204,$F$29)>=0,INDEX(SAISIE!$D$5:$D$204,MATCH(MAXIFS(SAISIE!$C$5:$C$204,SAISIE!$B$5:$B$204,"*Vent Av./Arr.*",SAISIE!$F$5:$F$204,$F$29),SAISIE!$C$5:$C$204,0)),INDEX(SAISIE!$D$5:$D$204,MATCH(MINIFS(SAISIE!$E$5:$E$204,SAISIE!$B$5:$B$204,"*Vent Av./Arr.*",SAISIE!$F$5:$F$204,$F$29),SAISIE!$E$5:$E$204,0))),"-")) | D35: =IF(OR($F$29="",NOT(COUNTIFS(SAISIE!$B$5:$B$204,"*Vent Av./Arr.*",SAISIE!$F$5:$F$204,$F$29)>0)),"",IFERROR(IF(MINIFS(SAISIE!$E$5:$E$204,SAISIE!$B$5:$B$204,"*Vent Av./Arr.*",SAISIE!$F$5:$F$204,$F$29)>=0,0,MINIFS(SAISIE!$E$5:$E$204,SAISIE!$B$5:$B$204,"*Vent Av./Arr.*",SAISIE!$F$5:$F$204,$F$29)),"-")) | E35: =IF($F$29="","",IF(OR(D35="",D35="-"),"",IF(D35>0,"(soulevement)",IF(D35<0,"(compression)","-")))) | I35: =IF(OR($M$29="",NOT(COUNTIFS(SAISIE!$J$5:$J$204,"*Vent Av./Arr.*",SAISIE!$M$5:$M$204,$M$29)>0)),"","Vent Av./Arr.") | J35: =IF(OR($M$29="",NOT(COUNTIFS(SAISIE!$J$5:$J$204,"*Vent Av./Arr.*",SAISIE!$M$5:$M$204,$M$29)>0)),"",IFERROR(IF(MINIFS(SAISIE!$L$5:$L$204,SAISIE!$J$5:$J$204,"*Vent Av./Arr.*",SAISIE!$M$5:$M$204,$M$29)>=0,MAXIFS(SAISIE!$K$5:$K$204,SAISIE!$J$5:$J$204,"*Vent Av./Arr.*",SAISIE!$M$5:$M$204,$M$29),INDEX(SAISIE!$K$5:$K$204,MATCH(MINIFS(SAISIE!$L$5:$L$204,SAISIE!$J$5:$J$204,"*Vent Av./Arr.*",SAISIE!$M$5:$M$204,$M$29),SAISIE!$L$5:$L$204,0))),"-")) | K35: =IF(OR($M$29="",NOT(COUNTIFS(SAISIE!$J$5:$J$204,"*Vent Av./Arr.*",SAISIE!$M$5:$M$204,$M$29)>0)),"",IFERROR(IF(MINIFS(SAISIE!$L$5:$L$204,SAISIE!$J$5:$J$204,"*Vent Av./Arr.*",SAISIE!$M$5:$M$204,$M$29)>=0,0,MINIFS(SAISIE!$L$5:$L$204,SAISIE!$J$5:$J$204,"*Vent Av./Arr.*",SAISIE!$M$5:$M$204,$M$29)),"-")) | L35: =IF($M$29="","",IF(OR(K35="",K35="-"),"",IF(K35>0,"(soulevement)",IF(K35<0,"(compression)","-"))))
