Workbook

Sheet MODE EMPLOI
A1: DDC Calculateur — 2 tableaux (avec / sans FY)
A4: CHOISISSEZ le tableau qui correspond a votre export Robot :
A6: TABLEAU 1 (lignes 5-204) : avec FY — stabilite 3D (FX, FY, FZ)
A7: TABLEAU 2 (lignes 210-409): sans FY — FX et FZ seulement
A9: Collez vos donnees dans UN seul tableau (pas les deux).
A10: SYNTHESE : 2 zones miroir — resultats dans la zone correspondante.
A11: Note dynamique : FZ > 0 = soulèvement, FZ < 0 = compression.
A12: F9 pour forcer le recalcul si besoin. Excel 2019 ou 365 requis.

Sheet SAISIE
A1: SAISIE — Collez vos cas de charge
A2: Utilisez le tableau AVEC FY ou SANS FY selon votre DDC Robot.
A3: TABLEAU — AVEC FY
A4: Noeud_Cas | B4: Nom_cas | C4: FX_daN | D4: FY_daN | E4: FZ_daN | F4: Noeud
A5: 47/1 | B5: G : Couverture : PA 6 BS 10 PV15 | C5: -116 | D5: 7 | E5: -1285 | F5: =IF(A5="","",VALUE(LEFT(A5,FIND("/",A5&"/")-1)))
A6: 47/2 | B6: Vent G/D dep.(-) Portique 2 | C6: 905 | D6: 40 | E6: 1422 | F6: =IF(A6="","",VALUE(LEFT(A6,FIND("/",A6&"/")-1)))
A7: 47/3 | B7: Vent G/D sur.(+) Portique 2 | C7: 900 | D7: 32 | E7: 1444 | F7: =IF(A7="","",VALUE(LEFT(A7,FIND("/",A7&"/")-1)))
A8: 47/4 | B8: Vent D/G dep.(-) Cpe - Portique 2 | C8: -345 | D8: 5 | E8: 462 | F8: =IF(A8="","",VALUE(LEFT(A8,FIND("/",A8&"/")-1)))
A9: 47/5 | B9: Vent D/G dep.(-) Cpe + Portique 2 | C9: -513 | D9: -11 | E9: -281 | F9: =IF(A9="","",VALUE(LEFT(A9,FIND("/",A9&"/")-1)))
A10: 47/6 | B10: Vent D/G sur.(+) Cpe - Portique 2 | C10: -349 | D10: -2 | E10: 485 | F10: =IF(A10="","",VALUE(LEFT(A10,FIND("/",A10&"/")-1)))
A11: 47/7 | B11: Vent D/G sur.(+) Cpe + Portique 2 | C11: -518 | D11: -22 | E11: -258 | F11: =IF(A11="","",VALUE(LEFT(A11,FIND("/",A11&"/")-1)))
A12: 47/8 | B12: Vent Av./Arr. dep.(-) Portique 2 | C12: -241 | D12: 205 | E12: 815 | F12: =IF(A12="","",VALUE(LEFT(A12,FIND("/",A12&"/")-1)))
A13: 47/9 | B13: Vent Av./Arr. sur.(+) Portique 2 | C13: -198 | D13: 195 | E13: 598 | F13: =IF(A13="","",VALUE(LEFT(A13,FIND("/",A13&"/")-1)))
A14: 47/10 | B14: Vent Arr./Av. dep.(-) Portique 2 | C14: -105 | D14: 0 | E14: 400 | F14: =IF(A14="","",VALUE(LEFT(A14,FIND("/",A14&"/")-1)))
A15: 47/11 | B15: Vent Arr./Av. sur.(+) Portique 2 | C15: -37 | D15: -11 | E15: 56 | F15: =IF(A15="","",VALUE(LEFT(A15,FIND("/",A15&"/")-1)))
A16: 47/12 | B16: Neige cas I | C16: -113 | D16: 0 | E16: -1010 | F16: =IF(A16="","",VALUE(LEFT(A16,FIND("/",A16&"/")-1)))
... A18: 47/14 | B18: Neige accidentel | C18: -251 | D18: 0 | E18: -2244 | F18: =IF(A18="","",VALUE(LEFT(A18,FIND("/",A18&"/")-1)))
F19: =IF(A19="","",VALUE(LEFT(A19,FIND("/",A19&"/")-1)))
F20: =IF(A20="","",VALUE(LEFT(A20,FIND("/",A20&"/")-1)))
F21: =IF(A21="","",VALUE(LEFT(A21,FIND("/",A21&"/")-1)))
F22: =IF(A22="","",VALUE(LEFT(A22,FIND("/",A22&"/")-1)))
F23: =IF(A23="","",VALUE(LEFT(A23,FIND("/",A23&"/")-1)))
F24: =IF(A24="","",VALUE(LEFT(A24,FIND("/",A24&"/")-1)))
F25: =IF(A25="","",VALUE(LEFT(A25,FIND("/",A25&"/")-1)))
F26: =IF(A26="","",VALUE(LEFT(A26,FIND("/",A26&"/")-1)))
F27: =IF(A27="","",VALUE(LEFT(A27,FIND("/",A27&"/")-1)))
F28: =IF(A28="","",VALUE(LEFT(A28,FIND("/",A28&"/")-1)))
F29: =IF(A29="","",VALUE(LEFT(A29,FIND("/",A29&"/")-1)))
F30: =IF(A30="","",VALUE(LEFT(A30,FIND("/",A30&"/")-1)))
... F204: =IF(A204="","",VALUE(LEFT(A204,FIND("/",A204&"/")-1)))
A206: ↓ Ne pas remplir les deux tableaux — choisir celui qui correspond ↓
A207: TABLEAU — SANS FY
A209: Noeud_Cas | B209: Nom_cas | C209: FX_daN | D209: FZ_daN | E209: Noeud
E210: =IF(A210="","",VALUE(LEFT(A210,FIND("/",A210&"/")-1)))
E211: =IF(A211="","",VALUE(LEFT(A211,FIND("/",A211&"/")-1)))
E212: =IF(A212="","",VALUE(LEFT(A212,FIND("/",A212&"/")-1)))
E213: =IF(A213="","",VALUE(LEFT(A213,FIND("/",A213&"/")-1)))
E214: =IF(A214="","",VALUE(LEFT(A214,FIND("/",A214&"/")-1)))
E215: =IF(A215="","",VALUE(LEFT(A215,FIND("/",A215&"/")-1)))
E216: =IF(A216="","",VALUE(LEFT(A216,FIND("/",A216&"/")-1)))
...

Sheet SYNTHESE
A1: SYNTHESE — Calcul automatique
A2: ="Avec FY : "&COUNTA(SAISIE!$A$5:$A$204)&" cas | "&SUMPRODUCT(--(MOD(ROW($G$7:$G$246)-7,12)=0)*($G$7:$G$246<>""))&" noeud(s) || "&"Sans FY : "&COUNTA(SAISIE!$A$210:$A$409)&" cas | "&SUMPRODUCT(--(MOD(ROW($H$251:$H$490)-251,12)=0)*($H$251:$H$490<>""))&" noeud(s)"
A5: SYNTHESE — AVEC FY
A6: Nom du cas | B6: FX [daN] | C6: FY [daN] | D6: FZ [daN] | E6: Note
A7: =IF($G$7="","","Noeud "&$G$7) | G7: =IFERROR(INDEX(SAISIE!$F$5:$F$204,AGGREGATE(15,6,ROW(SAISIE!$F$5:$F$204)-ROW(SAISIE!$F$5)+1/(SAISIE!$F$5:$F$204<>"")/(COUNTIF($G$4:G6,SAISIE!$F$5:$F$204)=0),1)),"")
A8: =IF(OR($G$7="",NOT(TRUE)),"","Couverture") | B8: =IF($G$7="","",IFERROR(IFERROR(LOOKUP(2,1/((SAISIE!$F$5:$F$204=$G$7)*(LEFT(SAISIE!$B$5:$B$204,2)="G ")),SAISIE!$C$5:$C$204),LOOKUP(2,1/((SAISIE!$F$5:$F$204=$G$7)*(ISNUMBER(SEARCH("Couverture",SAISIE!$B$5:$B$204)))),SAISIE!$C$5:$C$204)),"-")) | C8: =IF($G$7="","",IFERROR(IFERROR(LOOKUP(2,1/((SAISIE!$F$5:$F$204=$G$7)*(LEFT(SAISIE!$B$5:$B$204,2)="G ")),SAISIE!$D$5:$D$204),LOOKUP(2,1/((SAISIE!$F$5:$F$204=$G$7)*(ISNUMBER(SEARCH("Couverture",SAISIE!$B$5:$B$204)))),SAISIE!$D$5:$D$204)),"-")) | D8: =IF($G$7="","",IFERROR(IFERROR(LOOKUP(2,1/((SAISIE!$F$5:$F$204=$G$7)*(LEFT(SAISIE!$B$5:$B$204,2)="G ")),SAISIE!$E$5:$E$204),LOOKUP(2,1/((SAISIE!$F$5:$F$204=$G$7)*(ISNUMBER(SEARCH("Couverture",SAISIE!$B$5:$B$204)))),SAISIE!$E$5:$E$204)),"-")) | E8: =IF($G$7="","",IF(OR(D8="",D8="-"),"",IF(D8>0,"(soulevement)",IF(D8<0,"(compression)","-"))))
A9: =IF(OR($G$7="",NOT(COUNTIFS(SAISIE!$B$5:$B$204,"*Vent G/D*",SAISIE!$F$5:$F$204,$G$7)>0)),"","Vent G/D") | B9: =IF(OR($G$7="",NOT(COUNTIFS(SAISIE!$B$5:$B$204,"*Vent G/D*",SAISIE!$F$5:$F$204,$G$7)>0)),"",IFERROR(IF(MINIFS(SAISIE!$E$5:$E$204,SAISIE!$B$5:$B$204,"*Vent G/D*",SAISIE!$F$5:$F$204,$G$7)>=0,MAXIFS(SAISIE!$C$5:$C$204,SAISIE!$B$5:$B$204,"*Vent G/D*",SAISIE!$F$5:$F$204,$G$7),INDEX(SAISIE!$C$5:$C$204,MATCH(MINIFS(SAISIE!$E$5:$E$204,SAISIE!$B$5:$B$204,"*Vent G/D*",SAISIE!$F$5:$F$204,$G$7),SAISIE!$E$5:$E$204,0))),"-")) | C9: =IF(OR($G$7="",NOT(COUNTIFS(SAISIE!$B$5:$B$204,"*Vent G/D*",SAISIE!$F$5:$F$204,$G$7)>0)),"",IFERROR(IF(MINIFS(SAISIE!$E$5:$E$204,SAISIE!$B$5:$B$204,"*Vent G/D*",SAISIE!$F$5:$F$204,$G$7)>=0,INDEX(SAISIE!$D$5:$D$204,MATCH(MAXIFS(SAISIE!$C$5:$C$204,SAISIE!$B$5:$B$204,"*Vent G/D*",SAISIE!$F$5:$F$204,$G$7),SAISIE!$C$5:$C$204,0)),INDEX(SAISIE!$D$5:$D$204,MATCH(MINIFS(SAISIE!$E$5:$E$204,SAISIE!$B$5:$B$204,"*Vent G/D*",SAISIE!$F$5:$F$204,$G$7),SAISIE!$E$5:$E$204,0))),"-")) | D9: =IF(OR($G$7="",NOT(COUNTIFS(SAISIE!$B$5:$B$204,"*Vent G/D*",SAISIE!$F$5:$F$204,$G$7)>0)),"",IFERROR(IF(MINIFS(SAISIE!$E$5:$E$204,SAISIE!$B$5:$B$204,"*Vent G/D*",SAISIE!$F$5:$F$204,$G$7)>=0,0,MINIFS(SAISIE!$E$5:$E$204,SAISIE!$B$5:$B$204,"*Vent G/D*",SAISIE!$F$5:$F$204,$G$7)),"-")) | E9: =IF($G$7="","",IF(OR(D9="",D9="-"),"",IF(D9>0,"(soulevement)",IF(D9<0,"(compression)","-"))))
A10: =IF(OR($G$7="",NOT(MAXIFS(SAISIE!$E$5:$E$204,SAISIE!$B$5:$B$204,"*Vent G/D*",SAISIE!$F$5:$F$204,$G$7)>0)),"","Vent G/D") | B10: =IF(OR($G$7="",NOT(MAXIFS(SAISIE!$E$5:$E$204,SAISIE!$B$5:$B$204,"*Vent G/D*",SAISIE!$F$5:$F$204,$G$7)>0)),"",IFERROR(INDEX(SAISIE!$C$5:$C$204,MATCH(MAXIFS(SAISIE!$E$5:$E$204,SAISIE!$B$5:$B$204,"*Vent G/D*",SAISIE!$F$5:$F$204,$G$7),SAISIE!$E$5:$E$204,0)),"-")) | C10: =IF(OR($G$7="",NOT(MAXIFS(SAISIE!$E$5:$E$204,SAISIE!$B$5:$B$204,"*Vent G/D*",SAISIE!$F$5:$F$204,$G$7)>0)),"",IFERROR(INDEX(SAISIE!$D$5:$D$204,MATCH(MAXIFS(SAISIE!$E$5:$E$204,SAISIE!$B$5:$B$204,"*Vent G/D*",SAISIE!$F$5:$F$204,$G$7),SAISIE!$E$5:$E$204,0)),"-")) | D10: =IF(OR($G$7="",NOT(MAXIFS(SAISIE!$E$5:$E$204,SAISIE!$B$5:$B$204,"*Vent G/D*",SAISIE!$F$5:$F$204,$G$7)>0)),"",IFERROR(MAXIFS(SAISIE!$E$5:$E$204,SAISIE!$B$5:$B$204,"*Vent G/D*",SAISIE!$F$5:$F$204,$G$7),"-")) | E10: =IF($G$7="","",IF(OR(D10="",D10="-"),"",IF(D10>0,"(soulevement)",IF(D10<0,"(compression)","-"))))
A11: =IF(OR($G$7="",NOT(COUNTIFS(SAISIE!$B$5:$B$204,"*Vent D/G*",SAISIE!$F$5:$F$204,$G$7)>0)),"","Vent D/G") | B11: =IF(OR($G$7="",NOT(COUNTIFS(SAISIE!$B$5:$B$204,"*Vent D/G*",SAISIE!$F$5:$F$204,$G$7)>0)),"",IFERROR(IF(MINIFS(SAISIE!$E$5:$E$204,SAISIE!$B$5:$B$204,"*Vent D/G*",SAISIE!$F$5:$F$204,$G$7)>=0,MAXIFS(SAISIE!$C$5:$C$204,SAISIE!$B$5:$B$204,"*Vent D/G*",SAISIE!$F$5:$F$204,$G$7),INDEX(SAISIE!$C$5:$C$204,MATCH(MINIFS(SAISIE!$E$5:$E$204,SAISIE!$B$5:$B$204,"*Vent D/G*",SAISIE!$F$5:$F$204,$G$7),SAISIE!$E$5:$E$204,0))),"-")) | C11: =IF(OR($G$7="",NOT(COUNTIFS(SAISIE!$B$5:$B$204,"*Vent D/G*",SAISIE!$F$5:$F$204,$G$7)>0)),"",IFERROR(IF(MINIFS(SAISIE!$E$5:$E$204,SAISIE!$B$5:$B$204,"*Vent D/G*",SAISIE!$F$5:$F$204,$G$7)>=0,INDEX(SAISIE!$D$5:$D$204,MATCH(MAXIFS(SAISIE!$C$5:$C$204,SAISIE!$B$5:$B$204,"*Vent D/G*",SAISIE!$F$5:$F$204,$G$7),SAISIE!$C$5:$C$204,0)),INDEX(SAISIE!$D$5:$D$204,MATCH(MINIFS(SAISIE!$E$5:$E$204,SAISIE!$B$5:$B$204,"*Vent D/G*",SAISIE!$F$5:$F$204,$G$7),SAISIE!$E$5:$E$204,0))),"-")) | D11: =IF(OR($G$7="",NOT(COUNTIFS(SAISIE!$B$5:$B$204,"*Vent D/G*",SAISIE!$F$5:$F$204,$G$7)>0)),"",IFERROR(IF(MINIFS(SAISIE!$E$5:$E$204,SAISIE!$B$5:$B$204,"*Vent D/G*",SAISIE!$F$5:$F$204,$G$7)>=0,0,MINIFS(SAISIE!$E$5:$E$204,SAISIE!$B$5:$B$204,"*Vent D/G*",SAISIE!$F$5:$F$204,$G$7)),"-")) | E11: =IF($G$7="","",IF(OR(D11="",D11="-"),"",IF(D11>0,"(soulevement)",IF(D11<0,"(compression)","-"))))
A12: =IF(OR($G$7="",NOT(MAXIFS(SAISIE!$E$5:$E$204,SAISIE!$B$5:$B$204,"*Vent D/G*",SAISIE!$F$5:$F$204,$G$7)>0)),"","Vent D/G") | B12: =IF(OR($G$7="",NOT(MAXIFS(SAISIE!$E$5:$E$204,SAISIE!$B$5:$B$204,"*Vent D/G*",SAISIE!$F$5:$F$204,$G$7)>0)),"",IFERROR(INDEX(SAISIE!$C$5:$C$204,MATCH(MAXIFS(SAISIE!$E$5:$E$204,SAISIE!$B$5:$B$204,"*Vent D/G*",SAISIE!$F$5:$F$204,$G$7),SAISIE!$E$5:$E$204,0)),"-")) | C12: =IF(OR($G$7="",NOT(MAXIFS(SAISIE!$E$5:$E$204,SAISIE!$B$5:$B$204,"*Vent D/G*",SAISIE!$F$5:$F$204,$G$7)>0)),"",IFERROR(INDEX(SAISIE!$D$5:$D$204,MATCH(MAXIFS(SAISIE!$E$5:$E$204,SAISIE!$B$5:$B$204,"*Vent D/G*",SAISIE!$F$5:$F$204,$G$7),SAISIE!$E$5:$E$204,0)),"-")) | D12: =IF(OR($G$7="",NOT(MAXIFS(SAISIE!$E$5:$E$204,SAISIE!$B$5:$B$204,"*Vent D/G*",SAISIE!$F$5:$F$204,$G$7)>0)),"",IFERROR(MAXIFS(SAISIE!$E$5:$E$204,SAISIE!$B$5:$B$204,"*Vent D/G*",SAISIE!$F$5:$F$204,$G$7),"-")) | E12: =IF($G$7="","",IF(OR(D12="",D12="-"),"",IF(D12>0,"(soulevement)",IF(D12<0,"(compression)","-"))))
A13: =IF(OR($G$7="",NOT(COUNTIFS(SAISIE!$B$5:$B$204,"*Vent Av./Arr.*",SAISIE!$F$5:$F$204,$G$7)>0)),"","Vent Av./Arr.") | B13: =IF(OR($G$7="",NOT(COUNTIFS(SAISIE!$B$5:$B$204,"*Vent Av./Arr.*",SAISIE!$F$5:$F$204,$G$7)>0)),"",IFERROR(IF(MINIFS(SAISIE!$E$5:$E$204,SAISIE!$B$5:$B$204,"*Vent Av./Arr.*",SAISIE!$F$5:$F$204,$G$7)>=0,MAXIFS(SAISIE!$C$5:$C$204,SAISIE!$B$5:$B$204,"*Vent Av./Arr.*",SAISIE!$F$5:$F$204,$G$7),INDEX(SAISIE!$C$5:$C$204,MATCH(MINIFS(SAISIE!$E$5:$E$204,SAISIE!$B$5:$B$204,"*Vent Av./Arr.*",SAISIE!$F$5:$F$204,$G$7),SAISIE!$E$5:$E$204,0))),"-")) | C13: =IF(OR($G$7="",NOT(COUNTIFS(SAISIE!$B$5:$B$204,"*Vent Av./Arr.*",SAISIE!$F$5:$F$204,$G$7)>0)),"",IFERROR(IF(MINIFS(SAISIE!$E$5:$E$204,SAISIE!$B$5:$B$204,"*Vent Av./Arr.*",SAISIE!$F$5:$F$204,$G$7)>=0,INDEX(SAISIE!$D$5:$D$204,MATCH(MAXIFS(SAISIE!$C$5:$C$204,SAISIE!$B$5:$B$204,"*Vent Av./Arr.*",SAISIE!$F$5:$F$204,$G$7),SAISIE!$C$5:$C$204,0)),INDEX(SAISIE!$D$5:$D$204,MATCH(MINIFS(SAISIE!$E$5:$E$204,SAISIE!$B$5:$B$204,"*Vent Av./Arr.*",SAISIE!$F$5:$F$204,$G$7),SAISIE!$E$5:$E$204,0))),"-")) | D13: =IF(OR($G$7="",NOT(COUNTIFS(SAISIE!$B$5:$B$204,"*Vent Av./Arr.*",SAISIE!$F$5:$F$204,$G$7)>0)),"",IFERROR(IF(MINIFS(SAISIE!$E$5:$E$204,SAISIE!$B$5:$B$204,"*Vent Av./Arr.*",SAISIE!$F$5:$F$204,$G$7)>=0,0,MINIFS(SAISIE!$E$5:$E$204,SAISIE!$B$5:$B$204,"*Vent Av./Arr.*",SAISIE!$F$5:$F$204,$G$7)),"-")) | E13: =IF($G$7="","",IF(OR(D13="",D13="-"),"",IF(D13>0,"(soulevement)",IF(D13<0,"(compression)","-"))))
A14: =IF(OR($G$7="",NOT(MAXIFS(SAISIE!$E$5:$E$204,SAISIE!$B$5:$B$204,"*Vent Av./Arr.*",SAISIE!$F$5:$F$204,$G$7)>0)),"","Vent Av./Arr.") | B14: =IF(OR($G$7="",NOT(MAXIFS(SAISIE!$E$5:$E$204,SAISIE!$B$5:$B$204,"*Vent Av./Arr.*",SAISIE!$F$5:$F$204,$G$7)>0)),"",IFERROR(INDEX(SAISIE!$C$5:$C$204,MATCH(MAXIFS(SAISIE!$E$5:$E$204,SAISIE!$B$5:$B$204,"*Vent Av./Arr.*",SAISIE!$F$5:$F$204,$G$7),SAISIE!$E$5:$E$204,0)),"-")) | C14: =IF(OR($G$7="",NOT(MAXIFS(SAISIE!$E$5:$E$204,SAISIE!$B$5:$B$204,"*Vent Av./Arr.*",SAISIE!$F$5:$F$204,$G$7)>0)),"",IFERROR(INDEX(SAISIE!$D$5:$D$204,MATCH(MAXIFS(SAISIE!$E$5:$E$204,SAISIE!$B$5:$B$204,"*Vent Av./Arr.*",SAISIE!$F$5:$F$204,$G$7),SAISIE!$E$5:$E$204,0)),"-")) | D14: =IF(OR($G$7="",NOT(MAXIFS(SAISIE!$E$5:$E$204,SAISIE!$B$5:$B$204,"*Vent Av./Arr.*",SAISIE!$F$5:$F$204,$G$7)>0)),"",IFERROR(MAXIFS(SAISIE!$E$5:$E$204,SAISIE!$B$5:$B$204,"*Vent Av./Arr.*",SAISIE!$F$5:$F$204,$G$7),"-")) | E14: =IF($G$7="","",IF(OR(D14="",D14="-"),"",IF(D14>0,"(soulevement)",IF(D14<0,"(compression)","-"))))
A15: =IF(OR($G$7="",NOT(COUNTIFS(SAISIE!$B$5:$B$204,"*Vent Arr./Av.*",SAISIE!$F$5:$F$204,$G$7)>0)),"","Vent Arr./Av.") | B15: =IF(OR($G$7="",NOT(COUNTIFS(SAISIE!$B$5:$B$204,"*Vent Arr./Av.*",SAISIE!$F$5:$F$204,$G$7)>0)),"",IFERROR(IF(MINIFS(SAISIE!$E$5:$E$204,SAISIE!$B$5:$B$204,"*Vent Arr./Av.*",SAISIE!$F$5:$F$204,$G$7)>=0,MAXIFS(SAISIE!$C$5:$C$204,SAISIE!$B$5:$B$204,"*Vent Arr./Av.*",SAISIE!$F$5:$F$204,$G$7),INDEX(SAISIE!$C$5:$C$204,MATCH(MINIFS(SAISIE!$E$5:$E$204,SAISIE!$B$5:$B$204,"*Vent Arr./Av.*",SAISIE!$F$5:$F$204,$G$7),SAISIE!$E$5:$E$204,0))),"-")) | C15: =IF(OR($G$7="",NOT(COUNTIFS(SAISIE!$B$5:$B$204,"*Vent Arr./Av.*",SAISIE!$F$5:$F$204,$G$7)>0)),"",IFERROR(IF(MINIFS(SAISIE!$E$5:$E$204,SAISIE!$B$5:$B$204,"*Vent Arr./Av.*",SAISIE!$F$5:$F$204,$G$7)>=0,INDEX(SAISIE!$D$5:$D$204,MATCH(MAXIFS(SAISIE!$C$5:$C$204,SAISIE!$B$5:$B$204,"*Vent Arr./Av.*",SAISIE!$F$5:$F$204,$G$7),SAISIE!$C$5:$C$204,0)),INDEX(SAISIE!$D$5:$D$204,MATCH(MINIFS(SAISIE!$E$5:$E$204,SAISIE!$B$5:$B$204,"*Vent Arr./Av.*",SAISIE!$F$5:$F$204,$G$7),SAISIE!$E$5:$E$204,0))),"-")) | D15: =IF(OR($G$7="",NOT(COUNTIFS(SAISIE!$B$5:$B$204,"*Vent Arr./Av.*",SAISIE!$F$5:$F$204,$G$7)>0)),"",IFERROR(IF(MINIFS(SAISIE!$E$5:$E$204,SAISIE!$B$5:$B$204,"*Vent Arr./Av.*",SAISIE!$F$5:$F$204,$G$7)>=0,0,MINIFS(SAISIE!$E$5:$E$204,SAISIE!$B$5:$B$204,"*Vent Arr./Av.*",SAISIE!$F$5:$F$204,$G$7)),"-")) | E15: =IF($G$7="","",IF(OR(D15="",D15="-"),"",IF(D15>0,"(soulevement)",IF(D15<0,"(compression)","-"))))
A16: =IF(OR($G$7="",NOT(MAXIFS(SAISIE!$E$5:$E$204,SAISIE!$B$5:$B$204,"*Vent Arr./Av.*",SAISIE!$F$5:$F$204,$G$7)>0)),"","Vent Arr./Av.") | B16: =IF(OR($G$7="",NOT(MAXIFS(SAISIE!$E$5:$E$204,SAISIE!$B$5:$B$204,"*Vent Arr./Av.*",SAISIE!$F$5:$F$204,$G$7)>0)),"",IFERROR(INDEX(SAISIE!$C$5:$C$204,MATCH(MAXIFS(SAISIE!$E$5:$E$204,SAISIE!$B$5:$B$204,"*Vent Arr./Av.*",SAISIE!$F$5:$F$204,$G$7),SAISIE!$E$5:$E$204,0)),"-")) | C16: =IF(OR($G$7="",NOT(MAXIFS(SAISIE!$E$5:$E$204,SAISIE!$B$5:$B$204,"*Vent Arr./Av.*",SAISIE!$F$5:$F$204,$G$7)>0)),"",IFERROR(INDEX(SAISIE!$D$5:$D$204,MATCH(MAXIFS(SAISIE!$E$5:$E$204,SAISIE!$B$5:$B$204,"*Vent Arr./Av.*",SAISIE!$F$5:$F$204,$G$7),SAISIE!$E$5:$E$204,0)),"-")) | D16: =IF(OR($G$7="",NOT(MAXIFS(SAISIE!$E$5:$E$204,SAISIE!$B$5:$B$204,"*Vent Arr./Av.*",SAISIE!$F$5:$F$204,$G$7)>0)),"",IFERROR(MAXIFS(SAISIE!$E$5:$E$204,SAISIE!$B$5:$B$204,"*Vent Arr./Av.*",SAISIE!$F$5:$F$204,$G$7),"-")) | E16: =IF($G$7="","",IF(OR(D16="",D16="-"),"",IF(D16>0,"(soulevement)",IF(D16<0,"(compression)","-"))))
A17: =IF(OR($G$7="",NOT(TRUE)),"","Neige normale") | B17: =IF($G$7="","",IFERROR(INDEX(SAISIE!$C$5:$C$204,MATCH(MINIFS(SAISIE!$E$5:$E$204,SAISIE!$B$5:$B$204,"*Neige*",SAISIE!$B$5:$B$204,"<>*accidentel*",SAISIE!$F$5:$F$204,$G$7),SAISIE!$E$5:$E$204,0)),"-")) | C17: =IF($G$7="","",IFERROR(INDEX(SAISIE!$D$5:$D$204,MATCH(MINIFS(SAISIE!$E$5:$E$204,SAISIE!$B$5:$B$204,"*Neige*",SAISIE!$B$5:$B$204,"<>*accidentel*",SAISIE!$F$5:$F$204,$G$7),SAISIE!$E$5:$E$204,0)),"-")) | D17: =IF($G$7="","",IFERROR(INDEX(SAISIE!$E$5:$E$204,MATCH(MINIFS(SAISIE!$E$5:$E$204,SAISIE!$B$5:$B$204,"*Neige*",SAISIE!$B$5:$B$204,"<>*accidentel*",SAISIE!$F$5:$F$204,$G$7),SAISIE!$E$5:$E$204,0)),"-")) | E17: =IF($G$7="","",IF(OR(D17="",D17="-"),"",IF(D17>0,"(soulevement)",IF(D17<0,"(compression)","-"))))
A18: =IF(OR($G$7="",NOT(TRUE)),"","Neige accidentelle") | B18: =IF($G$7="","",IFERROR(LOOKUP(2,1/((SAISIE!$F$5:$F$204=$G$7)*(ISNUMBER(SEARCH("accidentel",SAISIE!$B$5:$B$204)))),SAISIE!$C$5:$C$204),"-")) | C18: =IF($G$7="","",IFERROR(LOOKUP(2,1/((SAISIE!$F$5:$F$204=$G$7)*(ISNUMBER(SEARCH("accidentel",SAISIE!$B$5:$B$204)))),SAISIE!$D$5:$D$204),"-")) | D18: =IF($G$7="","",IFERROR(LOOKUP(2,1/((SAISIE!$F$5:$F$204=$G$7)*(ISNUMBER(SEARCH("accidentel",SAISIE!$B$5:$B$204)))),SAISIE!$E$5:$E$204),"-")) | E18: =IF($G$7="","",IF(OR(D18="",D18="-"),"",IF(D18>0,"(soulevement)",IF(D18<0,"(compression)","-"))))
A19: =IF($G$19="","","Noeud "&$G$19) | G19: =IFERROR(INDEX(SAISIE!$F$5:$F$204,AGGREGATE(15,6,ROW(SAISIE!$F$5:$F$204)-ROW(SAISIE!$F$5)+1/(SAISIE!$F$5:$F$204<>"")/(COUNTIF($G$4:G18,SAISIE!$F$5:$F$204)=0),1)),"")
A20: =IF(OR($G$19="",NOT(TRUE)),"","Couverture") | B20: =IF($G$19="","",IFERROR(IFERROR(LOOKUP(2,1/((SAISIE!$F$5:$F$204=$G$19)*(LEFT(SAISIE!$B$5:$B$204,2)="G ")),SAISIE!$C$5:$C$204),LOOKUP(2,1/((SAISIE!$F$5:$F$204=$G$19)*(ISNUMBER(SEARCH("Couverture",SAISIE!$B$5:$B$204)))),SAISIE!$C$5:$C$204)),"-")) | C20: =IF($G$19="","",IFERROR(IFERROR(LOOKUP(2,1/((SAISIE!$F$5:$F$204=$G$19)*(LEFT(SAISIE!$B$5:$B$204,2)="G ")),SAISIE!$D$5:$D$204),LOOKUP(2,1/((SAISIE!$F$5:$F$204=$G$19)*(ISNUMBER(SEARCH("Couverture",SAISIE!$B$5:$B$204)))),SAISIE!$D$5:$D$204)),"-")) | D20: =IF($G$19="","",IFERROR(IFERROR(LOOKUP(2,1/((SAISIE!$F$5:$F$204=$G$19)*(LEFT(SAISIE!$B$5:$B$204,2)="G ")),SAISIE!$E$5:$E$204),LOOKUP(2,1/((SAISIE!$F$5:$F$204=$G$19)*(ISNUMBER(SEARCH("Couverture",SAISIE!$B$5:$B$204)))),SAISIE!$E$5:$E$204)),"-")) | E20: =IF($G$19="","",IF(OR(D20="",D20="-"),"",IF(D20>0,"(soulevement)",IF(D20<0,"(compression)","-"))))
A21: =IF(OR($G$19="",NOT(COUNTIFS(SAISIE!$B$5:$B$204,"*Vent G/D*",SAISIE!$F$5:$F$204,$G$19)>0)),"","Vent G/D") | B21: =IF(OR($G$19="",NOT(COUNTIFS(SAISIE!$B$5:$B$204,"*Vent G/D*",SAISIE!$F$5:$F$204,$G$19)>0)),"",IFERROR(IF(MINIFS(SAISIE!$E$5:$E$204,SAISIE!$B$5:$B$204,"*Vent G/D*",SAISIE!$F$5:$F$204,$G$19)>=0,MAXIFS(SAISIE!$C$5:$C$204,SAISIE!$B$5:$B$204,"*Vent G/D*",SAISIE!$F$5:$F$204,$G$19),INDEX(SAISIE!$C$5:$C$204,MATCH(MINIFS(SAISIE!$E$5:$E$204,SAISIE!$B$5:$B$204,"*Vent G/D*",SAISIE!$F$5:$F$204,$G$19),SAISIE!$E$5:$E$204,0))),"-")) | C21: =IF(OR($G$19="",NOT(COUNTIFS(SAISIE!$B$5:$B$204,"*Vent G/D*",SAISIE!$F$5:$F$204,$G$19)>0)),"",IFERROR(IF(MINIFS(SAISIE!$E$5:$E$204,SAISIE!$B$5:$B$204,"*Vent G/D*",SAISIE!$F$5:$F$204,$G$19)>=0,INDEX(SAISIE!$D$5:$D$204,MATCH(MAXIFS(SAISIE!$C$5:$C$204,SAISIE!$B$5:$B$204,"*Vent G/D*",SAISIE!$F$5:$F$204,$G$19),SAISIE!$C$5:$C$204,0)),INDEX(SAISIE!$D$5:$D$204,MATCH(MINIFS(SAISIE!$E$5:$E$204,SAISIE!$B$5:$B$204,"*Vent G/D*",SAISIE!$F$5:$F$204,$G$19),SAISIE!$E$5:$E$204,0))),"-")) | D21: =IF(OR($G$19="",NOT(COUNTIFS(SAISIE!$B$5:$B$204,"*Vent G/D*",SAISIE!$F$5:$F$204,$G$19)>0)),"",IFERROR(IF(MINIFS(SAISIE!$E$5:$E$204,SAISIE!$B$5:$B$204,"*Vent G/D*",SAISIE!$F$5:$F$204,$G$19)>=0,0,MINIFS(SAISIE!$E$5:$E$204,SAISIE!$B$5:$B$204,"*Vent G/D*",SAISIE!$F$5:$F$204,$G$19)),"-")) | E21: =IF($G$19="","",IF(OR(D21="",D21="-"),"",IF(D21>0,"(soulevement)",IF(D21<0,"(compression)","-"))))
A22: =IF(OR($G$19="",NOT(MAXIFS(SAISIE!$E$5:$E$204,SAISIE!$B$5:$B$204,"*Vent G/D*",SAISIE!$F$5:$F$204,$G$19)>0)),"","Vent G/D") | B22: =IF(OR($G$19="",NOT(MAXIFS(SAISIE!$E$5:$E$204,SAISIE!$B$5:$B$204,"*Vent G/D*",SAISIE!$F$5:$F$204,$G$19)>0)),"",IFERROR(INDEX(SAISIE!$C$5:$C$204,MATCH(MAXIFS(SAISIE!$E$5:$E$204,SAISIE!$B$5:$B$204,"*Vent G/D*",SAISIE!$F$5:$F$204,$G$19),SAISIE!$E$5:$E$204,0)),"-")) | C22: =IF(OR($G$19="",NOT(MAXIFS(SAISIE!$E$5:$E$204,SAISIE!$B$5:$B$204,"*Vent G/D*",SAISIE!$F$5:$F$204,$G$19)>0)),"",IFERROR(INDEX(SAISIE!$D$5:$D$204,MATCH(MAXIFS(SAISIE!$E$5:$E$204,SAISIE!$B$5:$B$204,"*Vent G/D*",SAISIE!$F$5:$F$204,$G$19),SAISIE!$E$5:$E$204,0)),"-")) | D22: =IF(OR($G$19="",NOT(MAXIFS(SAISIE!$E$5:$E$204,SAISIE!$B$5:$B$204,"*Vent G/D*",SAISIE!$F$5:$F$204,$G$19)>0)),"",IFERROR(MAXIFS(SAISIE!$E$5:$E$204,SAISIE!$B$5:$B$204,"*Vent G/D*",SAISIE!$F$5:$F$204,$G$19),"-")) | E22: =IF($G$19="","",IF(OR(D22="",D22="-"),"",IF(D22>0,"(soulevement)",IF(D22<0,"(compression)","-"))))
A23: =IF(OR($G$19="",NOT(COUNTIFS(SAISIE!$B$5:$B$204,"*Vent D/G*",SAISIE!$F$5:$F$204,$G$19)>0)),"","Vent D/G") | B23: =IF(OR($G$19="",NOT(COUNTIFS(SAISIE!$B$5:$B$204,"*Vent D/G*",SAISIE!$F$5:$F$204,$G$19)>0)),"",IFERROR(IF(MINIFS(SAISIE!$E$5:$E$204,SAISIE!$B$5:$B$204,"*Vent D/G*",SAISIE!$F$5:$F$204,$G$19)>=0,MAXIFS(SAISIE!$C$5:$C$204,SAISIE!$B$5:$B$204,"*Vent D/G*",SAISIE!$F$5:$F$204,$G$19),INDEX(SAISIE!$C$5:$C$204,MATCH(MINIFS(SAISIE!$E$5:$E$204,SAISIE!$B$5:$B$204,"*Vent D/G*",SAISIE!$F$5:$F$204,$G$19),SAISIE!$E$5:$E$204,0))),"-")) | C23: =IF(OR($G$19="",NOT(COUNTIFS(SAISIE!$B$5:$B$204,"*Vent D/G*",SAISIE!$F$5:$F$204,$G$19)>0)),"",IFERROR(IF(MINIFS(SAISIE!$E$5:$E$204,SAISIE!$B$5:$B$204,"*Vent D/G*",SAISIE!$F$5:$F$204,$G$19)>=0,INDEX(SAISIE!$D$5:$D$204,MATCH(MAXIFS(SAISIE!$C$5:$C$204,SAISIE!$B$5:$B$204,"*Vent D/G*",SAISIE!$F$5:$F$204,$G$19),SAISIE!$C$5:$C$204,0)),INDEX(SAISIE!$D$5:$D$204,MATCH(MINIFS(SAISIE!$E$5:$E$204,SAISIE!$B$5:$B$204,"*Vent D/G*",SAISIE!$F$5:$F$204,$G$19),SAISIE!$E$5:$E$204,0))),"-")) | D23: =IF(OR($G$19="",NOT(COUNTIFS(SAISIE!$B$5:$B$204,"*Vent D/G*",SAISIE!$F$5:$F$204,$G$19)>0)),"",IFERROR(IF(MINIFS(SAISIE!$E$5:$E$204,SAISIE!$B$5:$B$204,"*Vent D/G*",SAISIE!$F$5:$F$204,$G$19)>=0,0,MINIFS(SAISIE!$E$5:$E$204,SAISIE!$B$5:$B$204,"*Vent D/G*",SAISIE!$F$5:$F$204,$G$19)),"-")) | E23: =IF($G$19="","",IF(OR(D23="",D23="-"),"",IF(D23>0,"(soulevement)",IF(D23<0,"(compression)","-"))))
A24: =IF(OR($G$19="",NOT(MAXIFS(SAISIE!$E$5:$E$204,SAISIE!$B$5:$B$204,"*Vent D/G*",SAISIE!$F$5:$F$204,$G$19)>0)),"","Vent D/G") | B24: =IF(OR($G$19="",NOT(MAXIFS(SAISIE!$E$5:$E$204,SAISIE!$B$5:$B$204,"*Vent D/G*",SAISIE!$F$5:$F$204,$G$19)>0)),"",IFERROR(INDEX(SAISIE!$C$5:$C$204,MATCH(MAXIFS(SAISIE!$E$5:$E$204,SAISIE!$B$5:$B$204,"*Vent D/G*",SAISIE!$F$5:$F$204,$G$19),SAISIE!$E$5:$E$204,0)),"-")) | C24: =IF(OR($G$19="",NOT(MAXIFS(SAISIE!$E$5:$E$204,SAISIE!$B$5:$B$204,"*Vent D/G*",SAISIE!$F$5:$F$204,$G$19)>0)),"",IFERROR(INDEX(SAISIE!$D$5:$D$204,MATCH(MAXIFS(SAISIE!$E$5:$E$204,SAISIE!$B$5:$B$204,"*Vent D/G*",SAISIE!$F$5:$F$204,$G$19),SAISIE!$E$5:$E$204,0)),"-")) | D24: =IF(OR($G$19="",NOT(MAXIFS(SAISIE!$E$5:$E$204,SAISIE!$B$5:$B$204,"*Vent D/G*",SAISIE!$F$5:$F$204,$G$19)>0)),"",IFERROR(MAXIFS(SAISIE!$E$5:$E$204,SAISIE!$B$5:$B$204,"*Vent D/G*",SAISIE!$F$5:$F$204,$G$19),"-")) | E24: =IF($G$19="","",IF(OR(D24="",D24="-"),"",IF(D24>0,"(soulevement)",IF(D24<0,"(compression)","-"))))
A25: =IF(OR($G$19="",NOT(COUNTIFS(SAISIE!$B$5:$B$204,"*Vent Av./Arr.*",SAISIE!$F$5:$F$204,$G$19)>0)),"","Vent Av./Arr.") | B25: =IF(OR($G$19="",NOT(COUNTIFS(SAISIE!$B$5:$B$204,"*Vent Av./Arr.*",SAISIE!$F$5:$F$204,$G$19)>0)),"",IFERROR(IF(MINIFS(SAISIE!$E$5:$E$204,SAISIE!$B$5:$B$204,"*Vent Av./Arr.*",SAISIE!$F$5:$F$204,$G$19)>=0,MAXIFS(SAISIE!$C$5:$C$204,SAISIE!$B$5:$B$204,"*Vent Av./Arr.*",SAISIE!$F$5:$F$204,$G$19),INDEX(SAISIE!$C$5:$C$204,MATCH(MINIFS(SAISIE!$E$5:$E$204,SAISIE!$B$5:$B$204,"*Vent Av./Arr.*",SAISIE!$F$5:$F$204,$G$19),SAISIE!$E$5:$E$204,0))),"-")) | C25: =IF(OR($G$19="",NOT(COUNTIFS(SAISIE!$B$5:$B$204,"*Vent Av./Arr.*",SAISIE!$F$5:$F$204,$G$19)>0)),"",IFERROR(IF(MINIFS(SAISIE!$E$5:$E$204,SAISIE!$B$5:$B$204,"*Vent Av./Arr.*",SAISIE!$F$5:$F$204,$G$19)>=0,INDEX(SAISIE!$D$5:$D$204,MATCH(MAXIFS(SAISIE!$C$5:$C$204,SAISIE!$B$5:$B$204,"*Vent Av./Arr.*",SAISIE!$F$5:$F$204,$G$19),SAISIE!$C$5:$C$204,0)),INDEX(SAISIE!$D$5:$D$204,MATCH(MINIFS(SAISIE!$E$5:$E$204,SAISIE!$B$5:$B$204,"*Vent Av./Arr.*",SAISIE!$F$5:$F$204,$G$19),SAISIE!$E$5:$E$204,0))),"-")) | D25: =IF(OR($G$19="",NOT(COUNTIFS(SAISIE!$B$5:$B$204,"*Vent Av./Arr.*",SAISIE!$F$5:$F$204,$G$19)>0)),"",IFERROR(IF(MINIFS(SAISIE!$E$5:$E$204,SAISIE!$B$5:$B$204,"*Vent Av./Arr.*",SAISIE!$F$5:$F$204,$G$19)>=0,0,MINIFS(SAISIE!$E$5:$E$204,SAISIE!$B$5:$B$204,"*Vent Av./Arr.*",SAISIE!$F$5:$F$204,$G$19)),"-")) | E25: =IF($G$19="","",IF(OR(D25="",D25="-"),"",IF(D25>0,"(soulevement)",IF(D25<0,"(compression)","-"))))
A26: =IF(OR($G$19="",NOT(MAXIFS(SAISIE!$E$5:$E$204,SAISIE!$B$5:$B$204,"*Vent Av./Arr.*",SAISIE!$F$5:$F$204,$G$19)>0)),"","Vent Av./Arr.") | B26: =IF(OR($G$19="",NOT(MAXIFS(SAISIE!$E$5:$E$204,SAISIE!$B$5:$B$204,"*Vent Av./Arr.*",SAISIE!$F$5:$F$204,$G$19)>0)),"",IFERROR(INDEX(SAISIE!$C$5:$C$204,MATCH(MAXIFS(SAISIE!$E$5:$E$204,SAISIE!$B$5:$B$204,"*Vent Av./Arr.*",SAISIE!$F$5:$F$204,$G$19),SAISIE!$E$5:$E$204,0)),"-")) | C26: =IF(OR($G$19="",NOT(MAXIFS(SAISIE!$E$5:$E$204,SAISIE!$B$5:$B$204,"*Vent Av./Arr.*",SAISIE!$F$5:$F$204,$G$19)>0)),"",IFERROR(INDEX(SAISIE!$D$5:$D$204,MATCH(MAXIFS(SAISIE!$E$5:$E$204,SAISIE!$B$5:$B$204,"*Vent Av./Arr.*",SAISIE!$F$5:$F$204,$G$19),SAISIE!$E$5:$E$204,0)),"-")) | D26: =IF(OR($G$19="",NOT(MAXIFS(SAISIE!$E$5:$E$204,SAISIE!$B$5:$B$204,"*Vent Av./Arr.*",SAISIE!$F$5:$F$204,$G$19)>0)),"",IFERROR(MAXIFS(SAISIE!$E$5:$E$204,SAISIE!$B$5:$B$204,"*Vent Av./Arr.*",SAISIE!$F$5:$F$204,$G$19),"-")) | E26: =IF($G$19="","",IF(OR(D26="",D26="-"),"",IF(D26>0,"(soulevement)",IF(D26<0,"(compression)","-"))))
A27: =IF(OR($G$19="",NOT(COUNTIFS(SAISIE!$B$5:$B$204,"*Vent Arr./Av.*",SAISIE!$F$5:$F$204,$G$19)>0)),"","Vent Arr./Av.") | B27: =IF(OR($G$19="",NOT(COUNTIFS(SAISIE!$B$5:$B$204,"*Vent Arr./Av.*",SAISIE!$F$5:$F$204,$G$19)>0)),"",IFERROR(IF(MINIFS(SAISIE!$E$5:$E$204,SAISIE!$B$5:$B$204,"*Vent Arr./Av.*",SAISIE!$F$5:$F$204,$G$19)>=0,MAXIFS(SAISIE!$C$5:$C$204,SAISIE!$B$5:$B$204,"*Vent Arr./Av.*",SAISIE!$F$5:$F$204,$G$19),INDEX(SAISIE!$C$5:$C$204,MATCH(MINIFS(SAISIE!$E$5:$E$204,SAISIE!$B$5:$B$204,"*Vent Arr./Av.*",SAISIE!$F$5:$F$204,$G$19),SAISIE!$E$5:$E$204,0))),"-")) | C27: =IF(OR($G$19="",NOT(COUNTIFS(SAISIE!$B$5:$B$204,"*Vent Arr./Av.*",SAISIE!$F$5:$F$204,$G$19)>0)),"",IFERROR(IF(MINIFS(SAISIE!$E$5:$E$204,SAISIE!$B$5:$B$204,"*Vent Arr./Av.*",SAISIE!$F$5:$F$204,$G$19)>=0,INDEX(SAISIE!$D$5:$D$204,MATCH(MAXIFS(SAISIE!$C$5:$C$204,SAISIE!$B$5:$B$204,"*Vent Arr./Av.*",SAISIE!$F$5:$F$204,$G$19),SAISIE!$C$5:$C$204,0)),INDEX(SAISIE!$D$5:$D$204,MATCH(MINIFS(SAISIE!$E$5:$E$204,SAISIE!$B$5:$B$204,"*Vent Arr./Av.*",SAISIE!$F$5:$F$204,$G$19),SAISIE!$E$5:$E$204,0))),"-")) | D27: =IF(OR($G$19="",NOT(COUNTIFS(SAISIE!$B$5:$B$204,"*Vent Arr./Av.*",SAISIE!$F$5:$F$204,$G$19)>0)),"",IFERROR(IF(MINIFS(SAISIE!$E$5:$E$204,SAISIE!$B$5:$B$204,"*Vent Arr./Av.*",SAISIE!$F$5:$F$204,$G$19)>=0,0,MINIFS(SAISIE!$E$5:$E$204,SAISIE!$B$5:$B$204,"*Vent Arr./Av.*",SAISIE!$F$5:$F$204,$G$19)),"-")) | E27: =IF($G$19="","",IF(OR(D27="",D27="-"),"",IF(D27>0,"(soulevement)",IF(D27<0,"(compression)","-"))))
A28: =IF(OR($G$19="",NOT(MAXIFS(SAISIE!$E$5:$E$204,SAISIE!$B$5:$B$204,"*Vent Arr./Av.*",SAISIE!$F$5:$F$204,$G$19)>0)),"","Vent Arr./Av.") | B28: =IF(OR($G$19="",NOT(MAXIFS(SAISIE!$E$5:$E$204,SAISIE!$B$5:$B$204,"*Vent Arr./Av.*",SAISIE!$F$5:$F$204,$G$19)>0)),"",IFERROR(INDEX(SAISIE!$C$5:$C$204,MATCH(MAXIFS(SAISIE!$E$5:$E$204,SAISIE!$B$5:$B$204,"*Vent Arr./Av.*",SAISIE!$F$5:$F$204,$G$19),SAISIE!$E$5:$E$204,0)),"-")) | C28: =IF(OR($G$19="",NOT(MAXIFS(SAISIE!$E$5:$E$204,SAISIE!$B$5:$B$204,"*Vent Arr./Av.*",SAISIE!$F$5:$F$204,$G$19)>0)),"",IFERROR(INDEX(SAISIE!$D$5:$D$204,MATCH(MAXIFS(SAISIE!$E$5:$E$204,SAISIE!$B$5:$B$204,"*Vent Arr./Av.*",SAISIE!$F$5:$F$204,$G$19),SAISIE!$E$5:$E$204,0)),"-")) | D28: =IF(OR($G$19="",NOT(MAXIFS(SAISIE!$E$5:$E$204,SAISIE!$B$5:$B$204,"*Vent Arr./Av.*",SAISIE!$F$5:$F$204,$G$19)>0)),"",IFERROR(MAXIFS(SAISIE!$E$5:$E$204,SAISIE!$B$5:$B$204,"*Vent Arr./Av.*",SAISIE!$F$5:$F$204,$G$19),"-")) | E28: =IF($G$19="","",IF(OR(D28="",D28="-"),"",IF(D28>0,"(soulevement)",IF(D28<0,"(compression)","-"))))
A29: =IF(OR($G$19="",NOT(TRUE)),"","Neige normale") | B29: =IF($G$19="","",IFERROR(INDEX(SAISIE!$C$5:$C$204,MATCH(MINIFS(SAISIE!$E$5:$E$204,SAISIE!$B$5:$B$204,"*Neige*",SAISIE!$B$5:$B$204,"<>*accidentel*",SAISIE!$F$5:$F$204,$G$19),SAISIE!$E$5:$E$204,0)),"-")) | C29: =IF($G$19="","",IFERROR(INDEX(SAISIE!$D$5:$D$204,MATCH(MINIFS(SAISIE!$E$5:$E$204,SAISIE!$B$5:$B$204,"*Neige*",SAISIE!$B$5:$B$204,"<>*accidentel*",SAISIE!$F$5:$F$204,$G$19),SAISIE!$E$5:$E$204,0)),"-")) | D29: =IF($G$19="","",IFERROR(INDEX(SAISIE!$E$5:$E$204,MATCH(MINIFS(SAISIE!$E$5:$E$204,SAISIE!$B$5:$B$204,"*Neige*",SAISIE!$B$5:$B$204,"<>*accidentel*",SAISIE!$F$5:$F$204,$G$19),SAISIE!$E$5:$E$204,0)),"-")) | E29: =IF($G$19="","",IF(OR(D29="",D29="-"),"",IF(D29>0,"(soulevement)",IF(D29<0,"(compression)","-"))))
A30: =IF(OR($G$19="",NOT(TRUE)),"","Neige accidentelle") | B30: =IF($G$19="","",IFERROR(LOOKUP(2,1/((SAISIE!$F$5:$F$204=$G$19)*(ISNUMBER(SEARCH("accidentel",SAISIE!$B$5:$B$204)))),SAISIE!$C$5:$C$204),"-")) | C30: =IF($G$19="","",IFERROR(LOOKUP(2,1/((SAISIE!$F$5:$F$204=$G$19)*(ISNUMBER(SEARCH("accidentel",SAISIE!$B$5:$B$204)))),SAISIE!$D$5:$D$204),"-")) | D30: =IF($G$19="","",IFERROR(LOOKUP(2,1/((SAISIE!$F$5:$F$204=$G$19)*(ISNUMBER(SEARCH("accidentel",SAISIE!$B$5:$B$204)))),SAISIE!$E$5:$E$204),"-")) | E30: =IF($G$19="","",IF(OR(D30="",D30="-"),"",IF(D30>0,"(soulevement)",IF(D30<0,"(compression)","-"))))
A31: =IF($G$31="","","Noeud "&$G$31) | G31: =IFERROR(INDEX(SAISIE!$F$5:$F$204,AGGREGATE(15,6,ROW(SAISIE!$F$5:$F$204)-ROW(SAISIE!$F$5)+1/(SAISIE!$F$5:$F$204<>"")/(COUNTIF($G$4:G30,SAISIE!$F$5:$F$204)=0),1)),"")
A32: =IF(OR($G$31="",NOT(TRUE)),"","Couverture") | B32: =IF($G$31="","",IFERROR(IFERROR(LOOKUP(2,1/((SAISIE!$F$5:$F$204=$G$31)*(LEFT(SAISIE!$B$5:$B$204,2)="G ")),SAISIE!$C$5:$C$204),LOOKUP(2,1/((SAISIE!$F$5:$F$204=$G$31)*(ISNUMBER(SEARCH("Couverture",SAISIE!$B$5:$B$204)))),SAISIE!$C$5:$C$204)),"-")) | C32: =IF($G$31="","",IFERROR(IFERROR(LOOKUP(2,1/((SAISIE!$F$5:$F$204=$G$31)*(LEFT(SAISIE!$B$5:$B$204,2)="G ")),SAISIE!$D$5:$D$204),LOOKUP(2,1/((SAISIE!$F$5:$F$204=$G$31)*(ISNUMBER(SEARCH("Couverture",SAISIE!$B$5:$B$204)))),SAISIE!$D$5:$D$204)),"-")) | D32: =IF($G$31="","",IFERROR(IFERROR(LOOKUP(2,1/((SAISIE!$F$5:$F$204=$G$31)*(LEFT(SAISIE!$B$5:$B$204,2)="G ")),SAISIE!$E$5:$E$204),LOOKUP(2,1/((SAISIE!$F$5:$F$204=$G$31)*(ISNUMBER(SEARCH("Couverture",SAISIE!$B$5:$B$204)))),SAISIE!$E$5:$E$204)),"-")) | E32: =IF($G$31="","",IF(OR(D32="",D32="-"),"",IF(D32>0,"(soulevement)",IF(D32<0,"(compression)","-"))))
A33: =IF(OR($G$31="",NOT(COUNTIFS(SAISIE!$B$5:$B$204,"*Vent G/D*",SAISIE!$F$5:$F$204,$G$31)>0)),"","Vent G/D") | B33: =IF(OR($G$31="",NOT(COUNTIFS(SAISIE!$B$5:$B$204,"*Vent G/D*",SAISIE!$F$5:$F$204,$G$31)>0)),"",IFERROR(IF(MINIFS(SAISIE!$E$5:$E$204,SAISIE!$B$5:$B$204,"*Vent G/D*",SAISIE!$F$5:$F$204,$G$31)>=0,MAXIFS(SAISIE!$C$5:$C$204,SAISIE!$B$5:$B$204,"*Vent G/D*",SAISIE!$F$5:$F$204,$G$31),INDEX(SAISIE!$C$5:$C$204,MATCH(MINIFS(SAISIE!$E$5:$E$204,SAISIE!$B$5:$B$204,"*Vent G/D*",SAISIE!$F$5:$F$204,$G$31),SAISIE!$E$5:$E$204,0))),"-")) | C33: =IF(OR($G$31="",NOT(COUNTIFS(SAISIE!$B$5:$B$204,"*Vent G/D*",SAISIE!$F$5:$F$204,$G$31)>0)),"",IFERROR(IF(MINIFS(SAISIE!$E$5:$E$204,SAISIE!$B$5:$B$204,"*Vent G/D*",SAISIE!$F$5:$F$204,$G$31)>=0,INDEX(SAISIE!$D$5:$D$204,MATCH(MAXIFS(SAISIE!$C$5:$C$204,SAISIE!$B$5:$B$204,"*Vent G/D*",SAISIE!$F$5:$F$204,$G$31),SAISIE!$C$5:$C$204,0)),INDEX(SAISIE!$D$5:$D$204,MATCH(MINIFS(SAISIE!$E$5:$E$204,SAISIE!$B$5:$B$204,"*Vent G/D*",SAISIE!$F$5:$F$204,$G$31),SAISIE!$E$5:$E$204,0))),"-")) | D33: =IF(OR($G$31="",NOT(COUNTIFS(SAISIE!$B$5:$B$204,"*Vent G/D*",SAISIE!$F$5:$F$204,$G$31)>0)),"",IFERROR(IF(MINIFS(SAISIE!$E$5:$E$204,SAISIE!$B$5:$B$204,"*Vent G/D*",SAISIE!$F$5:$F$204,$G$31)>=0,0,MINIFS(SAISIE!$E$5:$E$204,SAISIE!$B$5:$B$204,"*Vent G/D*",SAISIE!$F$5:$F$204,$G$31)),"-")) | E33: =IF($G$31="","",IF(OR(D33="",D33="-"),"",IF(D33>0,"(soulevement)",IF(D33<0,"(compression)","-"))))
A34: =IF(OR($G$31="",NOT(MAXIFS(SAISIE!$E$5:$E$204,SAISIE!$B$5:$B$204,"*Vent G/D*",SAISIE!$F$5:$F$204,$G$31)>0)),"","Vent G/D") | B34: =IF(OR($G$31="",NOT(MAXIFS(SAISIE!$E$5:$E$204,SAISIE!$B$5:$B$204,"*Vent G/D*",SAISIE!$F$5:$F$204,$G$31)>0)),"",IFERROR(INDEX(SAISIE!$C$5:$C$204,MATCH(MAXIFS(SAISIE!$E$5:$E$204,SAISIE!$B$5:$B$204,"*Vent G/D*",SAISIE!$F$5:$F$204,$G$31),SAISIE!$E$5:$E$204,0)),"-")) | C34: =IF(OR($G$31="",NOT(MAXIFS(SAISIE!$E$5:$E$204,SAISIE!$B$5:$B$204,"*Vent G/D*",SAISIE!$F$5:$F$204,$G$31)>0)),"",IFERROR(INDEX(SAISIE!$D$5:$D$204,MATCH(MAXIFS(SAISIE!$E$5:$E$204,SAISIE!$B$5:$B$204,"*Vent G/D*",SAISIE!$F$5:$F$204,$G$31),SAISIE!$E$5:$E$204,0)),"-")) | D34: =IF(OR($G$31="",NOT(MAXIFS(SAISIE!$E$5:$E$204,SAISIE!$B$5:$B$204,"*Vent G/D*",SAISIE!$F$5:$F$204,$G$31)>0)),"",IFERROR(MAXIFS(SAISIE!$E$5:$E$204,SAISIE!$B$5:$B$204,"*Vent G/D*",SAISIE!$F$5:$F$204,$G$31),"-")) | E34: =IF($G$31="","",IF(OR(D34="",D34="-"),"",IF(D34>0,"(soulevement)",IF(D34<0,"(compression)","-"))))
A35: =IF(OR($G$31="",NOT(COUNTIFS(SAISIE!$B$5:$B$204,"*Vent D/G*",SAISIE!$F$5:$F$204,$G$31)>0)),"","Vent D/G") | B35: =IF(OR($G$31="",NOT(COUNTIFS(SAISIE!$B$5:$B$204,"*Vent D/G*",SAISIE!$F$5:$F$204,$G$31)>0)),"",IFERROR(IF(MINIFS(SAISIE!$E$5:$E$204,SAISIE!$B$5:$B$204,"*Vent D/G*",SAISIE!$F$5:$F$204,$G$31)>=0,MAXIFS(SAISIE!$C$5:$C$204,SAISIE!$B$5:$B$204,"*Vent D/G*",SAISIE!$F$5:$F$204,$G$31),INDEX(SAISIE!$C$5:$C$204,MATCH(MINIFS(SAISIE!$E$5:$E$204,SAISIE!$B$5:$B$204,"*Vent D/G*",SAISIE!$F$5:$F$204,$G$31),SAISIE!$E$5:$E$204,0))),"-")) | C35: =IF(OR($G$31="",NOT(COUNTIFS(SAISIE!$B$5:$B$204,"*Vent D/G*",SAISIE!$F$5:$F$204,$G$31)>0)),"",IFERROR(IF(MINIFS(SAISIE!$E$5:$E$204,SAISIE!$B$5:$B$204,"*Vent D/G*",SAISIE!$F$5:$F$204,$G$31)>=0,INDEX(SAISIE!$D$5:$D$204,MATCH(MAXIFS(SAISIE!$C$5:$C$204,SAISIE!$B$5:$B$204,"*Vent D/G*",SAISIE!$F$5:$F$204,$G$31),SAISIE!$C$5:$C$204,0)),INDEX(SAISIE!$D$5:$D$204,MATCH(MINIFS(SAISIE!$E$5:$E$204,SAISIE!$B$5:$B$204,"*Vent D/G*",SAISIE!$F$5:$F$204,$G$31),SAISIE!$E$5:$E$204,0))),"-")) | D35: =IF(OR($G$31="",NOT(COUNTIFS(SAISIE!$B$5:$B$204,"*Vent D/G*",SAISIE!$F$5:$F$204,$G$31)>0)),"",IFERROR(IF(MINIFS(SAISIE!$E$5:$E$204,SAISIE!$B$5:$B$204,"*Vent D/G*",SAISIE!$F$5:$F$204,$G$31)>=0,0,MINIFS(SAISIE!$E$5:$E$204,SAISIE!$B$5:$B$204,"*Vent D/G*",SAISIE!$F$5:$F$204,$G$31)),"-")) | E35: =IF($G$31="","",IF(OR(D35="",D35="-"),"",IF(D35>0,"(soulevement)",IF(D35<0,"(compression)","-"))))
A36: =IF(OR($G$31="",NOT(MAXIFS(SAISIE!$E$5:$E$204,SAISIE!$B$5:$B$204,"*Vent D/G*",SAISIE!$F$5:$F$204,$G$31)>0)),"","Vent D/G") | B36: =IF(OR($G$31="",NOT(MAXIFS(SAISIE!$E$5:$E$204,SAISIE!$B$5:$B$204,"*Vent D/G*",SAISIE!$F$5:$F$204,$G$31)>0)),"",IFERROR(INDEX(SAISIE!$C$5:$C$204,MATCH(MAXIFS(SAISIE!$E$5:$E$204,SAISIE!$B$5:$B$204,"*Vent D/G*",SAISIE!$F$5:$F$204,$G$31),SAISIE!$E$5:$E$204,0)),"-")) | C36: =IF(OR($G$31="",NOT(MAXIFS(SAISIE!$E$5:$E$204,SAISIE!$B$5:$B$204,"*Vent D/G*",SAISIE!$F$5:$F$204,$G$31)>0)),"",IFERROR(INDEX(SAISIE!$D$5:$D$204,MATCH(MAXIFS(SAISIE!$E$5:$E$204,SAISIE!$B$5:$B$204,"*Vent D/G*",SAISIE!$F$5:$F$204,$G$31),SAISIE!$E$5:$E$204,0)),"-")) | D36: =IF(OR($G$31="",NOT(MAXIFS(SAISIE!$E$5:$E$204,SAISIE!$B$5:$B$204,"*Vent D/G*",SAISIE!$F$5:$F$204,$G$31)>0)),"",IFERROR(MAXIFS(SAISIE!$E$5:$E$204,SAISIE!$B$5:$B$204,"*Vent D/G*",SAISIE!$F$5:$F$204,$G$31),"-")) | E36: =IF($G$31="","",IF(OR(D36="",D36="-"),"",IF(D36>0,"(soulevement)",IF(D36<0,"(compression)","-"))))
A37: =IF(OR($G$31="",NOT(COUNTIFS(SAISIE!$B$5:$B$204,"*Vent Av./Arr.*",SAISIE!$F$5:$F$204,$G$31)>0)),"","Vent Av./Arr.") | B37: =IF(OR($G$31="",NOT(COUNTIFS(SAISIE!$B$5:$B$204,"*Vent Av./Arr.*",SAISIE!$F$5:$F$204,$G$31)>0)),"",IFERROR(IF(MINIFS(SAISIE!$E$5:$E$204,SAISIE!$B$5:$B$204,"*Vent Av./Arr.*",SAISIE!$F$5:$F$204,$G$31)>=0,MAXIFS(SAISIE!$C$5:$C$204,SAISIE!$B$5:$B$204,"*Vent Av./Arr.*",SAISIE!$F$5:$F$204,$G$31),INDEX(SAISIE!$C$5:$C$204,MATCH(MINIFS(SAISIE!$E$5:$E$204,SAISIE!$B$5:$B$204,"*Vent Av./Arr.*",SAISIE!$F$5:$F$204,$G$31),SAISIE!$E$5:$E$204,0))),"-")) | C37: =IF(OR($G$31="",NOT(COUNTIFS(SAISIE!$B$5:$B$204,"*Vent Av./Arr.*",SAISIE!$F$5:$F$204,$G$31)>0)),"",IFERROR(IF(MINIFS(SAISIE!$E$5:$E$204,SAISIE!$B$5:$B$204,"*Vent Av./Arr.*",SAISIE!$F$5:$F$204,$G$31)>=0,INDEX(SAISIE!$D$5:$D$204,MATCH(MAXIFS(SAISIE!$C$5:$C$204,SAISIE!$B$5:$B$204,"*Vent Av./Arr.*",SAISIE!$F$5:$F$204,$G$31),SAISIE!$C$5:$C$204,0)),INDEX(SAISIE!$D$5:$D$204,MATCH(MINIFS(SAISIE!$E$5:$E$204,SAISIE!$B$5:$B$204,"*Vent Av./Arr.*",SAISIE!$F$5:$F$204,$G$31),SAISIE!$E$5:$E$204,0))),"-")) | D37: =IF(OR($G$31="",NOT(COUNTIFS(SAISIE!$B$5:$B$204,"*Vent Av./Arr.*",SAISIE!$F$5:$F$204,$G$31)>0)),"",IFERROR(IF(MINIFS(SAISIE!$E$5:$E$204,SAISIE!$B$5:$B$204,"*Vent Av./Arr.*",SAISIE!$F$5:$F$204,$G$31)>=0,0,MINIFS(SAISIE!$E$5:$E$204,SAISIE!$B$5:$B$204,"*Vent Av./Arr.*",SAISIE!$F$5:$F$204,$G$31)),"-")) | E37: =IF($G$31="","",IF(OR(D37="",D37="-"),"",IF(D37>0,"(soulevement)",IF(D37<0,"(compression)","-"))))
A38: =IF(OR($G$31="",NOT(MAXIFS(SAISIE!$E$5:$E$204,SAISIE!$B$5:$B$204,"*Vent Av./Arr.*",SAISIE!$F$5:$F$204,$G$31)>0)),"","Vent Av./Arr.") | B38: =IF(OR($G$31="",NOT(MAXIFS(SAISIE!$E$5:$E$204,SAISIE!$B$5:$B$204,"*Vent Av./Arr.*",SAISIE!$F$5:$F$204,$G$31)>0)),"",IFERROR(INDEX(SAISIE!$C$5:$C$204,MATCH(MAXIFS(SAISIE!$E$5:$E$204,SAISIE!$B$5:$B$204,"*Vent Av./Arr.*",SAISIE!$F$5:$F$204,$G$31),SAISIE!$E$5:$E$204,0)),"-")) | C38: =IF(OR($G$31="",NOT(MAXIFS(SAISIE!$E$5:$E$204,SAISIE!$B$5:$B$204,"*Vent Av./Arr.*",SAISIE!$F$5:$F$204,$G$31)>0)),"",IFERROR(INDEX(SAISIE!$D$5:$D$204,MATCH(MAXIFS(SAISIE!$E$5:$E$204,SAISIE!$B$5:$B$204,"*Vent Av./Arr.*",SAISIE!$F$5:$F$204,$G$31),SAISIE!$E$5:$E$204,0)),"-")) | D38: =IF(OR($G$31="",NOT(MAXIFS(SAISIE!$E$5:$E$204,SAISIE!$B$5:$B$204,"*Vent Av./Arr.*",SAISIE!$F$5:$F$204,$G$31)>0)),"",IFERROR(MAXIFS(SAISIE!$E$5:$E$204,SAISIE!$B$5:$B$204,"*Vent Av./Arr.*",SAISIE!$F$5:$F$204,$G$31),"-")) | E38: =IF($G$31="","",IF(OR(D38="",D38="-"),"",IF(D38>0,"(soulevement)",IF(D38<0,"(compression)","-"))))
A39: =IF(OR($G$31="",NOT(COUNTIFS(SAISIE!$B$5:$B$204,"*Vent Arr./Av.*",SAISIE!$F$5:$F$204,$G$31)>0)),"","Vent Arr./Av.") | B39: =IF(OR($G$31="",NOT(COUNTIFS(SAISIE!$B$5:$B$204,"*Vent Arr./Av.*",SAISIE!$F$5:$F$204,$G$31)>0)),"",IFERROR(IF(MINIFS(SAISIE!$E$5:$E$204,SAISIE!$B$5:$B$204,"*Vent Arr./Av.*",SAISIE!$F$5:$F$204,$G$31)>=0,MAXIFS(SAISIE!$C$5:$C$204,SAISIE!$B$5:$B$204,"*Vent Arr./Av.*",SAISIE!$F$5:$F$204,$G$31),INDEX(SAISIE!$C$5:$C$204,MATCH(MINIFS(SAISIE!$E$5:$E$204,SAISIE!$B$5:$B$204,"*Vent Arr./Av.*",SAISIE!$F$5:$F$204,$G$31),SAISIE!$E$5:$E$204,0))),"-")) | C39: =IF(OR($G$31="",NOT(COUNTIFS(SAISIE!$B$5:$B$204,"*Vent Arr./Av.*",SAISIE!$F$5:$F$204,$G$31)>0)),"",IFERROR(IF(MINIFS(SAISIE!$E$5:$E$204,SAISIE!$B$5:$B$204,"*Vent Arr./Av.*",SAISIE!$F$5:$F$204,$G$31)>=0,INDEX(SAISIE!$D$5:$D$204,MATCH(MAXIFS(SAISIE!$C$5:$C$204,SAISIE!$B$5:$B$204,"*Vent Arr./Av.*",SAISIE!$F$5:$F$204,$G$31),SAISIE!$C$5:$C$204,0)),INDEX(SAISIE!$D$5:$D$204,MATCH(MINIFS(SAISIE!$E$5:$E$204,SAISIE!$B$5:$B$204,"*Vent Arr./Av.*",SAISIE!$F$5:$F$204,$G$31),SAISIE!$E$5:$E$204,0))),"-")) | D39: =IF(OR($G$31="",NOT(COUNTIFS(SAISIE!$B$5:$B$204,"*Vent Arr./Av.*",SAISIE!$F$5:$F$204,$G$31)>0)),"",IFERROR(IF(MINIFS(SAISIE!$E$5:$E$204,SAISIE!$B$5:$B$204,"*Vent Arr./Av.*",SAISIE!$F$5:$F$204,$G$31)>=0,0,MINIFS(SAISIE!$E$5:$E$204,SAISIE!$B$5:$B$204,"*Vent Arr./Av.*",SAISIE!$F$5:$F$204,$G$31)),"-")) | E39: =IF($G$31="","",IF(OR(D39="",D39="-"),"",IF(D39>0,"(soulevement)",IF(D39<0,"(compression)","-"))))
A40: =IF(OR($G$31="",NOT(MAXIFS(SAISIE!$E$5:$E$204,SAISIE!$B$5:$B$204,"*Vent Arr./Av.*",SAISIE!$F$5:$F$204,$G$31)>0)),"","Vent Arr./Av.") | B40: =IF(OR($G$31="",NOT(MAXIFS(SAISIE!$E$5:$E$204,SAISIE!$B$5:$B$204,"*Vent Arr./Av.*",SAISIE!$F$5:$F$204,$G$31)>0)),"",IFERROR(INDEX(SAISIE!$C$5:$C$204,MATCH(MAXIFS(SAISIE!$E$5:$E$204,SAISIE!$B$5:$B$204,"*Vent Arr./Av.*",SAISIE!$F$5:$F$204,$G$31),SAISIE!$E$5:$E$204,0)),"-")) | C40: =IF(OR($G$31="",NOT(MAXIFS(SAISIE!$E$5:$E$204,SAISIE!$B$5:$B$204,"*Vent Arr./Av.*",SAISIE!$F$5:$F$204,$G$31)>0)),"",IFERROR(INDEX(SAISIE!$D$5:$D$204,MATCH(MAXIFS(SAISIE!$E$5:$E$204,SAISIE!$B$5:$B$204,"*Vent Arr./Av.*",SAISIE!$F$5:$F$204,$G$31),SAISIE!$E$5:$E$204,0)),"-")) | D40: =IF(OR($G$31="",NOT(MAXIFS(SAISIE!$E$5:$E$204,SAISIE!$B$5:$B$204,"*Vent Arr./Av.*",SAISIE!$F$5:$F$204,$G$31)>0)),"",IFERROR(MAXIFS(SAISIE!$E$5:$E$204,SAISIE!$B$5:$B$204,"*Vent Arr./Av.*",SAISIE!$F$5:$F$204,$G$31),"-")) | E40: =IF($G$31="","",IF(OR(D40="",D40="-"),"",IF(D40>0,"(soulevement)",IF(D40<0,"(compression)","-"))))
A41: =IF(OR($G$31="",NOT(TRUE)),"","Neige normale") | B41: =IF($G$31="","",IFERROR(INDEX(SAISIE!$C$5:$C$204,MATCH(MINIFS(SAISIE!$E$5:$E$204,SAISIE!$B$5:$B$204,"*Neige*",SAISIE!$B$5:$B$204,"<>*accidentel*",SAISIE!$F$5:$F$204,$G$31),SAISIE!$E$5:$E$204,0)),"-")) | C41: =IF($G$31="","",IFERROR(INDEX(SAISIE!$D$5:$D$204,MATCH(MINIFS(SAISIE!$E$5:$E$204,SAISIE!$B$5:$B$204,"*Neige*",SAISIE!$B$5:$B$204,"<>*accidentel*",SAISIE!$F$5:$F$204,$G$31),SAISIE!$E$5:$E$204,0)),"-")) | D41: =IF($G$31="","",IFERROR(INDEX(SAISIE!$E$5:$E$204,MATCH(MINIFS(SAISIE!$E$5:$E$204,SAISIE!$B$5:$B$204,"*Neige*",SAISIE!$B$5:$B$204,"<>*accidentel*",SAISIE!$F$5:$F$204,$G$31),SAISIE!$E$5:$E$204,0)),"-")) | E41: =IF($G$31="","",IF(OR(D41="",D41="-"),"",IF(D41>0,"(soulevement)",IF(D41<0,"(compression)","-"))))
A42: =IF(OR($G$31="",NOT(TRUE)),"","Neige accidentelle") | B42: =IF($G$31="","",IFERROR(LOOKUP(2,1/((SAISIE!$F$5:$F$204=$G$31)*(ISNUMBER(SEARCH("accidentel",SAISIE!$B$5:$B$204)))),SAISIE!$C$5:$C$204),"-")) | C42: =IF($G$31="","",IFERROR(LOOKUP(2,1/((SAISIE!$F$5:$F$204=$G$31)*(ISNUMBER(SEARCH("accidentel",SAISIE!$B$5:$B$204)))),SAISIE!$D$5:$D$204),"-")) | D42: =IF($G$31="","",IFERROR(LOOKUP(2,1/((SAISIE!$F$5:$F$204=$G$31)*(ISNUMBER(SEARCH("accidentel",SAISIE!$B$5:$B$204)))),SAISIE!$E$5:$E$204),"-")) | E42: =IF($G$31="","",IF(OR(D42="",D42="-"),"",IF(D42>0,"(soulevement)",IF(D42<0,"(compression)","-"))))
...
